{
 "cells": [
  {
   "cell_type": "markdown",
   "metadata": {},
   "source": [
    "# CDL"
   ]
  },
  {
   "cell_type": "markdown",
   "metadata": {},
   "source": [
    "### import module"
   ]
  },
  {
   "cell_type": "code",
   "execution_count": 1,
   "metadata": {},
   "outputs": [
    {
     "name": "stderr",
     "output_type": "stream",
     "text": [
      "Using TensorFlow backend.\n"
     ]
    }
   ],
   "source": [
    "import numpy as np\n",
    "import pickle\n",
    "import tensorflow as tf\n",
    "import pandas as pd\n",
    "from keras.preprocessing.text import Tokenizer, one_hot\n",
    "from pandas.api.types import CategoricalDtype\n",
    "from scipy.sparse import csr_matrix\n",
    "#init random seed\n",
    "np.random.seed(5)"
   ]
  },
  {
   "cell_type": "markdown",
   "metadata": {},
   "source": [
    "## 1. Data Preprocessing"
   ]
  },
  {
   "cell_type": "code",
   "execution_count": 2,
   "metadata": {},
   "outputs": [],
   "source": [
    "df = pd.read_json('D:/Datasets/amazon_reviews/Video_Games_5_proc.json')"
   ]
  },
  {
   "cell_type": "code",
   "execution_count": 3,
   "metadata": {},
   "outputs": [
    {
     "data": {
      "text/html": [
       "<div>\n",
       "<style scoped>\n",
       "    .dataframe tbody tr th:only-of-type {\n",
       "        vertical-align: middle;\n",
       "    }\n",
       "\n",
       "    .dataframe tbody tr th {\n",
       "        vertical-align: top;\n",
       "    }\n",
       "\n",
       "    .dataframe thead th {\n",
       "        text-align: right;\n",
       "    }\n",
       "</style>\n",
       "<table border=\"1\" class=\"dataframe\">\n",
       "  <thead>\n",
       "    <tr style=\"text-align: right;\">\n",
       "      <th></th>\n",
       "      <th>asin</th>\n",
       "      <th>helpful</th>\n",
       "      <th>overall</th>\n",
       "      <th>reviewText</th>\n",
       "      <th>reviewTextProc</th>\n",
       "      <th>reviewTime</th>\n",
       "      <th>reviewerID</th>\n",
       "      <th>reviewerName</th>\n",
       "      <th>summary</th>\n",
       "      <th>unixReviewTime</th>\n",
       "    </tr>\n",
       "  </thead>\n",
       "  <tbody>\n",
       "    <tr>\n",
       "      <th>0</th>\n",
       "      <td>0700099867</td>\n",
       "      <td>[8, 12]</td>\n",
       "      <td>1</td>\n",
       "      <td>Installing the game was a struggle (because of...</td>\n",
       "      <td>instal game struggle game window live bugs).so...</td>\n",
       "      <td>07 9, 2012</td>\n",
       "      <td>A2HD75EMZR8QLN</td>\n",
       "      <td>123</td>\n",
       "      <td>Pay to unlock content? I don't think so.</td>\n",
       "      <td>1341792000</td>\n",
       "    </tr>\n",
       "    <tr>\n",
       "      <th>1</th>\n",
       "      <td>0700099867</td>\n",
       "      <td>[0, 0]</td>\n",
       "      <td>4</td>\n",
       "      <td>If you like rally cars get this game you will ...</td>\n",
       "      <td>if like rally car game fun it orient 34;europe...</td>\n",
       "      <td>06 30, 2013</td>\n",
       "      <td>A3UR8NLLY1ZHCX</td>\n",
       "      <td>Alejandro Henao \"Electronic Junky\"</td>\n",
       "      <td>Good rally game</td>\n",
       "      <td>1372550400</td>\n",
       "    </tr>\n",
       "    <tr>\n",
       "      <th>10</th>\n",
       "      <td>0700099867</td>\n",
       "      <td>[1, 1]</td>\n",
       "      <td>5</td>\n",
       "      <td>I'm not quite finished with the game's DiRT To...</td>\n",
       "      <td>i be finish game 's dirt tour mode i believe i...</td>\n",
       "      <td>06 28, 2011</td>\n",
       "      <td>A38NXTZUFB1O2K</td>\n",
       "      <td>FiSH</td>\n",
       "      <td>Best in the series!</td>\n",
       "      <td>1309219200</td>\n",
       "    </tr>\n",
       "    <tr>\n",
       "      <th>100</th>\n",
       "      <td>9882155456</td>\n",
       "      <td>[0, 0]</td>\n",
       "      <td>3</td>\n",
       "      <td>They work fine but i feel like they have a lit...</td>\n",
       "      <td>they work fine feel like little lag control us...</td>\n",
       "      <td>01 7, 2014</td>\n",
       "      <td>A19IX3U60WJL1V</td>\n",
       "      <td>Edgar</td>\n",
       "      <td>works but flawed.</td>\n",
       "      <td>1389052800</td>\n",
       "    </tr>\n",
       "    <tr>\n",
       "      <th>1000</th>\n",
       "      <td>B00000I1BE</td>\n",
       "      <td>[8, 10]</td>\n",
       "      <td>5</td>\n",
       "      <td>This game in my opinion is the best of all the...</td>\n",
       "      <td>this game opinion good castlevania series far ...</td>\n",
       "      <td>10 3, 2000</td>\n",
       "      <td>A2U7ABLSDAITGC</td>\n",
       "      <td>D. Lewis</td>\n",
       "      <td>Castlevania Mania</td>\n",
       "      <td>970531200</td>\n",
       "    </tr>\n",
       "  </tbody>\n",
       "</table>\n",
       "</div>"
      ],
      "text/plain": [
       "            asin  helpful  overall  \\\n",
       "0     0700099867  [8, 12]        1   \n",
       "1     0700099867   [0, 0]        4   \n",
       "10    0700099867   [1, 1]        5   \n",
       "100   9882155456   [0, 0]        3   \n",
       "1000  B00000I1BE  [8, 10]        5   \n",
       "\n",
       "                                             reviewText  \\\n",
       "0     Installing the game was a struggle (because of...   \n",
       "1     If you like rally cars get this game you will ...   \n",
       "10    I'm not quite finished with the game's DiRT To...   \n",
       "100   They work fine but i feel like they have a lit...   \n",
       "1000  This game in my opinion is the best of all the...   \n",
       "\n",
       "                                         reviewTextProc   reviewTime  \\\n",
       "0     instal game struggle game window live bugs).so...   07 9, 2012   \n",
       "1     if like rally car game fun it orient 34;europe...  06 30, 2013   \n",
       "10    i be finish game 's dirt tour mode i believe i...  06 28, 2011   \n",
       "100   they work fine feel like little lag control us...   01 7, 2014   \n",
       "1000  this game opinion good castlevania series far ...   10 3, 2000   \n",
       "\n",
       "          reviewerID                        reviewerName  \\\n",
       "0     A2HD75EMZR8QLN                                 123   \n",
       "1     A3UR8NLLY1ZHCX  Alejandro Henao \"Electronic Junky\"   \n",
       "10    A38NXTZUFB1O2K                                FiSH   \n",
       "100   A19IX3U60WJL1V                               Edgar   \n",
       "1000  A2U7ABLSDAITGC                            D. Lewis   \n",
       "\n",
       "                                       summary  unixReviewTime  \n",
       "0     Pay to unlock content? I don't think so.      1341792000  \n",
       "1                              Good rally game      1372550400  \n",
       "10                         Best in the series!      1309219200  \n",
       "100                          works but flawed.      1389052800  \n",
       "1000                         Castlevania Mania       970531200  "
      ]
     },
     "execution_count": 3,
     "metadata": {},
     "output_type": "execute_result"
    }
   ],
   "source": [
    "df.head()"
   ]
  },
  {
   "cell_type": "code",
   "execution_count": 4,
   "metadata": {},
   "outputs": [],
   "source": [
    "reviews = df.groupby('asin').reviewTextProc.agg(' '.join)"
   ]
  },
  {
   "cell_type": "code",
   "execution_count": 5,
   "metadata": {},
   "outputs": [],
   "source": [
    "from sklearn.feature_extraction.text import CountVectorizer\n",
    "\n",
    "vectorizer = CountVectorizer(max_features=10000)\n",
    "vectorizer.fit(reviews.values)\n",
    "\n",
    "X_train = vectorizer.transform(reviews.values)"
   ]
  },
  {
   "cell_type": "code",
   "execution_count": 6,
   "metadata": {},
   "outputs": [
    {
     "name": "stdout",
     "output_type": "stream",
     "text": [
      "(10672, 10000)\n"
     ]
    }
   ],
   "source": [
    "print(X_train.shape)"
   ]
  },
  {
   "cell_type": "code",
   "execution_count": 7,
   "metadata": {},
   "outputs": [
    {
     "data": {
      "text/plain": [
       "[('axel', 850),\n",
       " ('nt', 6034),\n",
       " ('nfl', 5934),\n",
       " ('disapoint', 2555),\n",
       " ('everytime', 3112),\n",
       " ('understandably', 9274),\n",
       " ('interrupt', 4680),\n",
       " ('hair', 4056),\n",
       " ('museum', 5789),\n",
       " ('suit', 8595)]"
      ]
     },
     "execution_count": 7,
     "metadata": {},
     "output_type": "execute_result"
    }
   ],
   "source": [
    "list(vectorizer.vocabulary_.items())[0:10]"
   ]
  },
  {
   "cell_type": "code",
   "execution_count": 8,
   "metadata": {},
   "outputs": [
    {
     "data": {
      "text/plain": [
       "['doubleheader',\n",
       " 'tarturus',\n",
       " 'starvation',\n",
       " 'dimensionsfor',\n",
       " '47bundle',\n",
       " 'whimpers',\n",
       " 'gumball',\n",
       " 'anf',\n",
       " 'quoteable',\n",
       " 'visaul']"
      ]
     },
     "execution_count": 8,
     "metadata": {},
     "output_type": "execute_result"
    }
   ],
   "source": [
    "list(vectorizer.stop_words_)[0:10]"
   ]
  },
  {
   "cell_type": "code",
   "execution_count": 9,
   "metadata": {},
   "outputs": [
    {
     "data": {
      "text/plain": [
       "<10672x10000 sparse matrix of type '<class 'numpy.int64'>'\n",
       "\twith 6711786 stored elements in Compressed Sparse Row format>"
      ]
     },
     "execution_count": 9,
     "metadata": {},
     "output_type": "execute_result"
    }
   ],
   "source": [
    "X_train"
   ]
  },
  {
   "cell_type": "markdown",
   "metadata": {},
   "source": [
    "#### build rating matrix citeulike-a"
   ]
  },
  {
   "cell_type": "code",
   "execution_count": 10,
   "metadata": {},
   "outputs": [],
   "source": [
    "asin = CategoricalDtype(sorted(df.asin.unique()), ordered=True)\n",
    "rev_id = CategoricalDtype(sorted(df.reviewerID.unique()), ordered=True)\n",
    "\n",
    "row_cat = df.reviewerID.astype(rev_id).cat\n",
    "col_cat = df.asin.astype(asin).cat\n",
    "\n",
    "row = row_cat.codes\n",
    "col = col_cat.codes\n",
    "\n",
    "sparse_matrix = csr_matrix((df[\"overall\"].values, (row, col)), \\\n",
    "                           shape=(rev_id.categories.size, asin.categories.size), dtype = 'd')"
   ]
  },
  {
   "cell_type": "code",
   "execution_count": 11,
   "metadata": {},
   "outputs": [],
   "source": [
    "rating_matrix = sparse_matrix"
   ]
  },
  {
   "cell_type": "markdown",
   "metadata": {},
   "source": [
    "#### save matrix by pickle"
   ]
  },
  {
   "cell_type": "code",
   "execution_count": 58,
   "metadata": {},
   "outputs": [],
   "source": [
    "with open(r'D:/Datasets/amazon_reviews/cdl_item_infomation_matrix.pickle', 'wb') as handle:\n",
    "    pickle.dump(X_train, handle, protocol=pickle.HIGHEST_PROTOCOL)\n",
    "    \n",
    "with open(r'D:/Datasets/amazon_reviews/cdl_rating_matrix.pickle', 'wb') as handle:\n",
    "    pickle.dump(rating_matrix, handle, protocol=pickle.HIGHEST_PROTOCOL)"
   ]
  },
  {
   "cell_type": "markdown",
   "metadata": {},
   "source": [
    "#### load matrix from pickle "
   ]
  },
  {
   "cell_type": "code",
   "execution_count": 5,
   "metadata": {},
   "outputs": [],
   "source": [
    "with open(r'D:/Datasets/amazon_reviews/cdl_item_infomation_matrix.pickle', 'rb') as handle:\n",
    "    X_train = pickle.load(handle)  \n",
    "    \n",
    "with open(r'D:/Datasets/amazon_reviews/cdl_rating_matrix.pickle', 'rb') as handle2:\n",
    "    rating_matrix = pickle.load(handle2)"
   ]
  },
  {
   "cell_type": "markdown",
   "metadata": {},
   "source": [
    "## 2. build model"
   ]
  },
  {
   "cell_type": "markdown",
   "metadata": {},
   "source": [
    "### matrix factorization model"
   ]
  },
  {
   "cell_type": "code",
   "execution_count": 12,
   "metadata": {},
   "outputs": [],
   "source": [
    "class MF():\n",
    "    def __init__(self , rating_matrix ):\n",
    "        self.num_u = rating_matrix.shape[0] #5551\n",
    "        self.num_v = rating_matrix.shape[1] #16980\n",
    "        \n",
    "        self.u_lambda = 100\n",
    "        self.v_lambda = 0.1\n",
    "        \n",
    "        self.k = 50 #latent維度\n",
    "        self.a = 1\n",
    "        self.b = 0.01\n",
    "        \n",
    "        self.R = np.mat(rating_matrix)\n",
    "        self.C = np.mat(np.ones(self.R.shape)) * self.b\n",
    "        self.C[np.where(self.R>0)] = self.a\n",
    "        \n",
    "        self.I_U = np.mat(np.eye(self.k) * self.u_lambda)\n",
    "        self.I_V = np.mat(np.eye(self.k) * self.v_lambda)\n",
    "        \n",
    "        self.U = np.mat(np.random.normal(0 , 1/self.u_lambda , size=(self.k,self.num_u)))\n",
    "        self.V = np.mat(np.random.normal(0 , 1/self.v_lambda , size=(self.k,self.num_v)))\n",
    "                        \n",
    "\n",
    "    def test(self):\n",
    "        print( ((U_cut*self.R[np.ravel(np.where(self.R[:,j]>0)[1]),j] + self.v_lambda * self.V_sdae[j])).shape)\n",
    "        \n",
    "    \n",
    "    def ALS(self , V_sdae):\n",
    "        self.V_sdae = np.mat(V_sdae)\n",
    "        \n",
    "        V_sq = self.V * self.V.T * self.b\n",
    "        for i in range(self.num_u):\n",
    "            idx_a = np.ravel(np.where(self.R[i,:]>0)[1])\n",
    "            V_cut = self.V[:,idx_a]\n",
    "            self.U[:,i] = np.linalg.pinv( V_sq+ V_cut * V_cut.T * (self.a-self.b) + self.I_U )*(V_cut*self.R[i,idx_a].T) #V_sq+V_cut*V_cut.T*a_m_b = VCV^T\n",
    "        \n",
    "        U_sq = self.U * self.U.T * self.b\n",
    "        for j in range(self.num_v):\n",
    "            idx_a = np.ravel(np.where(self.R[:,j]>0)[1])\n",
    "            U_cut = self.U[:,idx_a]\n",
    "            self.V[:,j] = np.linalg.pinv(U_sq+U_cut*U_cut.T*(self.a-self.b)+self.I_V)* (U_cut*self.R[idx_a,j] + self.v_lambda * np.resize(self.V_sdae[j],(self.k,1)))\n",
    "        \n",
    "        return self.U ,self.V"
   ]
  },
  {
   "cell_type": "markdown",
   "metadata": {},
   "source": [
    "#### masking noise "
   ]
  },
  {
   "cell_type": "code",
   "execution_count": 19,
   "metadata": {},
   "outputs": [],
   "source": [
    "def mask(corruption_level, shape):\n",
    "    mask = np.random.binomial(1, 1 - corruption_level, shape)\n",
    "    return mask\n",
    "\n",
    "def add_noise(x , corruption_level ):\n",
    "    mask_ = mask(corruption_level , x.shape)\n",
    "    x = np.multiply(x, mask_)\n",
    "    print(\"Noising completed..:\" + str(x.shape))\n",
    "    return x"
   ]
  },
  {
   "cell_type": "code",
   "execution_count": 15,
   "metadata": {},
   "outputs": [],
   "source": [
    "class CDL():\n",
    "    def __init__(self , rating_matrix , item_infomation_matrix):\n",
    "        # model參數設定\n",
    "        self.n_input = 8000\n",
    "        self.n_hidden1 = 200\n",
    "        self.n_hidden2 = 50\n",
    "        self.k = 50\n",
    "        \n",
    "        self.lambda_w = 1\n",
    "        self.lambda_n = 1\n",
    "        self.lambda_u = 1\n",
    "        self.lambda_v = 1\n",
    "        \n",
    "        self.drop_ratio = 0.1\n",
    "        self.learning_rate = 0.001\n",
    "        self.epochs = 10\n",
    "        self.batch_size = 32\n",
    "        \n",
    "        self.num_u = rating_matrix.shape[0]\n",
    "        self.num_v = rating_matrix.shape[1]\n",
    "        \n",
    "        self.Weights = {\n",
    "            'w1' : tf.Variable(tf.random_normal( [self.n_input , self.n_hidden1] , mean=0.0, stddev=1 / self.lambda_w )),\n",
    "            'w2' : tf.Variable(tf.random_normal( [self.n_hidden1 , self.n_hidden2] , mean=0.0, stddev=1 / self.lambda_w )),\n",
    "            'w3' : tf.Variable(tf.random_normal( [self.n_hidden2 , self.n_hidden1] , mean=0.0, stddev=1 / self.lambda_w )),\n",
    "            'w4' : tf.Variable(tf.random_normal( [self.n_hidden1 , self.n_input] , mean=0.0, stddev=1 / self.lambda_w ))   \n",
    "        }\n",
    "        self.Biases = {\n",
    "            'b1' : tf.Variable(tf.random_normal( [self.n_hidden1] , mean=0.0, stddev=1 / self.lambda_w )),\n",
    "            'b2' : tf.Variable(tf.random_normal( [self.n_hidden2] , mean=0.0, stddev=1 / self.lambda_w )),\n",
    "            'b3' : tf.Variable(tf.random_normal( [self.n_hidden1] , mean=0.0, stddev=1 / self.lambda_w )),\n",
    "            'b4' : tf.Variable(tf.random_normal( [self.n_input] , mean=0.0, stddev=1 / self.lambda_w ))\n",
    "        }\n",
    "        \n",
    "        self.item_infomation_matrix = item_infomation_matrix\n",
    "        self.rating_matrix = rating_matrix\n",
    "    \n",
    "        self.build_model()\n",
    "        \n",
    "    def encoder(self , x , drop_ratio):\n",
    "        w1 = self.Weights['w1']\n",
    "        b1 = self.Biases['b1']\n",
    "        L1 = tf.nn.sigmoid( tf.matmul(x,w1) + b1 )\n",
    "        L1 = tf.nn.dropout( L1 , keep_prob= 1 - drop_ratio )\n",
    "        \n",
    "        w2 = self.Weights['w2']\n",
    "        b2 = self.Biases['b2']\n",
    "        L2 = tf.nn.sigmoid( tf.matmul(L1,w2) + b2 )\n",
    "        L2 = tf.nn.dropout(L2 , keep_prob= 1 - drop_ratio)\n",
    "        \n",
    "        return L2\n",
    "    \n",
    "    def decoder(self , x , drop_ratio):\n",
    "        w3 = self.Weights['w3']\n",
    "        b3 = self.Biases['b3']\n",
    "        L3 = tf.nn.sigmoid(tf.matmul(x,w3) + b3)\n",
    "        L3 = tf.nn.dropout(L3 , keep_prob= 1 - drop_ratio)\n",
    "\n",
    "        w4 = self.Weights['w4']\n",
    "        b4 = self.Biases['b4']\n",
    "        L4 = tf.nn.sigmoid(tf.matmul(L3,w4) + b4)\n",
    "        L4 = tf.nn.dropout(L4 , keep_prob= 1 - drop_ratio)\n",
    "\n",
    "        return L4\n",
    "    \n",
    "    def build_model(self):\n",
    "        self.model_X_0 = tf.placeholder(tf.float32 , shape=(None , self.n_input))\n",
    "        self.model_X_c = tf.placeholder(tf.float32 , shape=(None , self.n_input))\n",
    "        self.model_V = tf.placeholder(tf.float32 , shape=(None , self.k))\n",
    "        self.model_drop_ratio = tf.placeholder(tf.float32)\n",
    "        \n",
    "        self.V_sdae = self.encoder( self.model_X_0 , self.model_drop_ratio )\n",
    "        self.y_pred = self.decoder( self.V_sdae , self.model_drop_ratio )\n",
    "        \n",
    "        self.Regularization = tf.reduce_sum([tf.nn.l2_loss(w) + tf.nn.l2_loss(b) \n",
    "                                             for w,b in zip(self.Weights.values() , self.Biases.values())])\n",
    "        loss_r =1/2 * self.lambda_w * self.Regularization\n",
    "        loss_a =1/2 * self.lambda_n * tf.reduce_sum(tf.pow( self.model_X_c - self.y_pred , 2 ))\n",
    "        loss_v =1/2 * self.lambda_v * tf.reduce_sum(tf.pow( self.model_V - self.V_sdae , 2 ))\n",
    "        \n",
    "        self.Loss = loss_r + loss_a + loss_v\n",
    "        self.optimizer = tf.train.AdamOptimizer(self.learning_rate).minimize(self.Loss)\n",
    "    \n",
    "    def training(self):\n",
    "        #np.random.shuffle(self.item_infomation_matrix) #random index of train data\n",
    "        \n",
    "        #self.item_infomation_matrix_noise = add_noise(self.item_infomation_matrix , 0.3)\n",
    "        \n",
    "        sess = tf.Session()\n",
    "        sess.run(tf.global_variables_initializer())\n",
    "        \n",
    "        mf = MF(self.rating_matrix)\n",
    "        \n",
    "        for epoch in range(self.epochs):\n",
    "            print(\"%d / %d\"%(epoch+1 , self.epochs))\n",
    "            \n",
    "            V_sdae = sess.run(self.V_sdae , feed_dict={self.model_X_0 : self.item_infomation_matrix_noise , self.model_drop_ratio : 0.1})\n",
    "            \n",
    "            U , V = mf.ALS(V_sdae)\n",
    "            V = np.resize(V,(16980 , 50))\n",
    "            for i in range(0 , self.item_infomation_matrix.shape[0] , self.batch_size):\n",
    "                X_train_batch = self.item_infomation_matrix_noise[i:i+self.batch_size]\n",
    "                y_train_batch = self.item_infomation_matrix[i:i+self.batch_size]\n",
    "                V_batch = V[i:i+self.batch_size]\n",
    "                \n",
    "                _ , my_loss = sess.run([self.optimizer, self.Loss] , feed_dict={self.model_X_0 :X_train_batch , self.model_X_c : y_train_batch , self.model_V:V_batch, self.model_drop_ratio : 0.1})\n",
    "            print(my_loss)\n",
    "        \n",
    "        sess.close()"
   ]
  },
  {
   "cell_type": "code",
   "execution_count": 20,
   "metadata": {},
   "outputs": [
    {
     "data": {
      "text/plain": [
       "(10672, 10000)"
      ]
     },
     "execution_count": 20,
     "metadata": {},
     "output_type": "execute_result"
    }
   ],
   "source": [
    "X_train.shape"
   ]
  },
  {
   "cell_type": "code",
   "execution_count": 21,
   "metadata": {},
   "outputs": [
    {
     "name": "stderr",
     "output_type": "stream",
     "text": [
      "ERROR:root:Internal Python error in the inspect module.\n",
      "Below is the traceback from this internal error.\n",
      "\n"
     ]
    },
    {
     "name": "stdout",
     "output_type": "stream",
     "text": [
      "Traceback (most recent call last):\n",
      "  File \"C:\\Users\\irina\\Miniconda3\\envs\\exmc\\lib\\site-packages\\scipy\\sparse\\base.py\", line 461, in __mul__\n",
      "    M, N = self.shape\n",
      "  File \"C:\\Users\\irina\\Miniconda3\\envs\\exmc\\lib\\site-packages\\scipy\\sparse\\base.py\", line 86, in get_shape\n",
      "    def get_shape(self):\n",
      "KeyboardInterrupt\n",
      "\n",
      "During handling of the above exception, another exception occurred:\n",
      "\n",
      "Traceback (most recent call last):\n",
      "  File \"C:\\Users\\irina\\Miniconda3\\envs\\exmc\\lib\\site-packages\\scipy\\sparse\\base.py\", line 461, in __mul__\n",
      "    M, N = self.shape\n",
      "SystemError: PyEval_EvalFrameEx returned a result with an error set\n",
      "\n",
      "During handling of the above exception, another exception occurred:\n",
      "\n",
      "Traceback (most recent call last):\n",
      "  File \"C:\\Users\\irina\\Miniconda3\\envs\\exmc\\lib\\site-packages\\scipy\\sparse\\base.py\", line 461, in __mul__\n",
      "    M, N = self.shape\n",
      "SystemError: PyEval_EvalFrameEx returned a result with an error set\n",
      "\n",
      "During handling of the above exception, another exception occurred:\n",
      "\n",
      "Traceback (most recent call last):\n",
      "  File \"C:\\Users\\irina\\Miniconda3\\envs\\exmc\\lib\\site-packages\\scipy\\sparse\\base.py\", line 461, in __mul__\n",
      "    M, N = self.shape\n",
      "SystemError: PyEval_EvalFrameEx returned a result with an error set\n",
      "\n",
      "During handling of the above exception, another exception occurred:\n",
      "\n",
      "Traceback (most recent call last):\n",
      "  File \"C:\\Users\\irina\\Miniconda3\\envs\\exmc\\lib\\site-packages\\scipy\\sparse\\base.py\", line 461, in __mul__\n",
      "    M, N = self.shape\n",
      "SystemError: PyEval_EvalFrameEx returned a result with an error set\n",
      "\n",
      "During handling of the above exception, another exception occurred:\n",
      "\n",
      "Traceback (most recent call last):\n",
      "  File \"C:\\Users\\irina\\Miniconda3\\envs\\exmc\\lib\\site-packages\\scipy\\sparse\\base.py\", line 461, in __mul__\n",
      "    M, N = self.shape\n",
      "SystemError: PyEval_EvalFrameEx returned a result with an error set\n",
      "\n",
      "During handling of the above exception, another exception occurred:\n",
      "\n",
      "Traceback (most recent call last):\n",
      "  File \"C:\\Users\\irina\\Miniconda3\\envs\\exmc\\lib\\site-packages\\scipy\\sparse\\base.py\", line 461, in __mul__\n",
      "    M, N = self.shape\n",
      "SystemError: PyEval_EvalFrameEx returned a result with an error set\n",
      "\n",
      "During handling of the above exception, another exception occurred:\n",
      "\n",
      "Traceback (most recent call last):\n",
      "  File \"C:\\Users\\irina\\Miniconda3\\envs\\exmc\\lib\\site-packages\\scipy\\sparse\\base.py\", line 461, in __mul__\n",
      "    M, N = self.shape\n",
      "SystemError: PyEval_EvalFrameEx returned a result with an error set\n",
      "\n",
      "During handling of the above exception, another exception occurred:\n",
      "\n",
      "Traceback (most recent call last):\n",
      "  File \"C:\\Users\\irina\\Miniconda3\\envs\\exmc\\lib\\site-packages\\scipy\\sparse\\base.py\", line 461, in __mul__\n",
      "    M, N = self.shape\n",
      "SystemError: PyEval_EvalFrameEx returned a result with an error set\n",
      "\n",
      "During handling of the above exception, another exception occurred:\n",
      "\n",
      "Traceback (most recent call last):\n",
      "  File \"C:\\Users\\irina\\Miniconda3\\envs\\exmc\\lib\\site-packages\\scipy\\sparse\\base.py\", line 461, in __mul__\n",
      "    M, N = self.shape\n",
      "SystemError: PyEval_EvalFrameEx returned a result with an error set\n",
      "\n",
      "During handling of the above exception, another exception occurred:\n",
      "\n",
      "Traceback (most recent call last):\n",
      "  File \"C:\\Users\\irina\\Miniconda3\\envs\\exmc\\lib\\site-packages\\scipy\\sparse\\base.py\", line 461, in __mul__\n",
      "    M, N = self.shape\n",
      "SystemError: PyEval_EvalFrameEx returned a result with an error set\n",
      "\n",
      "During handling of the above exception, another exception occurred:\n",
      "\n",
      "Traceback (most recent call last):\n",
      "  File \"C:\\Users\\irina\\Miniconda3\\envs\\exmc\\lib\\site-packages\\scipy\\sparse\\base.py\", line 461, in __mul__\n",
      "    M, N = self.shape\n",
      "SystemError: PyEval_EvalFrameEx returned a result with an error set\n",
      "\n",
      "During handling of the above exception, another exception occurred:\n",
      "\n",
      "Traceback (most recent call last):\n",
      "  File \"C:\\Users\\irina\\Miniconda3\\envs\\exmc\\lib\\site-packages\\scipy\\sparse\\base.py\", line 461, in __mul__\n",
      "    M, N = self.shape\n",
      "SystemError: PyEval_EvalFrameEx returned a result with an error set\n",
      "\n",
      "During handling of the above exception, another exception occurred:\n",
      "\n",
      "Traceback (most recent call last):\n",
      "  File \"C:\\Users\\irina\\Miniconda3\\envs\\exmc\\lib\\site-packages\\scipy\\sparse\\base.py\", line 461, in __mul__\n",
      "    M, N = self.shape\n",
      "SystemError: PyEval_EvalFrameEx returned a result with an error set\n",
      "\n",
      "During handling of the above exception, another exception occurred:\n",
      "\n",
      "Traceback (most recent call last):\n",
      "  File \"C:\\Users\\irina\\Miniconda3\\envs\\exmc\\lib\\site-packages\\scipy\\sparse\\base.py\", line 461, in __mul__\n",
      "    M, N = self.shape\n",
      "SystemError: PyEval_EvalFrameEx returned a result with an error set\n",
      "\n",
      "During handling of the above exception, another exception occurred:\n",
      "\n",
      "Traceback (most recent call last):\n",
      "  File \"C:\\Users\\irina\\Miniconda3\\envs\\exmc\\lib\\site-packages\\scipy\\sparse\\base.py\", line 461, in __mul__\n",
      "    M, N = self.shape\n",
      "SystemError: PyEval_EvalFrameEx returned a result with an error set\n",
      "\n",
      "During handling of the above exception, another exception occurred:\n",
      "\n",
      "Traceback (most recent call last):\n",
      "  File \"C:\\Users\\irina\\Miniconda3\\envs\\exmc\\lib\\site-packages\\scipy\\sparse\\base.py\", line 461, in __mul__\n",
      "    M, N = self.shape\n",
      "SystemError: PyEval_EvalFrameEx returned a result with an error set\n",
      "\n",
      "During handling of the above exception, another exception occurred:\n",
      "\n",
      "Traceback (most recent call last):\n",
      "  File \"C:\\Users\\irina\\Miniconda3\\envs\\exmc\\lib\\site-packages\\scipy\\sparse\\base.py\", line 461, in __mul__\n",
      "    M, N = self.shape\n",
      "SystemError: PyEval_EvalFrameEx returned a result with an error set\n",
      "\n",
      "During handling of the above exception, another exception occurred:\n",
      "\n",
      "Traceback (most recent call last):\n",
      "  File \"C:\\Users\\irina\\Miniconda3\\envs\\exmc\\lib\\site-packages\\scipy\\sparse\\base.py\", line 461, in __mul__\n",
      "    M, N = self.shape\n",
      "SystemError: PyEval_EvalFrameEx returned a result with an error set\n",
      "\n",
      "During handling of the above exception, another exception occurred:\n",
      "\n",
      "Traceback (most recent call last):\n",
      "  File \"C:\\Users\\irina\\Miniconda3\\envs\\exmc\\lib\\site-packages\\scipy\\sparse\\base.py\", line 461, in __mul__\n",
      "    M, N = self.shape\n",
      "SystemError: PyEval_EvalFrameEx returned a result with an error set\n",
      "\n",
      "During handling of the above exception, another exception occurred:\n",
      "\n",
      "Traceback (most recent call last):\n",
      "  File \"C:\\Users\\irina\\Miniconda3\\envs\\exmc\\lib\\site-packages\\scipy\\sparse\\base.py\", line 461, in __mul__\n",
      "    M, N = self.shape\n",
      "SystemError: PyEval_EvalFrameEx returned a result with an error set\n",
      "\n",
      "During handling of the above exception, another exception occurred:\n",
      "\n",
      "Traceback (most recent call last):\n",
      "  File \"C:\\Users\\irina\\Miniconda3\\envs\\exmc\\lib\\site-packages\\scipy\\sparse\\base.py\", line 461, in __mul__\n",
      "    M, N = self.shape\n",
      "SystemError: PyEval_EvalFrameEx returned a result with an error set\n",
      "\n",
      "During handling of the above exception, another exception occurred:\n",
      "\n",
      "Traceback (most recent call last):\n",
      "  File \"C:\\Users\\irina\\Miniconda3\\envs\\exmc\\lib\\site-packages\\scipy\\sparse\\base.py\", line 461, in __mul__\n",
      "    M, N = self.shape\n",
      "SystemError: PyEval_EvalFrameEx returned a result with an error set\n",
      "\n",
      "During handling of the above exception, another exception occurred:\n",
      "\n",
      "Traceback (most recent call last):\n",
      "  File \"C:\\Users\\irina\\Miniconda3\\envs\\exmc\\lib\\site-packages\\scipy\\sparse\\base.py\", line 461, in __mul__\n",
      "    M, N = self.shape\n",
      "SystemError: PyEval_EvalFrameEx returned a result with an error set\n",
      "\n",
      "During handling of the above exception, another exception occurred:\n",
      "\n",
      "Traceback (most recent call last):\n",
      "  File \"C:\\Users\\irina\\Miniconda3\\envs\\exmc\\lib\\site-packages\\scipy\\sparse\\base.py\", line 461, in __mul__\n",
      "    M, N = self.shape\n",
      "SystemError: PyEval_EvalFrameEx returned a result with an error set\n",
      "\n",
      "During handling of the above exception, another exception occurred:\n",
      "\n",
      "Traceback (most recent call last):\n",
      "  File \"C:\\Users\\irina\\Miniconda3\\envs\\exmc\\lib\\site-packages\\scipy\\sparse\\base.py\", line 461, in __mul__\n",
      "    M, N = self.shape\n",
      "SystemError: PyEval_EvalFrameEx returned a result with an error set\n",
      "\n",
      "During handling of the above exception, another exception occurred:\n",
      "\n",
      "Traceback (most recent call last):\n",
      "  File \"C:\\Users\\irina\\Miniconda3\\envs\\exmc\\lib\\site-packages\\scipy\\sparse\\base.py\", line 461, in __mul__\n",
      "    M, N = self.shape\n",
      "SystemError: PyEval_EvalFrameEx returned a result with an error set\n",
      "\n",
      "During handling of the above exception, another exception occurred:\n",
      "\n",
      "Traceback (most recent call last):\n",
      "  File \"C:\\Users\\irina\\Miniconda3\\envs\\exmc\\lib\\site-packages\\scipy\\sparse\\base.py\", line 461, in __mul__\n",
      "    M, N = self.shape\n",
      "SystemError: PyEval_EvalFrameEx returned a result with an error set\n",
      "\n",
      "During handling of the above exception, another exception occurred:\n",
      "\n",
      "Traceback (most recent call last):\n",
      "  File \"C:\\Users\\irina\\Miniconda3\\envs\\exmc\\lib\\site-packages\\scipy\\sparse\\base.py\", line 461, in __mul__\n",
      "    M, N = self.shape\n",
      "SystemError: PyEval_EvalFrameEx returned a result with an error set\n",
      "\n",
      "During handling of the above exception, another exception occurred:\n",
      "\n",
      "Traceback (most recent call last):\n",
      "  File \"C:\\Users\\irina\\Miniconda3\\envs\\exmc\\lib\\site-packages\\scipy\\sparse\\base.py\", line 461, in __mul__\n",
      "    M, N = self.shape\n",
      "SystemError: PyEval_EvalFrameEx returned a result with an error set\n",
      "\n",
      "During handling of the above exception, another exception occurred:\n",
      "\n",
      "Traceback (most recent call last):\n",
      "  File \"C:\\Users\\irina\\Miniconda3\\envs\\exmc\\lib\\site-packages\\scipy\\sparse\\base.py\", line 461, in __mul__\n",
      "    M, N = self.shape\n",
      "SystemError: PyEval_EvalFrameEx returned a result with an error set\n",
      "\n",
      "During handling of the above exception, another exception occurred:\n",
      "\n",
      "Traceback (most recent call last):\n",
      "  File \"C:\\Users\\irina\\Miniconda3\\envs\\exmc\\lib\\site-packages\\scipy\\sparse\\base.py\", line 461, in __mul__\n",
      "    M, N = self.shape\n",
      "SystemError: PyEval_EvalFrameEx returned a result with an error set\n",
      "\n",
      "During handling of the above exception, another exception occurred:\n",
      "\n",
      "Traceback (most recent call last):\n",
      "  File \"C:\\Users\\irina\\Miniconda3\\envs\\exmc\\lib\\site-packages\\scipy\\sparse\\base.py\", line 461, in __mul__\n",
      "    M, N = self.shape\n",
      "SystemError: PyEval_EvalFrameEx returned a result with an error set\n",
      "\n",
      "During handling of the above exception, another exception occurred:\n",
      "\n",
      "Traceback (most recent call last):\n",
      "  File \"C:\\Users\\irina\\Miniconda3\\envs\\exmc\\lib\\site-packages\\scipy\\sparse\\base.py\", line 461, in __mul__\n",
      "    M, N = self.shape\n",
      "SystemError: PyEval_EvalFrameEx returned a result with an error set\n",
      "\n",
      "During handling of the above exception, another exception occurred:\n",
      "\n",
      "Traceback (most recent call last):\n",
      "  File \"C:\\Users\\irina\\Miniconda3\\envs\\exmc\\lib\\site-packages\\scipy\\sparse\\base.py\", line 461, in __mul__\n",
      "    M, N = self.shape\n",
      "SystemError: PyEval_EvalFrameEx returned a result with an error set\n",
      "\n",
      "During handling of the above exception, another exception occurred:\n",
      "\n",
      "Traceback (most recent call last):\n",
      "  File \"C:\\Users\\irina\\Miniconda3\\envs\\exmc\\lib\\site-packages\\scipy\\sparse\\base.py\", line 461, in __mul__\n",
      "    M, N = self.shape\n",
      "SystemError: PyEval_EvalFrameEx returned a result with an error set\n",
      "\n",
      "During handling of the above exception, another exception occurred:\n",
      "\n",
      "Traceback (most recent call last):\n",
      "  File \"C:\\Users\\irina\\Miniconda3\\envs\\exmc\\lib\\site-packages\\scipy\\sparse\\base.py\", line 461, in __mul__\n",
      "    M, N = self.shape\n",
      "SystemError: PyEval_EvalFrameEx returned a result with an error set\n",
      "\n",
      "During handling of the above exception, another exception occurred:\n",
      "\n",
      "Traceback (most recent call last):\n",
      "  File \"C:\\Users\\irina\\Miniconda3\\envs\\exmc\\lib\\site-packages\\scipy\\sparse\\base.py\", line 461, in __mul__\n",
      "    M, N = self.shape\n",
      "SystemError: PyEval_EvalFrameEx returned a result with an error set\n",
      "\n",
      "During handling of the above exception, another exception occurred:\n",
      "\n",
      "Traceback (most recent call last):\n",
      "  File \"C:\\Users\\irina\\Miniconda3\\envs\\exmc\\lib\\site-packages\\scipy\\sparse\\base.py\", line 461, in __mul__\n",
      "    M, N = self.shape\n",
      "SystemError: PyEval_EvalFrameEx returned a result with an error set\n",
      "\n",
      "During handling of the above exception, another exception occurred:\n",
      "\n",
      "Traceback (most recent call last):\n",
      "  File \"C:\\Users\\irina\\Miniconda3\\envs\\exmc\\lib\\site-packages\\scipy\\sparse\\base.py\", line 461, in __mul__\n",
      "    M, N = self.shape\n",
      "SystemError: PyEval_EvalFrameEx returned a result with an error set\n",
      "\n",
      "During handling of the above exception, another exception occurred:\n",
      "\n",
      "Traceback (most recent call last):\n",
      "  File \"C:\\Users\\irina\\Miniconda3\\envs\\exmc\\lib\\site-packages\\scipy\\sparse\\base.py\", line 461, in __mul__\n",
      "    M, N = self.shape\n",
      "SystemError: PyEval_EvalFrameEx returned a result with an error set\n",
      "\n",
      "During handling of the above exception, another exception occurred:\n",
      "\n",
      "Traceback (most recent call last):\n",
      "  File \"C:\\Users\\irina\\Miniconda3\\envs\\exmc\\lib\\site-packages\\scipy\\sparse\\base.py\", line 461, in __mul__\n",
      "    M, N = self.shape\n",
      "SystemError: PyEval_EvalFrameEx returned a result with an error set\n",
      "\n",
      "During handling of the above exception, another exception occurred:\n",
      "\n",
      "Traceback (most recent call last):\n",
      "  File \"C:\\Users\\irina\\Miniconda3\\envs\\exmc\\lib\\site-packages\\scipy\\sparse\\base.py\", line 461, in __mul__\n",
      "    M, N = self.shape\n",
      "SystemError: PyEval_EvalFrameEx returned a result with an error set\n",
      "\n",
      "During handling of the above exception, another exception occurred:\n",
      "\n",
      "Traceback (most recent call last):\n",
      "  File \"C:\\Users\\irina\\Miniconda3\\envs\\exmc\\lib\\site-packages\\scipy\\sparse\\base.py\", line 461, in __mul__\n",
      "    M, N = self.shape\n",
      "SystemError: PyEval_EvalFrameEx returned a result with an error set\n",
      "\n",
      "During handling of the above exception, another exception occurred:\n",
      "\n",
      "Traceback (most recent call last):\n",
      "  File \"C:\\Users\\irina\\Miniconda3\\envs\\exmc\\lib\\site-packages\\scipy\\sparse\\base.py\", line 461, in __mul__\n",
      "    M, N = self.shape\n",
      "SystemError: PyEval_EvalFrameEx returned a result with an error set\n",
      "\n",
      "During handling of the above exception, another exception occurred:\n",
      "\n",
      "Traceback (most recent call last):\n",
      "  File \"C:\\Users\\irina\\Miniconda3\\envs\\exmc\\lib\\site-packages\\scipy\\sparse\\base.py\", line 461, in __mul__\n",
      "    M, N = self.shape\n",
      "SystemError: PyEval_EvalFrameEx returned a result with an error set\n",
      "\n",
      "During handling of the above exception, another exception occurred:\n",
      "\n",
      "Traceback (most recent call last):\n",
      "  File \"C:\\Users\\irina\\Miniconda3\\envs\\exmc\\lib\\site-packages\\scipy\\sparse\\base.py\", line 461, in __mul__\n",
      "    M, N = self.shape\n",
      "SystemError: PyEval_EvalFrameEx returned a result with an error set\n",
      "\n",
      "During handling of the above exception, another exception occurred:\n",
      "\n",
      "Traceback (most recent call last):\n",
      "  File \"C:\\Users\\irina\\Miniconda3\\envs\\exmc\\lib\\site-packages\\scipy\\sparse\\base.py\", line 461, in __mul__\n",
      "    M, N = self.shape\n",
      "SystemError: PyEval_EvalFrameEx returned a result with an error set\n",
      "\n",
      "During handling of the above exception, another exception occurred:\n",
      "\n",
      "Traceback (most recent call last):\n",
      "  File \"C:\\Users\\irina\\Miniconda3\\envs\\exmc\\lib\\site-packages\\scipy\\sparse\\base.py\", line 461, in __mul__\n",
      "    M, N = self.shape\n",
      "SystemError: PyEval_EvalFrameEx returned a result with an error set\n",
      "\n",
      "During handling of the above exception, another exception occurred:\n",
      "\n",
      "Traceback (most recent call last):\n",
      "  File \"C:\\Users\\irina\\Miniconda3\\envs\\exmc\\lib\\site-packages\\scipy\\sparse\\base.py\", line 461, in __mul__\n",
      "    M, N = self.shape\n",
      "SystemError: PyEval_EvalFrameEx returned a result with an error set\n",
      "\n",
      "During handling of the above exception, another exception occurred:\n",
      "\n",
      "Traceback (most recent call last):\n",
      "  File \"C:\\Users\\irina\\Miniconda3\\envs\\exmc\\lib\\site-packages\\scipy\\sparse\\base.py\", line 461, in __mul__\n",
      "    M, N = self.shape\n",
      "SystemError: PyEval_EvalFrameEx returned a result with an error set\n",
      "\n",
      "During handling of the above exception, another exception occurred:\n",
      "\n",
      "Traceback (most recent call last):\n",
      "  File \"C:\\Users\\irina\\Miniconda3\\envs\\exmc\\lib\\site-packages\\scipy\\sparse\\base.py\", line 461, in __mul__\n",
      "    M, N = self.shape\n",
      "SystemError: PyEval_EvalFrameEx returned a result with an error set\n",
      "\n",
      "During handling of the above exception, another exception occurred:\n",
      "\n",
      "Traceback (most recent call last):\n",
      "  File \"C:\\Users\\irina\\Miniconda3\\envs\\exmc\\lib\\site-packages\\scipy\\sparse\\base.py\", line 461, in __mul__\n",
      "    M, N = self.shape\n",
      "SystemError: PyEval_EvalFrameEx returned a result with an error set\n",
      "\n",
      "During handling of the above exception, another exception occurred:\n",
      "\n",
      "Traceback (most recent call last):\n",
      "  File \"C:\\Users\\irina\\Miniconda3\\envs\\exmc\\lib\\site-packages\\scipy\\sparse\\base.py\", line 461, in __mul__\n",
      "    M, N = self.shape\n",
      "SystemError: PyEval_EvalFrameEx returned a result with an error set\n",
      "\n",
      "During handling of the above exception, another exception occurred:\n",
      "\n",
      "Traceback (most recent call last):\n",
      "  File \"C:\\Users\\irina\\Miniconda3\\envs\\exmc\\lib\\site-packages\\scipy\\sparse\\base.py\", line 461, in __mul__\n",
      "    M, N = self.shape\n",
      "SystemError: PyEval_EvalFrameEx returned a result with an error set\n",
      "\n",
      "During handling of the above exception, another exception occurred:\n",
      "\n",
      "Traceback (most recent call last):\n",
      "  File \"C:\\Users\\irina\\Miniconda3\\envs\\exmc\\lib\\site-packages\\scipy\\sparse\\base.py\", line 461, in __mul__\n",
      "    M, N = self.shape\n",
      "SystemError: PyEval_EvalFrameEx returned a result with an error set\n",
      "\n",
      "During handling of the above exception, another exception occurred:\n",
      "\n",
      "Traceback (most recent call last):\n",
      "  File \"C:\\Users\\irina\\Miniconda3\\envs\\exmc\\lib\\site-packages\\scipy\\sparse\\base.py\", line 461, in __mul__\n",
      "    M, N = self.shape\n",
      "SystemError: PyEval_EvalFrameEx returned a result with an error set\n",
      "\n",
      "During handling of the above exception, another exception occurred:\n",
      "\n",
      "Traceback (most recent call last):\n",
      "  File \"C:\\Users\\irina\\Miniconda3\\envs\\exmc\\lib\\site-packages\\scipy\\sparse\\base.py\", line 461, in __mul__\n",
      "    M, N = self.shape\n",
      "SystemError: PyEval_EvalFrameEx returned a result with an error set\n",
      "\n",
      "During handling of the above exception, another exception occurred:\n",
      "\n",
      "Traceback (most recent call last):\n",
      "  File \"C:\\Users\\irina\\Miniconda3\\envs\\exmc\\lib\\site-packages\\scipy\\sparse\\base.py\", line 461, in __mul__\n",
      "    M, N = self.shape\n",
      "SystemError: PyEval_EvalFrameEx returned a result with an error set\n",
      "\n",
      "During handling of the above exception, another exception occurred:\n",
      "\n",
      "Traceback (most recent call last):\n",
      "  File \"C:\\Users\\irina\\Miniconda3\\envs\\exmc\\lib\\site-packages\\scipy\\sparse\\base.py\", line 461, in __mul__\n",
      "    M, N = self.shape\n",
      "SystemError: PyEval_EvalFrameEx returned a result with an error set\n",
      "\n",
      "During handling of the above exception, another exception occurred:\n",
      "\n",
      "Traceback (most recent call last):\n",
      "  File \"C:\\Users\\irina\\Miniconda3\\envs\\exmc\\lib\\site-packages\\scipy\\sparse\\base.py\", line 461, in __mul__\n",
      "    M, N = self.shape\n",
      "SystemError: PyEval_EvalFrameEx returned a result with an error set\n",
      "\n",
      "During handling of the above exception, another exception occurred:\n",
      "\n",
      "Traceback (most recent call last):\n",
      "  File \"C:\\Users\\irina\\Miniconda3\\envs\\exmc\\lib\\site-packages\\scipy\\sparse\\base.py\", line 461, in __mul__\n",
      "    M, N = self.shape\n",
      "SystemError: PyEval_EvalFrameEx returned a result with an error set\n",
      "\n",
      "During handling of the above exception, another exception occurred:\n",
      "\n",
      "Traceback (most recent call last):\n",
      "  File \"C:\\Users\\irina\\Miniconda3\\envs\\exmc\\lib\\site-packages\\scipy\\sparse\\base.py\", line 461, in __mul__\n",
      "    M, N = self.shape\n",
      "SystemError: PyEval_EvalFrameEx returned a result with an error set\n",
      "\n",
      "During handling of the above exception, another exception occurred:\n",
      "\n",
      "Traceback (most recent call last):\n",
      "  File \"C:\\Users\\irina\\Miniconda3\\envs\\exmc\\lib\\site-packages\\scipy\\sparse\\base.py\", line 461, in __mul__\n",
      "    M, N = self.shape\n",
      "SystemError: PyEval_EvalFrameEx returned a result with an error set\n",
      "\n",
      "During handling of the above exception, another exception occurred:\n",
      "\n",
      "Traceback (most recent call last):\n",
      "  File \"C:\\Users\\irina\\Miniconda3\\envs\\exmc\\lib\\site-packages\\scipy\\sparse\\base.py\", line 461, in __mul__\n",
      "    M, N = self.shape\n",
      "SystemError: PyEval_EvalFrameEx returned a result with an error set\n",
      "\n",
      "During handling of the above exception, another exception occurred:\n",
      "\n",
      "Traceback (most recent call last):\n",
      "  File \"C:\\Users\\irina\\Miniconda3\\envs\\exmc\\lib\\site-packages\\scipy\\sparse\\base.py\", line 461, in __mul__\n",
      "    M, N = self.shape\n",
      "SystemError: PyEval_EvalFrameEx returned a result with an error set\n",
      "\n",
      "During handling of the above exception, another exception occurred:\n",
      "\n",
      "Traceback (most recent call last):\n",
      "  File \"C:\\Users\\irina\\Miniconda3\\envs\\exmc\\lib\\site-packages\\scipy\\sparse\\base.py\", line 461, in __mul__\n",
      "    M, N = self.shape\n",
      "SystemError: PyEval_EvalFrameEx returned a result with an error set\n",
      "\n",
      "During handling of the above exception, another exception occurred:\n",
      "\n",
      "Traceback (most recent call last):\n",
      "  File \"C:\\Users\\irina\\Miniconda3\\envs\\exmc\\lib\\site-packages\\scipy\\sparse\\base.py\", line 461, in __mul__\n",
      "    M, N = self.shape\n",
      "SystemError: PyEval_EvalFrameEx returned a result with an error set\n",
      "\n",
      "During handling of the above exception, another exception occurred:\n",
      "\n",
      "Traceback (most recent call last):\n",
      "  File \"C:\\Users\\irina\\Miniconda3\\envs\\exmc\\lib\\site-packages\\scipy\\sparse\\base.py\", line 461, in __mul__\n",
      "    M, N = self.shape\n",
      "SystemError: PyEval_EvalFrameEx returned a result with an error set\n",
      "\n",
      "During handling of the above exception, another exception occurred:\n",
      "\n",
      "Traceback (most recent call last):\n",
      "  File \"C:\\Users\\irina\\Miniconda3\\envs\\exmc\\lib\\site-packages\\scipy\\sparse\\base.py\", line 461, in __mul__\n",
      "    M, N = self.shape\n",
      "SystemError: PyEval_EvalFrameEx returned a result with an error set\n",
      "\n",
      "During handling of the above exception, another exception occurred:\n",
      "\n",
      "Traceback (most recent call last):\n",
      "  File \"C:\\Users\\irina\\Miniconda3\\envs\\exmc\\lib\\site-packages\\scipy\\sparse\\base.py\", line 461, in __mul__\n",
      "    M, N = self.shape\n",
      "SystemError: PyEval_EvalFrameEx returned a result with an error set\n",
      "\n",
      "During handling of the above exception, another exception occurred:\n",
      "\n",
      "Traceback (most recent call last):\n",
      "  File \"C:\\Users\\irina\\Miniconda3\\envs\\exmc\\lib\\site-packages\\scipy\\sparse\\base.py\", line 461, in __mul__\n",
      "    M, N = self.shape\n",
      "SystemError: PyEval_EvalFrameEx returned a result with an error set\n",
      "\n",
      "During handling of the above exception, another exception occurred:\n",
      "\n",
      "Traceback (most recent call last):\n",
      "  File \"C:\\Users\\irina\\Miniconda3\\envs\\exmc\\lib\\site-packages\\scipy\\sparse\\base.py\", line 461, in __mul__\n",
      "    M, N = self.shape\n",
      "SystemError: PyEval_EvalFrameEx returned a result with an error set\n",
      "\n",
      "During handling of the above exception, another exception occurred:\n",
      "\n",
      "Traceback (most recent call last):\n",
      "  File \"C:\\Users\\irina\\Miniconda3\\envs\\exmc\\lib\\site-packages\\scipy\\sparse\\base.py\", line 461, in __mul__\n",
      "    M, N = self.shape\n",
      "SystemError: PyEval_EvalFrameEx returned a result with an error set\n",
      "\n",
      "During handling of the above exception, another exception occurred:\n",
      "\n",
      "Traceback (most recent call last):\n",
      "  File \"C:\\Users\\irina\\Miniconda3\\envs\\exmc\\lib\\site-packages\\scipy\\sparse\\base.py\", line 461, in __mul__\n",
      "    M, N = self.shape\n",
      "SystemError: PyEval_EvalFrameEx returned a result with an error set\n",
      "\n",
      "During handling of the above exception, another exception occurred:\n",
      "\n",
      "Traceback (most recent call last):\n",
      "  File \"C:\\Users\\irina\\Miniconda3\\envs\\exmc\\lib\\site-packages\\scipy\\sparse\\base.py\", line 461, in __mul__\n",
      "    M, N = self.shape\n",
      "SystemError: PyEval_EvalFrameEx returned a result with an error set\n",
      "\n",
      "During handling of the above exception, another exception occurred:\n",
      "\n",
      "Traceback (most recent call last):\n",
      "  File \"C:\\Users\\irina\\Miniconda3\\envs\\exmc\\lib\\site-packages\\scipy\\sparse\\base.py\", line 461, in __mul__\n",
      "    M, N = self.shape\n",
      "SystemError: PyEval_EvalFrameEx returned a result with an error set\n",
      "\n",
      "During handling of the above exception, another exception occurred:\n",
      "\n",
      "Traceback (most recent call last):\n",
      "  File \"C:\\Users\\irina\\Miniconda3\\envs\\exmc\\lib\\site-packages\\scipy\\sparse\\base.py\", line 461, in __mul__\n",
      "    M, N = self.shape\n",
      "SystemError: PyEval_EvalFrameEx returned a result with an error set\n",
      "\n",
      "During handling of the above exception, another exception occurred:\n",
      "\n",
      "Traceback (most recent call last):\n",
      "  File \"C:\\Users\\irina\\Miniconda3\\envs\\exmc\\lib\\site-packages\\scipy\\sparse\\base.py\", line 461, in __mul__\n",
      "    M, N = self.shape\n",
      "SystemError: PyEval_EvalFrameEx returned a result with an error set\n",
      "\n",
      "During handling of the above exception, another exception occurred:\n",
      "\n",
      "Traceback (most recent call last):\n",
      "  File \"C:\\Users\\irina\\Miniconda3\\envs\\exmc\\lib\\site-packages\\scipy\\sparse\\base.py\", line 461, in __mul__\n",
      "    M, N = self.shape\n",
      "SystemError: PyEval_EvalFrameEx returned a result with an error set\n",
      "\n",
      "During handling of the above exception, another exception occurred:\n",
      "\n",
      "Traceback (most recent call last):\n",
      "  File \"C:\\Users\\irina\\Miniconda3\\envs\\exmc\\lib\\site-packages\\scipy\\sparse\\base.py\", line 461, in __mul__\n",
      "    M, N = self.shape\n",
      "SystemError: PyEval_EvalFrameEx returned a result with an error set\n",
      "\n",
      "During handling of the above exception, another exception occurred:\n",
      "\n",
      "Traceback (most recent call last):\n",
      "  File \"C:\\Users\\irina\\Miniconda3\\envs\\exmc\\lib\\site-packages\\scipy\\sparse\\base.py\", line 461, in __mul__\n",
      "    M, N = self.shape\n",
      "SystemError: PyEval_EvalFrameEx returned a result with an error set\n",
      "\n",
      "During handling of the above exception, another exception occurred:\n",
      "\n",
      "Traceback (most recent call last):\n",
      "  File \"C:\\Users\\irina\\Miniconda3\\envs\\exmc\\lib\\site-packages\\scipy\\sparse\\base.py\", line 461, in __mul__\n",
      "    M, N = self.shape\n",
      "SystemError: PyEval_EvalFrameEx returned a result with an error set\n",
      "\n",
      "During handling of the above exception, another exception occurred:\n",
      "\n",
      "Traceback (most recent call last):\n",
      "  File \"C:\\Users\\irina\\Miniconda3\\envs\\exmc\\lib\\site-packages\\scipy\\sparse\\base.py\", line 461, in __mul__\n",
      "    M, N = self.shape\n",
      "SystemError: PyEval_EvalFrameEx returned a result with an error set\n",
      "\n",
      "During handling of the above exception, another exception occurred:\n",
      "\n",
      "Traceback (most recent call last):\n",
      "  File \"C:\\Users\\irina\\Miniconda3\\envs\\exmc\\lib\\site-packages\\scipy\\sparse\\base.py\", line 461, in __mul__\n",
      "    M, N = self.shape\n",
      "SystemError: PyEval_EvalFrameEx returned a result with an error set\n",
      "\n",
      "During handling of the above exception, another exception occurred:\n",
      "\n",
      "Traceback (most recent call last):\n",
      "  File \"C:\\Users\\irina\\Miniconda3\\envs\\exmc\\lib\\site-packages\\scipy\\sparse\\base.py\", line 461, in __mul__\n",
      "    M, N = self.shape\n",
      "SystemError: PyEval_EvalFrameEx returned a result with an error set\n",
      "\n",
      "During handling of the above exception, another exception occurred:\n",
      "\n",
      "Traceback (most recent call last):\n",
      "  File \"C:\\Users\\irina\\Miniconda3\\envs\\exmc\\lib\\site-packages\\scipy\\sparse\\base.py\", line 461, in __mul__\n",
      "    M, N = self.shape\n",
      "SystemError: PyEval_EvalFrameEx returned a result with an error set\n",
      "\n",
      "During handling of the above exception, another exception occurred:\n",
      "\n",
      "Traceback (most recent call last):\n",
      "  File \"C:\\Users\\irina\\Miniconda3\\envs\\exmc\\lib\\site-packages\\scipy\\sparse\\base.py\", line 461, in __mul__\n",
      "    M, N = self.shape\n",
      "SystemError: PyEval_EvalFrameEx returned a result with an error set\n",
      "\n",
      "During handling of the above exception, another exception occurred:\n",
      "\n",
      "Traceback (most recent call last):\n",
      "  File \"C:\\Users\\irina\\Miniconda3\\envs\\exmc\\lib\\site-packages\\scipy\\sparse\\base.py\", line 461, in __mul__\n",
      "    M, N = self.shape\n",
      "SystemError: PyEval_EvalFrameEx returned a result with an error set\n",
      "\n",
      "During handling of the above exception, another exception occurred:\n",
      "\n",
      "Traceback (most recent call last):\n",
      "  File \"C:\\Users\\irina\\Miniconda3\\envs\\exmc\\lib\\site-packages\\scipy\\sparse\\base.py\", line 461, in __mul__\n",
      "    M, N = self.shape\n",
      "SystemError: PyEval_EvalFrameEx returned a result with an error set\n",
      "\n",
      "During handling of the above exception, another exception occurred:\n",
      "\n",
      "Traceback (most recent call last):\n",
      "  File \"C:\\Users\\irina\\Miniconda3\\envs\\exmc\\lib\\site-packages\\scipy\\sparse\\base.py\", line 461, in __mul__\n",
      "    M, N = self.shape\n",
      "SystemError: PyEval_EvalFrameEx returned a result with an error set\n",
      "\n",
      "During handling of the above exception, another exception occurred:\n",
      "\n",
      "Traceback (most recent call last):\n",
      "  File \"C:\\Users\\irina\\Miniconda3\\envs\\exmc\\lib\\site-packages\\scipy\\sparse\\base.py\", line 461, in __mul__\n",
      "    M, N = self.shape\n",
      "SystemError: PyEval_EvalFrameEx returned a result with an error set\n",
      "\n",
      "During handling of the above exception, another exception occurred:\n",
      "\n",
      "Traceback (most recent call last):\n",
      "  File \"C:\\Users\\irina\\Miniconda3\\envs\\exmc\\lib\\site-packages\\scipy\\sparse\\base.py\", line 461, in __mul__\n",
      "    M, N = self.shape\n",
      "SystemError: PyEval_EvalFrameEx returned a result with an error set\n",
      "\n",
      "During handling of the above exception, another exception occurred:\n",
      "\n",
      "Traceback (most recent call last):\n",
      "  File \"C:\\Users\\irina\\Miniconda3\\envs\\exmc\\lib\\site-packages\\scipy\\sparse\\base.py\", line 461, in __mul__\n",
      "    M, N = self.shape\n",
      "SystemError: PyEval_EvalFrameEx returned a result with an error set\n",
      "\n",
      "During handling of the above exception, another exception occurred:\n",
      "\n",
      "Traceback (most recent call last):\n",
      "  File \"C:\\Users\\irina\\Miniconda3\\envs\\exmc\\lib\\site-packages\\scipy\\sparse\\base.py\", line 461, in __mul__\n",
      "    M, N = self.shape\n",
      "SystemError: PyEval_EvalFrameEx returned a result with an error set\n",
      "\n",
      "During handling of the above exception, another exception occurred:\n",
      "\n",
      "Traceback (most recent call last):\n",
      "  File \"C:\\Users\\irina\\Miniconda3\\envs\\exmc\\lib\\site-packages\\scipy\\sparse\\base.py\", line 461, in __mul__\n",
      "    M, N = self.shape\n",
      "SystemError: PyEval_EvalFrameEx returned a result with an error set\n",
      "\n",
      "During handling of the above exception, another exception occurred:\n",
      "\n",
      "Traceback (most recent call last):\n",
      "  File \"C:\\Users\\irina\\Miniconda3\\envs\\exmc\\lib\\site-packages\\scipy\\sparse\\base.py\", line 461, in __mul__\n",
      "    M, N = self.shape\n",
      "SystemError: PyEval_EvalFrameEx returned a result with an error set\n",
      "\n",
      "During handling of the above exception, another exception occurred:\n",
      "\n",
      "Traceback (most recent call last):\n",
      "  File \"C:\\Users\\irina\\Miniconda3\\envs\\exmc\\lib\\site-packages\\scipy\\sparse\\base.py\", line 461, in __mul__\n",
      "    M, N = self.shape\n",
      "SystemError: PyEval_EvalFrameEx returned a result with an error set\n",
      "\n",
      "During handling of the above exception, another exception occurred:\n",
      "\n",
      "Traceback (most recent call last):\n",
      "  File \"C:\\Users\\irina\\Miniconda3\\envs\\exmc\\lib\\site-packages\\scipy\\sparse\\base.py\", line 461, in __mul__\n",
      "    M, N = self.shape\n",
      "SystemError: PyEval_EvalFrameEx returned a result with an error set\n",
      "\n",
      "During handling of the above exception, another exception occurred:\n",
      "\n",
      "Traceback (most recent call last):\n",
      "  File \"C:\\Users\\irina\\Miniconda3\\envs\\exmc\\lib\\site-packages\\scipy\\sparse\\base.py\", line 461, in __mul__\n",
      "    M, N = self.shape\n",
      "SystemError: PyEval_EvalFrameEx returned a result with an error set\n",
      "\n",
      "During handling of the above exception, another exception occurred:\n",
      "\n",
      "Traceback (most recent call last):\n",
      "  File \"C:\\Users\\irina\\Miniconda3\\envs\\exmc\\lib\\site-packages\\scipy\\sparse\\base.py\", line 461, in __mul__\n",
      "    M, N = self.shape\n",
      "SystemError: PyEval_EvalFrameEx returned a result with an error set\n",
      "\n",
      "During handling of the above exception, another exception occurred:\n",
      "\n",
      "Traceback (most recent call last):\n",
      "  File \"C:\\Users\\irina\\Miniconda3\\envs\\exmc\\lib\\site-packages\\scipy\\sparse\\base.py\", line 461, in __mul__\n",
      "    M, N = self.shape\n",
      "SystemError: PyEval_EvalFrameEx returned a result with an error set\n",
      "\n",
      "During handling of the above exception, another exception occurred:\n",
      "\n",
      "Traceback (most recent call last):\n",
      "  File \"C:\\Users\\irina\\Miniconda3\\envs\\exmc\\lib\\site-packages\\scipy\\sparse\\base.py\", line 461, in __mul__\n",
      "    M, N = self.shape\n",
      "SystemError: PyEval_EvalFrameEx returned a result with an error set\n",
      "\n",
      "During handling of the above exception, another exception occurred:\n",
      "\n",
      "Traceback (most recent call last):\n",
      "  File \"C:\\Users\\irina\\Miniconda3\\envs\\exmc\\lib\\site-packages\\scipy\\sparse\\base.py\", line 461, in __mul__\n",
      "    M, N = self.shape\n",
      "SystemError: PyEval_EvalFrameEx returned a result with an error set\n",
      "\n",
      "During handling of the above exception, another exception occurred:\n",
      "\n",
      "Traceback (most recent call last):\n",
      "  File \"C:\\Users\\irina\\Miniconda3\\envs\\exmc\\lib\\site-packages\\scipy\\sparse\\base.py\", line 461, in __mul__\n",
      "    M, N = self.shape\n",
      "SystemError: PyEval_EvalFrameEx returned a result with an error set\n",
      "\n",
      "During handling of the above exception, another exception occurred:\n",
      "\n",
      "Traceback (most recent call last):\n",
      "  File \"C:\\Users\\irina\\Miniconda3\\envs\\exmc\\lib\\site-packages\\scipy\\sparse\\base.py\", line 461, in __mul__\n",
      "    M, N = self.shape\n",
      "SystemError: PyEval_EvalFrameEx returned a result with an error set\n",
      "\n",
      "During handling of the above exception, another exception occurred:\n",
      "\n",
      "Traceback (most recent call last):\n",
      "  File \"C:\\Users\\irina\\Miniconda3\\envs\\exmc\\lib\\site-packages\\scipy\\sparse\\base.py\", line 461, in __mul__\n",
      "    M, N = self.shape\n",
      "SystemError: PyEval_EvalFrameEx returned a result with an error set\n",
      "\n",
      "During handling of the above exception, another exception occurred:\n",
      "\n",
      "Traceback (most recent call last):\n",
      "  File \"C:\\Users\\irina\\Miniconda3\\envs\\exmc\\lib\\site-packages\\scipy\\sparse\\base.py\", line 461, in __mul__\n",
      "    M, N = self.shape\n",
      "SystemError: PyEval_EvalFrameEx returned a result with an error set\n",
      "\n",
      "During handling of the above exception, another exception occurred:\n",
      "\n",
      "Traceback (most recent call last):\n",
      "  File \"C:\\Users\\irina\\Miniconda3\\envs\\exmc\\lib\\site-packages\\scipy\\sparse\\base.py\", line 461, in __mul__\n",
      "    M, N = self.shape\n",
      "SystemError: PyEval_EvalFrameEx returned a result with an error set\n",
      "\n",
      "During handling of the above exception, another exception occurred:\n",
      "\n",
      "Traceback (most recent call last):\n",
      "  File \"C:\\Users\\irina\\Miniconda3\\envs\\exmc\\lib\\site-packages\\scipy\\sparse\\base.py\", line 461, in __mul__\n",
      "    M, N = self.shape\n",
      "SystemError: PyEval_EvalFrameEx returned a result with an error set\n",
      "\n",
      "During handling of the above exception, another exception occurred:\n",
      "\n",
      "Traceback (most recent call last):\n",
      "  File \"C:\\Users\\irina\\Miniconda3\\envs\\exmc\\lib\\site-packages\\scipy\\sparse\\base.py\", line 461, in __mul__\n",
      "    M, N = self.shape\n",
      "SystemError: PyEval_EvalFrameEx returned a result with an error set\n",
      "\n",
      "During handling of the above exception, another exception occurred:\n",
      "\n",
      "Traceback (most recent call last):\n",
      "  File \"C:\\Users\\irina\\Miniconda3\\envs\\exmc\\lib\\site-packages\\scipy\\sparse\\base.py\", line 461, in __mul__\n",
      "    M, N = self.shape\n",
      "SystemError: PyEval_EvalFrameEx returned a result with an error set\n",
      "\n",
      "During handling of the above exception, another exception occurred:\n",
      "\n",
      "Traceback (most recent call last):\n",
      "  File \"C:\\Users\\irina\\Miniconda3\\envs\\exmc\\lib\\site-packages\\scipy\\sparse\\base.py\", line 461, in __mul__\n",
      "    M, N = self.shape\n",
      "SystemError: PyEval_EvalFrameEx returned a result with an error set\n",
      "\n",
      "During handling of the above exception, another exception occurred:\n",
      "\n",
      "Traceback (most recent call last):\n",
      "  File \"C:\\Users\\irina\\Miniconda3\\envs\\exmc\\lib\\site-packages\\scipy\\sparse\\base.py\", line 461, in __mul__\n",
      "    M, N = self.shape\n",
      "SystemError: PyEval_EvalFrameEx returned a result with an error set\n",
      "\n",
      "During handling of the above exception, another exception occurred:\n",
      "\n",
      "Traceback (most recent call last):\n",
      "  File \"C:\\Users\\irina\\Miniconda3\\envs\\exmc\\lib\\site-packages\\scipy\\sparse\\base.py\", line 461, in __mul__\n",
      "    M, N = self.shape\n",
      "SystemError: PyEval_EvalFrameEx returned a result with an error set\n",
      "\n",
      "During handling of the above exception, another exception occurred:\n",
      "\n",
      "Traceback (most recent call last):\n",
      "  File \"C:\\Users\\irina\\Miniconda3\\envs\\exmc\\lib\\site-packages\\scipy\\sparse\\base.py\", line 461, in __mul__\n",
      "    M, N = self.shape\n",
      "SystemError: PyEval_EvalFrameEx returned a result with an error set\n",
      "\n",
      "During handling of the above exception, another exception occurred:\n",
      "\n",
      "Traceback (most recent call last):\n",
      "  File \"C:\\Users\\irina\\Miniconda3\\envs\\exmc\\lib\\site-packages\\scipy\\sparse\\base.py\", line 461, in __mul__\n",
      "    M, N = self.shape\n",
      "SystemError: PyEval_EvalFrameEx returned a result with an error set\n",
      "\n",
      "During handling of the above exception, another exception occurred:\n",
      "\n",
      "Traceback (most recent call last):\n",
      "  File \"C:\\Users\\irina\\Miniconda3\\envs\\exmc\\lib\\site-packages\\scipy\\sparse\\base.py\", line 461, in __mul__\n",
      "    M, N = self.shape\n",
      "SystemError: PyEval_EvalFrameEx returned a result with an error set\n",
      "\n",
      "During handling of the above exception, another exception occurred:\n",
      "\n",
      "Traceback (most recent call last):\n",
      "  File \"C:\\Users\\irina\\Miniconda3\\envs\\exmc\\lib\\site-packages\\scipy\\sparse\\base.py\", line 461, in __mul__\n",
      "    M, N = self.shape\n",
      "SystemError: PyEval_EvalFrameEx returned a result with an error set\n",
      "\n",
      "During handling of the above exception, another exception occurred:\n",
      "\n",
      "Traceback (most recent call last):\n",
      "  File \"C:\\Users\\irina\\Miniconda3\\envs\\exmc\\lib\\site-packages\\scipy\\sparse\\base.py\", line 461, in __mul__\n",
      "    M, N = self.shape\n",
      "SystemError: PyEval_EvalFrameEx returned a result with an error set\n",
      "\n",
      "During handling of the above exception, another exception occurred:\n",
      "\n",
      "Traceback (most recent call last):\n",
      "  File \"C:\\Users\\irina\\Miniconda3\\envs\\exmc\\lib\\site-packages\\scipy\\sparse\\base.py\", line 461, in __mul__\n",
      "    M, N = self.shape\n",
      "SystemError: PyEval_EvalFrameEx returned a result with an error set\n",
      "\n",
      "During handling of the above exception, another exception occurred:\n",
      "\n",
      "Traceback (most recent call last):\n",
      "  File \"C:\\Users\\irina\\Miniconda3\\envs\\exmc\\lib\\site-packages\\scipy\\sparse\\base.py\", line 461, in __mul__\n",
      "    M, N = self.shape\n",
      "SystemError: PyEval_EvalFrameEx returned a result with an error set\n",
      "\n",
      "During handling of the above exception, another exception occurred:\n",
      "\n",
      "Traceback (most recent call last):\n",
      "  File \"C:\\Users\\irina\\Miniconda3\\envs\\exmc\\lib\\site-packages\\scipy\\sparse\\base.py\", line 461, in __mul__\n",
      "    M, N = self.shape\n",
      "SystemError: PyEval_EvalFrameEx returned a result with an error set\n",
      "\n",
      "During handling of the above exception, another exception occurred:\n",
      "\n",
      "Traceback (most recent call last):\n",
      "  File \"C:\\Users\\irina\\Miniconda3\\envs\\exmc\\lib\\site-packages\\scipy\\sparse\\base.py\", line 461, in __mul__\n",
      "    M, N = self.shape\n",
      "SystemError: PyEval_EvalFrameEx returned a result with an error set\n",
      "\n",
      "During handling of the above exception, another exception occurred:\n",
      "\n",
      "Traceback (most recent call last):\n",
      "  File \"C:\\Users\\irina\\Miniconda3\\envs\\exmc\\lib\\site-packages\\scipy\\sparse\\base.py\", line 461, in __mul__\n",
      "    M, N = self.shape\n",
      "SystemError: PyEval_EvalFrameEx returned a result with an error set\n",
      "\n",
      "During handling of the above exception, another exception occurred:\n",
      "\n",
      "Traceback (most recent call last):\n",
      "  File \"C:\\Users\\irina\\Miniconda3\\envs\\exmc\\lib\\site-packages\\scipy\\sparse\\base.py\", line 461, in __mul__\n",
      "    M, N = self.shape\n",
      "SystemError: PyEval_EvalFrameEx returned a result with an error set\n",
      "\n",
      "During handling of the above exception, another exception occurred:\n",
      "\n",
      "Traceback (most recent call last):\n",
      "  File \"C:\\Users\\irina\\Miniconda3\\envs\\exmc\\lib\\site-packages\\scipy\\sparse\\base.py\", line 461, in __mul__\n",
      "    M, N = self.shape\n",
      "SystemError: PyEval_EvalFrameEx returned a result with an error set\n",
      "\n",
      "During handling of the above exception, another exception occurred:\n",
      "\n",
      "Traceback (most recent call last):\n",
      "  File \"C:\\Users\\irina\\Miniconda3\\envs\\exmc\\lib\\site-packages\\scipy\\sparse\\base.py\", line 461, in __mul__\n",
      "    M, N = self.shape\n",
      "SystemError: PyEval_EvalFrameEx returned a result with an error set\n",
      "\n",
      "During handling of the above exception, another exception occurred:\n",
      "\n",
      "Traceback (most recent call last):\n",
      "  File \"C:\\Users\\irina\\Miniconda3\\envs\\exmc\\lib\\site-packages\\scipy\\sparse\\base.py\", line 461, in __mul__\n",
      "    M, N = self.shape\n",
      "SystemError: PyEval_EvalFrameEx returned a result with an error set\n",
      "\n",
      "During handling of the above exception, another exception occurred:\n",
      "\n",
      "Traceback (most recent call last):\n",
      "  File \"C:\\Users\\irina\\Miniconda3\\envs\\exmc\\lib\\site-packages\\scipy\\sparse\\base.py\", line 461, in __mul__\n",
      "    M, N = self.shape\n",
      "SystemError: PyEval_EvalFrameEx returned a result with an error set\n",
      "\n",
      "During handling of the above exception, another exception occurred:\n",
      "\n",
      "Traceback (most recent call last):\n",
      "  File \"C:\\Users\\irina\\Miniconda3\\envs\\exmc\\lib\\site-packages\\IPython\\core\\interactiveshell.py\", line 2869, in run_code\n",
      "    exec(code_obj, self.user_global_ns, self.user_ns)\n",
      "  File \"<ipython-input-21-bd35159c1e37>\", line 1, in <module>\n",
      "    X_train_noised = add_noise(X_train , 0.3)\n",
      "  File \"<ipython-input-19-64159d24f078>\", line 7, in add_noise\n",
      "    x = np.multiply(x, mask_)\n",
      "  File \"C:\\Users\\irina\\Miniconda3\\envs\\exmc\\lib\\site-packages\\scipy\\sparse\\base.py\", line 461, in __mul__\n",
      "    M, N = self.shape\n",
      "SystemError: PyEval_EvalFrameEx returned a result with an error set\n",
      "\n",
      "During handling of the above exception, another exception occurred:\n",
      "\n",
      "Traceback (most recent call last):\n",
      "  File \"C:\\Users\\irina\\Miniconda3\\envs\\exmc\\lib\\site-packages\\IPython\\core\\interactiveshell.py\", line 2872, in run_code\n",
      "    sys.excepthook = old_excepthook\n",
      "KeyboardInterrupt\n",
      "\n",
      "During handling of the above exception, another exception occurred:\n",
      "\n",
      "Traceback (most recent call last):\n",
      "  File \"C:\\Users\\irina\\Miniconda3\\envs\\exmc\\lib\\site-packages\\IPython\\core\\interactiveshell.py\", line 2809, in run_ast_nodes\n",
      "    if self.run_code(code, result):\n",
      "  File \"C:\\Users\\irina\\Miniconda3\\envs\\exmc\\lib\\site-packages\\IPython\\core\\interactiveshell.py\", line 2873, in run_code\n",
      "    except SystemExit as e:\n",
      "KeyboardInterrupt\n",
      "\n",
      "During handling of the above exception, another exception occurred:\n",
      "\n",
      "Traceback (most recent call last):\n",
      "  File \"C:\\Users\\irina\\Miniconda3\\envs\\exmc\\lib\\site-packages\\IPython\\core\\interactiveshell.py\", line 1809, in showtraceback\n",
      "    stb = value._render_traceback_()\n",
      "AttributeError: 'KeyboardInterrupt' object has no attribute '_render_traceback_'\n",
      "\n",
      "During handling of the above exception, another exception occurred:\n",
      "\n",
      "Traceback (most recent call last):\n",
      "  File \"C:\\Users\\irina\\Miniconda3\\envs\\exmc\\lib\\site-packages\\IPython\\core\\ultratb.py\", line 1132, in get_records\n",
      "    return _fixed_getinnerframes(etb, number_of_lines_of_context, tb_offset)\n",
      "  File \"C:\\Users\\irina\\Miniconda3\\envs\\exmc\\lib\\site-packages\\IPython\\core\\ultratb.py\", line 313, in wrapped\n",
      "    return f(*args, **kwargs)\n",
      "  File \"C:\\Users\\irina\\Miniconda3\\envs\\exmc\\lib\\site-packages\\IPython\\core\\ultratb.py\", line 358, in _fixed_getinnerframes\n",
      "    records = fix_frame_records_filenames(inspect.getinnerframes(etb, context))\n",
      "  File \"C:\\Users\\irina\\Miniconda3\\envs\\exmc\\lib\\inspect.py\", line 1459, in getinnerframes\n",
      "    frameinfo = (tb.tb_frame,) + getframeinfo(tb, context)\n",
      "  File \"C:\\Users\\irina\\Miniconda3\\envs\\exmc\\lib\\inspect.py\", line 1421, in getframeinfo\n",
      "    lines, lnum = findsource(frame)\n",
      "  File \"C:\\Users\\irina\\Miniconda3\\envs\\exmc\\lib\\site-packages\\IPython\\core\\ultratb.py\", line 182, in findsource\n",
      "    lines = linecache.getlines(file, globals_dict)\n",
      "  File \"C:\\Users\\irina\\Miniconda3\\envs\\exmc\\lib\\linecache.py\", line 47, in getlines\n",
      "    return updatecache(filename, module_globals)\n",
      "  File \"C:\\Users\\irina\\Miniconda3\\envs\\exmc\\lib\\linecache.py\", line 137, in updatecache\n",
      "    lines = fp.readlines()\n",
      "  File \"C:\\Users\\irina\\Miniconda3\\envs\\exmc\\lib\\codecs.py\", line 318, in decode\n",
      "    def decode(self, input, final=False):\n",
      "KeyboardInterrupt\n"
     ]
    },
    {
     "ename": "KeyboardInterrupt",
     "evalue": "",
     "output_type": "error",
     "traceback": [
      "\u001b[0;31m---------------------------------------------------------------------------\u001b[0m",
      "\u001b[0;31mKeyboardInterrupt\u001b[0m                         Traceback (most recent call last)",
      "\u001b[0;32mC:\\Users\\irina\\Miniconda3\\envs\\exmc\\lib\\site-packages\\scipy\\sparse\\base.py\u001b[0m in \u001b[0;36m__mul__\u001b[0;34m(self, other)\u001b[0m\n\u001b[1;32m    460\u001b[0m \u001b[0;34m\u001b[0m\u001b[0m\n\u001b[0;32m--> 461\u001b[0;31m         \u001b[0mM\u001b[0m\u001b[0;34m,\u001b[0m \u001b[0mN\u001b[0m \u001b[0;34m=\u001b[0m \u001b[0mself\u001b[0m\u001b[0;34m.\u001b[0m\u001b[0mshape\u001b[0m\u001b[0;34m\u001b[0m\u001b[0m\n\u001b[0m\u001b[1;32m    462\u001b[0m \u001b[0;34m\u001b[0m\u001b[0m\n",
      "\u001b[0;32mC:\\Users\\irina\\Miniconda3\\envs\\exmc\\lib\\site-packages\\scipy\\sparse\\base.py\u001b[0m in \u001b[0;36mget_shape\u001b[0;34m(self)\u001b[0m\n\u001b[1;32m     85\u001b[0m \u001b[0;34m\u001b[0m\u001b[0m\n\u001b[0;32m---> 86\u001b[0;31m     \u001b[0;32mdef\u001b[0m \u001b[0mget_shape\u001b[0m\u001b[0;34m(\u001b[0m\u001b[0mself\u001b[0m\u001b[0;34m)\u001b[0m\u001b[0;34m:\u001b[0m\u001b[0;34m\u001b[0m\u001b[0m\n\u001b[0m\u001b[1;32m     87\u001b[0m         \u001b[0;34m\"\"\"Get shape of a matrix.\"\"\"\u001b[0m\u001b[0;34m\u001b[0m\u001b[0m\n",
      "\u001b[0;31mKeyboardInterrupt\u001b[0m: ",
      "\nDuring handling of the above exception, another exception occurred:\n",
      "\u001b[0;31mSystemError\u001b[0m                               Traceback (most recent call last)",
      "\u001b[0;32mC:\\Users\\irina\\Miniconda3\\envs\\exmc\\lib\\site-packages\\scipy\\sparse\\base.py\u001b[0m in \u001b[0;36m__mul__\u001b[0;34m(self, other)\u001b[0m\n\u001b[1;32m    460\u001b[0m \u001b[0;34m\u001b[0m\u001b[0m\n\u001b[0;32m--> 461\u001b[0;31m         \u001b[0mM\u001b[0m\u001b[0;34m,\u001b[0m \u001b[0mN\u001b[0m \u001b[0;34m=\u001b[0m \u001b[0mself\u001b[0m\u001b[0;34m.\u001b[0m\u001b[0mshape\u001b[0m\u001b[0;34m\u001b[0m\u001b[0m\n\u001b[0m\u001b[1;32m    462\u001b[0m \u001b[0;34m\u001b[0m\u001b[0m\n",
      "\u001b[0;31mSystemError\u001b[0m: PyEval_EvalFrameEx returned a result with an error set",
      "\nDuring handling of the above exception, another exception occurred:\n",
      "\u001b[0;31mSystemError\u001b[0m                               Traceback (most recent call last)",
      "\u001b[0;32mC:\\Users\\irina\\Miniconda3\\envs\\exmc\\lib\\site-packages\\scipy\\sparse\\base.py\u001b[0m in \u001b[0;36m__mul__\u001b[0;34m(self, other)\u001b[0m\n\u001b[1;32m    460\u001b[0m \u001b[0;34m\u001b[0m\u001b[0m\n\u001b[0;32m--> 461\u001b[0;31m         \u001b[0mM\u001b[0m\u001b[0;34m,\u001b[0m \u001b[0mN\u001b[0m \u001b[0;34m=\u001b[0m \u001b[0mself\u001b[0m\u001b[0;34m.\u001b[0m\u001b[0mshape\u001b[0m\u001b[0;34m\u001b[0m\u001b[0m\n\u001b[0m\u001b[1;32m    462\u001b[0m \u001b[0;34m\u001b[0m\u001b[0m\n",
      "\u001b[0;31mSystemError\u001b[0m: PyEval_EvalFrameEx returned a result with an error set",
      "\nDuring handling of the above exception, another exception occurred:\n",
      "\u001b[0;31mSystemError\u001b[0m                               Traceback (most recent call last)",
      "\u001b[0;32mC:\\Users\\irina\\Miniconda3\\envs\\exmc\\lib\\site-packages\\scipy\\sparse\\base.py\u001b[0m in \u001b[0;36m__mul__\u001b[0;34m(self, other)\u001b[0m\n\u001b[1;32m    460\u001b[0m \u001b[0;34m\u001b[0m\u001b[0m\n\u001b[0;32m--> 461\u001b[0;31m         \u001b[0mM\u001b[0m\u001b[0;34m,\u001b[0m \u001b[0mN\u001b[0m \u001b[0;34m=\u001b[0m \u001b[0mself\u001b[0m\u001b[0;34m.\u001b[0m\u001b[0mshape\u001b[0m\u001b[0;34m\u001b[0m\u001b[0m\n\u001b[0m\u001b[1;32m    462\u001b[0m \u001b[0;34m\u001b[0m\u001b[0m\n",
      "\u001b[0;31mSystemError\u001b[0m: PyEval_EvalFrameEx returned a result with an error set",
      "\nDuring handling of the above exception, another exception occurred:\n",
      "\u001b[0;31mSystemError\u001b[0m                               Traceback (most recent call last)",
      "\u001b[0;32mC:\\Users\\irina\\Miniconda3\\envs\\exmc\\lib\\site-packages\\scipy\\sparse\\base.py\u001b[0m in \u001b[0;36m__mul__\u001b[0;34m(self, other)\u001b[0m\n\u001b[1;32m    460\u001b[0m \u001b[0;34m\u001b[0m\u001b[0m\n\u001b[0;32m--> 461\u001b[0;31m         \u001b[0mM\u001b[0m\u001b[0;34m,\u001b[0m \u001b[0mN\u001b[0m \u001b[0;34m=\u001b[0m \u001b[0mself\u001b[0m\u001b[0;34m.\u001b[0m\u001b[0mshape\u001b[0m\u001b[0;34m\u001b[0m\u001b[0m\n\u001b[0m\u001b[1;32m    462\u001b[0m \u001b[0;34m\u001b[0m\u001b[0m\n",
      "\u001b[0;31mSystemError\u001b[0m: PyEval_EvalFrameEx returned a result with an error set",
      "\nDuring handling of the above exception, another exception occurred:\n",
      "\u001b[0;31mSystemError\u001b[0m                               Traceback (most recent call last)",
      "\u001b[0;32mC:\\Users\\irina\\Miniconda3\\envs\\exmc\\lib\\site-packages\\scipy\\sparse\\base.py\u001b[0m in \u001b[0;36m__mul__\u001b[0;34m(self, other)\u001b[0m\n\u001b[1;32m    460\u001b[0m \u001b[0;34m\u001b[0m\u001b[0m\n\u001b[0;32m--> 461\u001b[0;31m         \u001b[0mM\u001b[0m\u001b[0;34m,\u001b[0m \u001b[0mN\u001b[0m \u001b[0;34m=\u001b[0m \u001b[0mself\u001b[0m\u001b[0;34m.\u001b[0m\u001b[0mshape\u001b[0m\u001b[0;34m\u001b[0m\u001b[0m\n\u001b[0m\u001b[1;32m    462\u001b[0m \u001b[0;34m\u001b[0m\u001b[0m\n",
      "\u001b[0;31mSystemError\u001b[0m: PyEval_EvalFrameEx returned a result with an error set",
      "\nDuring handling of the above exception, another exception occurred:\n",
      "\u001b[0;31mSystemError\u001b[0m                               Traceback (most recent call last)",
      "\u001b[0;32mC:\\Users\\irina\\Miniconda3\\envs\\exmc\\lib\\site-packages\\scipy\\sparse\\base.py\u001b[0m in \u001b[0;36m__mul__\u001b[0;34m(self, other)\u001b[0m\n\u001b[1;32m    460\u001b[0m \u001b[0;34m\u001b[0m\u001b[0m\n\u001b[0;32m--> 461\u001b[0;31m         \u001b[0mM\u001b[0m\u001b[0;34m,\u001b[0m \u001b[0mN\u001b[0m \u001b[0;34m=\u001b[0m \u001b[0mself\u001b[0m\u001b[0;34m.\u001b[0m\u001b[0mshape\u001b[0m\u001b[0;34m\u001b[0m\u001b[0m\n\u001b[0m\u001b[1;32m    462\u001b[0m \u001b[0;34m\u001b[0m\u001b[0m\n",
      "\u001b[0;31mSystemError\u001b[0m: PyEval_EvalFrameEx returned a result with an error set",
      "\nDuring handling of the above exception, another exception occurred:\n",
      "\u001b[0;31mSystemError\u001b[0m                               Traceback (most recent call last)",
      "\u001b[0;32mC:\\Users\\irina\\Miniconda3\\envs\\exmc\\lib\\site-packages\\scipy\\sparse\\base.py\u001b[0m in \u001b[0;36m__mul__\u001b[0;34m(self, other)\u001b[0m\n\u001b[1;32m    460\u001b[0m \u001b[0;34m\u001b[0m\u001b[0m\n\u001b[0;32m--> 461\u001b[0;31m         \u001b[0mM\u001b[0m\u001b[0;34m,\u001b[0m \u001b[0mN\u001b[0m \u001b[0;34m=\u001b[0m \u001b[0mself\u001b[0m\u001b[0;34m.\u001b[0m\u001b[0mshape\u001b[0m\u001b[0;34m\u001b[0m\u001b[0m\n\u001b[0m\u001b[1;32m    462\u001b[0m \u001b[0;34m\u001b[0m\u001b[0m\n",
      "\u001b[0;31mSystemError\u001b[0m: PyEval_EvalFrameEx returned a result with an error set",
      "\nDuring handling of the above exception, another exception occurred:\n",
      "\u001b[0;31mSystemError\u001b[0m                               Traceback (most recent call last)",
      "\u001b[0;32mC:\\Users\\irina\\Miniconda3\\envs\\exmc\\lib\\site-packages\\scipy\\sparse\\base.py\u001b[0m in \u001b[0;36m__mul__\u001b[0;34m(self, other)\u001b[0m\n\u001b[1;32m    460\u001b[0m \u001b[0;34m\u001b[0m\u001b[0m\n\u001b[0;32m--> 461\u001b[0;31m         \u001b[0mM\u001b[0m\u001b[0;34m,\u001b[0m \u001b[0mN\u001b[0m \u001b[0;34m=\u001b[0m \u001b[0mself\u001b[0m\u001b[0;34m.\u001b[0m\u001b[0mshape\u001b[0m\u001b[0;34m\u001b[0m\u001b[0m\n\u001b[0m\u001b[1;32m    462\u001b[0m \u001b[0;34m\u001b[0m\u001b[0m\n",
      "\u001b[0;31mSystemError\u001b[0m: PyEval_EvalFrameEx returned a result with an error set",
      "\nDuring handling of the above exception, another exception occurred:\n",
      "\u001b[0;31mSystemError\u001b[0m                               Traceback (most recent call last)",
      "\u001b[0;32mC:\\Users\\irina\\Miniconda3\\envs\\exmc\\lib\\site-packages\\scipy\\sparse\\base.py\u001b[0m in \u001b[0;36m__mul__\u001b[0;34m(self, other)\u001b[0m\n\u001b[1;32m    460\u001b[0m \u001b[0;34m\u001b[0m\u001b[0m\n\u001b[0;32m--> 461\u001b[0;31m         \u001b[0mM\u001b[0m\u001b[0;34m,\u001b[0m \u001b[0mN\u001b[0m \u001b[0;34m=\u001b[0m \u001b[0mself\u001b[0m\u001b[0;34m.\u001b[0m\u001b[0mshape\u001b[0m\u001b[0;34m\u001b[0m\u001b[0m\n\u001b[0m\u001b[1;32m    462\u001b[0m \u001b[0;34m\u001b[0m\u001b[0m\n",
      "\u001b[0;31mSystemError\u001b[0m: PyEval_EvalFrameEx returned a result with an error set",
      "\nDuring handling of the above exception, another exception occurred:\n",
      "\u001b[0;31mSystemError\u001b[0m                               Traceback (most recent call last)",
      "\u001b[0;32mC:\\Users\\irina\\Miniconda3\\envs\\exmc\\lib\\site-packages\\scipy\\sparse\\base.py\u001b[0m in \u001b[0;36m__mul__\u001b[0;34m(self, other)\u001b[0m\n\u001b[1;32m    460\u001b[0m \u001b[0;34m\u001b[0m\u001b[0m\n\u001b[0;32m--> 461\u001b[0;31m         \u001b[0mM\u001b[0m\u001b[0;34m,\u001b[0m \u001b[0mN\u001b[0m \u001b[0;34m=\u001b[0m \u001b[0mself\u001b[0m\u001b[0;34m.\u001b[0m\u001b[0mshape\u001b[0m\u001b[0;34m\u001b[0m\u001b[0m\n\u001b[0m\u001b[1;32m    462\u001b[0m \u001b[0;34m\u001b[0m\u001b[0m\n",
      "\u001b[0;31mSystemError\u001b[0m: PyEval_EvalFrameEx returned a result with an error set",
      "\nDuring handling of the above exception, another exception occurred:\n",
      "\u001b[0;31mSystemError\u001b[0m                               Traceback (most recent call last)",
      "\u001b[0;32mC:\\Users\\irina\\Miniconda3\\envs\\exmc\\lib\\site-packages\\scipy\\sparse\\base.py\u001b[0m in \u001b[0;36m__mul__\u001b[0;34m(self, other)\u001b[0m\n\u001b[1;32m    460\u001b[0m \u001b[0;34m\u001b[0m\u001b[0m\n\u001b[0;32m--> 461\u001b[0;31m         \u001b[0mM\u001b[0m\u001b[0;34m,\u001b[0m \u001b[0mN\u001b[0m \u001b[0;34m=\u001b[0m \u001b[0mself\u001b[0m\u001b[0;34m.\u001b[0m\u001b[0mshape\u001b[0m\u001b[0;34m\u001b[0m\u001b[0m\n\u001b[0m\u001b[1;32m    462\u001b[0m \u001b[0;34m\u001b[0m\u001b[0m\n",
      "\u001b[0;31mSystemError\u001b[0m: PyEval_EvalFrameEx returned a result with an error set",
      "\nDuring handling of the above exception, another exception occurred:\n",
      "\u001b[0;31mSystemError\u001b[0m                               Traceback (most recent call last)",
      "\u001b[0;32mC:\\Users\\irina\\Miniconda3\\envs\\exmc\\lib\\site-packages\\scipy\\sparse\\base.py\u001b[0m in \u001b[0;36m__mul__\u001b[0;34m(self, other)\u001b[0m\n\u001b[1;32m    460\u001b[0m \u001b[0;34m\u001b[0m\u001b[0m\n\u001b[0;32m--> 461\u001b[0;31m         \u001b[0mM\u001b[0m\u001b[0;34m,\u001b[0m \u001b[0mN\u001b[0m \u001b[0;34m=\u001b[0m \u001b[0mself\u001b[0m\u001b[0;34m.\u001b[0m\u001b[0mshape\u001b[0m\u001b[0;34m\u001b[0m\u001b[0m\n\u001b[0m\u001b[1;32m    462\u001b[0m \u001b[0;34m\u001b[0m\u001b[0m\n",
      "\u001b[0;31mSystemError\u001b[0m: PyEval_EvalFrameEx returned a result with an error set",
      "\nDuring handling of the above exception, another exception occurred:\n",
      "\u001b[0;31mSystemError\u001b[0m                               Traceback (most recent call last)",
      "\u001b[0;32mC:\\Users\\irina\\Miniconda3\\envs\\exmc\\lib\\site-packages\\scipy\\sparse\\base.py\u001b[0m in \u001b[0;36m__mul__\u001b[0;34m(self, other)\u001b[0m\n\u001b[1;32m    460\u001b[0m \u001b[0;34m\u001b[0m\u001b[0m\n\u001b[0;32m--> 461\u001b[0;31m         \u001b[0mM\u001b[0m\u001b[0;34m,\u001b[0m \u001b[0mN\u001b[0m \u001b[0;34m=\u001b[0m \u001b[0mself\u001b[0m\u001b[0;34m.\u001b[0m\u001b[0mshape\u001b[0m\u001b[0;34m\u001b[0m\u001b[0m\n\u001b[0m\u001b[1;32m    462\u001b[0m \u001b[0;34m\u001b[0m\u001b[0m\n",
      "\u001b[0;31mSystemError\u001b[0m: PyEval_EvalFrameEx returned a result with an error set",
      "\nDuring handling of the above exception, another exception occurred:\n",
      "\u001b[0;31mSystemError\u001b[0m                               Traceback (most recent call last)",
      "\u001b[0;32mC:\\Users\\irina\\Miniconda3\\envs\\exmc\\lib\\site-packages\\scipy\\sparse\\base.py\u001b[0m in \u001b[0;36m__mul__\u001b[0;34m(self, other)\u001b[0m\n\u001b[1;32m    460\u001b[0m \u001b[0;34m\u001b[0m\u001b[0m\n\u001b[0;32m--> 461\u001b[0;31m         \u001b[0mM\u001b[0m\u001b[0;34m,\u001b[0m \u001b[0mN\u001b[0m \u001b[0;34m=\u001b[0m \u001b[0mself\u001b[0m\u001b[0;34m.\u001b[0m\u001b[0mshape\u001b[0m\u001b[0;34m\u001b[0m\u001b[0m\n\u001b[0m\u001b[1;32m    462\u001b[0m \u001b[0;34m\u001b[0m\u001b[0m\n",
      "\u001b[0;31mSystemError\u001b[0m: PyEval_EvalFrameEx returned a result with an error set",
      "\nDuring handling of the above exception, another exception occurred:\n",
      "\u001b[0;31mSystemError\u001b[0m                               Traceback (most recent call last)",
      "\u001b[0;32mC:\\Users\\irina\\Miniconda3\\envs\\exmc\\lib\\site-packages\\scipy\\sparse\\base.py\u001b[0m in \u001b[0;36m__mul__\u001b[0;34m(self, other)\u001b[0m\n\u001b[1;32m    460\u001b[0m \u001b[0;34m\u001b[0m\u001b[0m\n\u001b[0;32m--> 461\u001b[0;31m         \u001b[0mM\u001b[0m\u001b[0;34m,\u001b[0m \u001b[0mN\u001b[0m \u001b[0;34m=\u001b[0m \u001b[0mself\u001b[0m\u001b[0;34m.\u001b[0m\u001b[0mshape\u001b[0m\u001b[0;34m\u001b[0m\u001b[0m\n\u001b[0m\u001b[1;32m    462\u001b[0m \u001b[0;34m\u001b[0m\u001b[0m\n",
      "\u001b[0;31mSystemError\u001b[0m: PyEval_EvalFrameEx returned a result with an error set",
      "\nDuring handling of the above exception, another exception occurred:\n",
      "\u001b[0;31mSystemError\u001b[0m                               Traceback (most recent call last)",
      "\u001b[0;32mC:\\Users\\irina\\Miniconda3\\envs\\exmc\\lib\\site-packages\\scipy\\sparse\\base.py\u001b[0m in \u001b[0;36m__mul__\u001b[0;34m(self, other)\u001b[0m\n\u001b[1;32m    460\u001b[0m \u001b[0;34m\u001b[0m\u001b[0m\n\u001b[0;32m--> 461\u001b[0;31m         \u001b[0mM\u001b[0m\u001b[0;34m,\u001b[0m \u001b[0mN\u001b[0m \u001b[0;34m=\u001b[0m \u001b[0mself\u001b[0m\u001b[0;34m.\u001b[0m\u001b[0mshape\u001b[0m\u001b[0;34m\u001b[0m\u001b[0m\n\u001b[0m\u001b[1;32m    462\u001b[0m \u001b[0;34m\u001b[0m\u001b[0m\n",
      "\u001b[0;31mSystemError\u001b[0m: PyEval_EvalFrameEx returned a result with an error set",
      "\nDuring handling of the above exception, another exception occurred:\n",
      "\u001b[0;31mSystemError\u001b[0m                               Traceback (most recent call last)",
      "\u001b[0;32mC:\\Users\\irina\\Miniconda3\\envs\\exmc\\lib\\site-packages\\scipy\\sparse\\base.py\u001b[0m in \u001b[0;36m__mul__\u001b[0;34m(self, other)\u001b[0m\n\u001b[1;32m    460\u001b[0m \u001b[0;34m\u001b[0m\u001b[0m\n\u001b[0;32m--> 461\u001b[0;31m         \u001b[0mM\u001b[0m\u001b[0;34m,\u001b[0m \u001b[0mN\u001b[0m \u001b[0;34m=\u001b[0m \u001b[0mself\u001b[0m\u001b[0;34m.\u001b[0m\u001b[0mshape\u001b[0m\u001b[0;34m\u001b[0m\u001b[0m\n\u001b[0m\u001b[1;32m    462\u001b[0m \u001b[0;34m\u001b[0m\u001b[0m\n",
      "\u001b[0;31mSystemError\u001b[0m: PyEval_EvalFrameEx returned a result with an error set",
      "\nDuring handling of the above exception, another exception occurred:\n",
      "\u001b[0;31mSystemError\u001b[0m                               Traceback (most recent call last)",
      "\u001b[0;32mC:\\Users\\irina\\Miniconda3\\envs\\exmc\\lib\\site-packages\\scipy\\sparse\\base.py\u001b[0m in \u001b[0;36m__mul__\u001b[0;34m(self, other)\u001b[0m\n\u001b[1;32m    460\u001b[0m \u001b[0;34m\u001b[0m\u001b[0m\n\u001b[0;32m--> 461\u001b[0;31m         \u001b[0mM\u001b[0m\u001b[0;34m,\u001b[0m \u001b[0mN\u001b[0m \u001b[0;34m=\u001b[0m \u001b[0mself\u001b[0m\u001b[0;34m.\u001b[0m\u001b[0mshape\u001b[0m\u001b[0;34m\u001b[0m\u001b[0m\n\u001b[0m\u001b[1;32m    462\u001b[0m \u001b[0;34m\u001b[0m\u001b[0m\n",
      "\u001b[0;31mSystemError\u001b[0m: PyEval_EvalFrameEx returned a result with an error set",
      "\nDuring handling of the above exception, another exception occurred:\n",
      "\u001b[0;31mSystemError\u001b[0m                               Traceback (most recent call last)",
      "\u001b[0;32mC:\\Users\\irina\\Miniconda3\\envs\\exmc\\lib\\site-packages\\scipy\\sparse\\base.py\u001b[0m in \u001b[0;36m__mul__\u001b[0;34m(self, other)\u001b[0m\n\u001b[1;32m    460\u001b[0m \u001b[0;34m\u001b[0m\u001b[0m\n\u001b[0;32m--> 461\u001b[0;31m         \u001b[0mM\u001b[0m\u001b[0;34m,\u001b[0m \u001b[0mN\u001b[0m \u001b[0;34m=\u001b[0m \u001b[0mself\u001b[0m\u001b[0;34m.\u001b[0m\u001b[0mshape\u001b[0m\u001b[0;34m\u001b[0m\u001b[0m\n\u001b[0m\u001b[1;32m    462\u001b[0m \u001b[0;34m\u001b[0m\u001b[0m\n",
      "\u001b[0;31mSystemError\u001b[0m: PyEval_EvalFrameEx returned a result with an error set",
      "\nDuring handling of the above exception, another exception occurred:\n",
      "\u001b[0;31mSystemError\u001b[0m                               Traceback (most recent call last)",
      "\u001b[0;32mC:\\Users\\irina\\Miniconda3\\envs\\exmc\\lib\\site-packages\\scipy\\sparse\\base.py\u001b[0m in \u001b[0;36m__mul__\u001b[0;34m(self, other)\u001b[0m\n\u001b[1;32m    460\u001b[0m \u001b[0;34m\u001b[0m\u001b[0m\n\u001b[0;32m--> 461\u001b[0;31m         \u001b[0mM\u001b[0m\u001b[0;34m,\u001b[0m \u001b[0mN\u001b[0m \u001b[0;34m=\u001b[0m \u001b[0mself\u001b[0m\u001b[0;34m.\u001b[0m\u001b[0mshape\u001b[0m\u001b[0;34m\u001b[0m\u001b[0m\n\u001b[0m\u001b[1;32m    462\u001b[0m \u001b[0;34m\u001b[0m\u001b[0m\n",
      "\u001b[0;31mSystemError\u001b[0m: PyEval_EvalFrameEx returned a result with an error set",
      "\nDuring handling of the above exception, another exception occurred:\n",
      "\u001b[0;31mSystemError\u001b[0m                               Traceback (most recent call last)",
      "\u001b[0;32mC:\\Users\\irina\\Miniconda3\\envs\\exmc\\lib\\site-packages\\scipy\\sparse\\base.py\u001b[0m in \u001b[0;36m__mul__\u001b[0;34m(self, other)\u001b[0m\n\u001b[1;32m    460\u001b[0m \u001b[0;34m\u001b[0m\u001b[0m\n\u001b[0;32m--> 461\u001b[0;31m         \u001b[0mM\u001b[0m\u001b[0;34m,\u001b[0m \u001b[0mN\u001b[0m \u001b[0;34m=\u001b[0m \u001b[0mself\u001b[0m\u001b[0;34m.\u001b[0m\u001b[0mshape\u001b[0m\u001b[0;34m\u001b[0m\u001b[0m\n\u001b[0m\u001b[1;32m    462\u001b[0m \u001b[0;34m\u001b[0m\u001b[0m\n",
      "\u001b[0;31mSystemError\u001b[0m: PyEval_EvalFrameEx returned a result with an error set",
      "\nDuring handling of the above exception, another exception occurred:\n",
      "\u001b[0;31mSystemError\u001b[0m                               Traceback (most recent call last)",
      "\u001b[0;32mC:\\Users\\irina\\Miniconda3\\envs\\exmc\\lib\\site-packages\\scipy\\sparse\\base.py\u001b[0m in \u001b[0;36m__mul__\u001b[0;34m(self, other)\u001b[0m\n\u001b[1;32m    460\u001b[0m \u001b[0;34m\u001b[0m\u001b[0m\n\u001b[0;32m--> 461\u001b[0;31m         \u001b[0mM\u001b[0m\u001b[0;34m,\u001b[0m \u001b[0mN\u001b[0m \u001b[0;34m=\u001b[0m \u001b[0mself\u001b[0m\u001b[0;34m.\u001b[0m\u001b[0mshape\u001b[0m\u001b[0;34m\u001b[0m\u001b[0m\n\u001b[0m\u001b[1;32m    462\u001b[0m \u001b[0;34m\u001b[0m\u001b[0m\n",
      "\u001b[0;31mSystemError\u001b[0m: PyEval_EvalFrameEx returned a result with an error set",
      "\nDuring handling of the above exception, another exception occurred:\n",
      "\u001b[0;31mSystemError\u001b[0m                               Traceback (most recent call last)",
      "\u001b[0;32mC:\\Users\\irina\\Miniconda3\\envs\\exmc\\lib\\site-packages\\scipy\\sparse\\base.py\u001b[0m in \u001b[0;36m__mul__\u001b[0;34m(self, other)\u001b[0m\n\u001b[1;32m    460\u001b[0m \u001b[0;34m\u001b[0m\u001b[0m\n\u001b[0;32m--> 461\u001b[0;31m         \u001b[0mM\u001b[0m\u001b[0;34m,\u001b[0m \u001b[0mN\u001b[0m \u001b[0;34m=\u001b[0m \u001b[0mself\u001b[0m\u001b[0;34m.\u001b[0m\u001b[0mshape\u001b[0m\u001b[0;34m\u001b[0m\u001b[0m\n\u001b[0m\u001b[1;32m    462\u001b[0m \u001b[0;34m\u001b[0m\u001b[0m\n",
      "\u001b[0;31mSystemError\u001b[0m: PyEval_EvalFrameEx returned a result with an error set",
      "\nDuring handling of the above exception, another exception occurred:\n",
      "\u001b[0;31mSystemError\u001b[0m                               Traceback (most recent call last)",
      "\u001b[0;32mC:\\Users\\irina\\Miniconda3\\envs\\exmc\\lib\\site-packages\\scipy\\sparse\\base.py\u001b[0m in \u001b[0;36m__mul__\u001b[0;34m(self, other)\u001b[0m\n\u001b[1;32m    460\u001b[0m \u001b[0;34m\u001b[0m\u001b[0m\n\u001b[0;32m--> 461\u001b[0;31m         \u001b[0mM\u001b[0m\u001b[0;34m,\u001b[0m \u001b[0mN\u001b[0m \u001b[0;34m=\u001b[0m \u001b[0mself\u001b[0m\u001b[0;34m.\u001b[0m\u001b[0mshape\u001b[0m\u001b[0;34m\u001b[0m\u001b[0m\n\u001b[0m\u001b[1;32m    462\u001b[0m \u001b[0;34m\u001b[0m\u001b[0m\n",
      "\u001b[0;31mSystemError\u001b[0m: PyEval_EvalFrameEx returned a result with an error set",
      "\nDuring handling of the above exception, another exception occurred:\n",
      "\u001b[0;31mSystemError\u001b[0m                               Traceback (most recent call last)",
      "\u001b[0;32mC:\\Users\\irina\\Miniconda3\\envs\\exmc\\lib\\site-packages\\scipy\\sparse\\base.py\u001b[0m in \u001b[0;36m__mul__\u001b[0;34m(self, other)\u001b[0m\n\u001b[1;32m    460\u001b[0m \u001b[0;34m\u001b[0m\u001b[0m\n\u001b[0;32m--> 461\u001b[0;31m         \u001b[0mM\u001b[0m\u001b[0;34m,\u001b[0m \u001b[0mN\u001b[0m \u001b[0;34m=\u001b[0m \u001b[0mself\u001b[0m\u001b[0;34m.\u001b[0m\u001b[0mshape\u001b[0m\u001b[0;34m\u001b[0m\u001b[0m\n\u001b[0m\u001b[1;32m    462\u001b[0m \u001b[0;34m\u001b[0m\u001b[0m\n",
      "\u001b[0;31mSystemError\u001b[0m: PyEval_EvalFrameEx returned a result with an error set",
      "\nDuring handling of the above exception, another exception occurred:\n",
      "\u001b[0;31mSystemError\u001b[0m                               Traceback (most recent call last)",
      "\u001b[0;32mC:\\Users\\irina\\Miniconda3\\envs\\exmc\\lib\\site-packages\\scipy\\sparse\\base.py\u001b[0m in \u001b[0;36m__mul__\u001b[0;34m(self, other)\u001b[0m\n\u001b[1;32m    460\u001b[0m \u001b[0;34m\u001b[0m\u001b[0m\n\u001b[0;32m--> 461\u001b[0;31m         \u001b[0mM\u001b[0m\u001b[0;34m,\u001b[0m \u001b[0mN\u001b[0m \u001b[0;34m=\u001b[0m \u001b[0mself\u001b[0m\u001b[0;34m.\u001b[0m\u001b[0mshape\u001b[0m\u001b[0;34m\u001b[0m\u001b[0m\n\u001b[0m\u001b[1;32m    462\u001b[0m \u001b[0;34m\u001b[0m\u001b[0m\n",
      "\u001b[0;31mSystemError\u001b[0m: PyEval_EvalFrameEx returned a result with an error set",
      "\nDuring handling of the above exception, another exception occurred:\n",
      "\u001b[0;31mSystemError\u001b[0m                               Traceback (most recent call last)",
      "\u001b[0;32mC:\\Users\\irina\\Miniconda3\\envs\\exmc\\lib\\site-packages\\scipy\\sparse\\base.py\u001b[0m in \u001b[0;36m__mul__\u001b[0;34m(self, other)\u001b[0m\n\u001b[1;32m    460\u001b[0m \u001b[0;34m\u001b[0m\u001b[0m\n\u001b[0;32m--> 461\u001b[0;31m         \u001b[0mM\u001b[0m\u001b[0;34m,\u001b[0m \u001b[0mN\u001b[0m \u001b[0;34m=\u001b[0m \u001b[0mself\u001b[0m\u001b[0;34m.\u001b[0m\u001b[0mshape\u001b[0m\u001b[0;34m\u001b[0m\u001b[0m\n\u001b[0m\u001b[1;32m    462\u001b[0m \u001b[0;34m\u001b[0m\u001b[0m\n",
      "\u001b[0;31mSystemError\u001b[0m: PyEval_EvalFrameEx returned a result with an error set",
      "\nDuring handling of the above exception, another exception occurred:\n",
      "\u001b[0;31mSystemError\u001b[0m                               Traceback (most recent call last)",
      "\u001b[0;32mC:\\Users\\irina\\Miniconda3\\envs\\exmc\\lib\\site-packages\\scipy\\sparse\\base.py\u001b[0m in \u001b[0;36m__mul__\u001b[0;34m(self, other)\u001b[0m\n\u001b[1;32m    460\u001b[0m \u001b[0;34m\u001b[0m\u001b[0m\n\u001b[0;32m--> 461\u001b[0;31m         \u001b[0mM\u001b[0m\u001b[0;34m,\u001b[0m \u001b[0mN\u001b[0m \u001b[0;34m=\u001b[0m \u001b[0mself\u001b[0m\u001b[0;34m.\u001b[0m\u001b[0mshape\u001b[0m\u001b[0;34m\u001b[0m\u001b[0m\n\u001b[0m\u001b[1;32m    462\u001b[0m \u001b[0;34m\u001b[0m\u001b[0m\n",
      "\u001b[0;31mSystemError\u001b[0m: PyEval_EvalFrameEx returned a result with an error set",
      "\nDuring handling of the above exception, another exception occurred:\n",
      "\u001b[0;31mSystemError\u001b[0m                               Traceback (most recent call last)",
      "\u001b[0;32mC:\\Users\\irina\\Miniconda3\\envs\\exmc\\lib\\site-packages\\scipy\\sparse\\base.py\u001b[0m in \u001b[0;36m__mul__\u001b[0;34m(self, other)\u001b[0m\n\u001b[1;32m    460\u001b[0m \u001b[0;34m\u001b[0m\u001b[0m\n\u001b[0;32m--> 461\u001b[0;31m         \u001b[0mM\u001b[0m\u001b[0;34m,\u001b[0m \u001b[0mN\u001b[0m \u001b[0;34m=\u001b[0m \u001b[0mself\u001b[0m\u001b[0;34m.\u001b[0m\u001b[0mshape\u001b[0m\u001b[0;34m\u001b[0m\u001b[0m\n\u001b[0m\u001b[1;32m    462\u001b[0m \u001b[0;34m\u001b[0m\u001b[0m\n",
      "\u001b[0;31mSystemError\u001b[0m: PyEval_EvalFrameEx returned a result with an error set",
      "\nDuring handling of the above exception, another exception occurred:\n",
      "\u001b[0;31mSystemError\u001b[0m                               Traceback (most recent call last)",
      "\u001b[0;32mC:\\Users\\irina\\Miniconda3\\envs\\exmc\\lib\\site-packages\\scipy\\sparse\\base.py\u001b[0m in \u001b[0;36m__mul__\u001b[0;34m(self, other)\u001b[0m\n\u001b[1;32m    460\u001b[0m \u001b[0;34m\u001b[0m\u001b[0m\n\u001b[0;32m--> 461\u001b[0;31m         \u001b[0mM\u001b[0m\u001b[0;34m,\u001b[0m \u001b[0mN\u001b[0m \u001b[0;34m=\u001b[0m \u001b[0mself\u001b[0m\u001b[0;34m.\u001b[0m\u001b[0mshape\u001b[0m\u001b[0;34m\u001b[0m\u001b[0m\n\u001b[0m\u001b[1;32m    462\u001b[0m \u001b[0;34m\u001b[0m\u001b[0m\n",
      "\u001b[0;31mSystemError\u001b[0m: PyEval_EvalFrameEx returned a result with an error set",
      "\nDuring handling of the above exception, another exception occurred:\n",
      "\u001b[0;31mSystemError\u001b[0m                               Traceback (most recent call last)",
      "\u001b[0;32mC:\\Users\\irina\\Miniconda3\\envs\\exmc\\lib\\site-packages\\scipy\\sparse\\base.py\u001b[0m in \u001b[0;36m__mul__\u001b[0;34m(self, other)\u001b[0m\n\u001b[1;32m    460\u001b[0m \u001b[0;34m\u001b[0m\u001b[0m\n\u001b[0;32m--> 461\u001b[0;31m         \u001b[0mM\u001b[0m\u001b[0;34m,\u001b[0m \u001b[0mN\u001b[0m \u001b[0;34m=\u001b[0m \u001b[0mself\u001b[0m\u001b[0;34m.\u001b[0m\u001b[0mshape\u001b[0m\u001b[0;34m\u001b[0m\u001b[0m\n\u001b[0m\u001b[1;32m    462\u001b[0m \u001b[0;34m\u001b[0m\u001b[0m\n",
      "\u001b[0;31mSystemError\u001b[0m: PyEval_EvalFrameEx returned a result with an error set",
      "\nDuring handling of the above exception, another exception occurred:\n",
      "\u001b[0;31mSystemError\u001b[0m                               Traceback (most recent call last)",
      "\u001b[0;32mC:\\Users\\irina\\Miniconda3\\envs\\exmc\\lib\\site-packages\\scipy\\sparse\\base.py\u001b[0m in \u001b[0;36m__mul__\u001b[0;34m(self, other)\u001b[0m\n\u001b[1;32m    460\u001b[0m \u001b[0;34m\u001b[0m\u001b[0m\n\u001b[0;32m--> 461\u001b[0;31m         \u001b[0mM\u001b[0m\u001b[0;34m,\u001b[0m \u001b[0mN\u001b[0m \u001b[0;34m=\u001b[0m \u001b[0mself\u001b[0m\u001b[0;34m.\u001b[0m\u001b[0mshape\u001b[0m\u001b[0;34m\u001b[0m\u001b[0m\n\u001b[0m\u001b[1;32m    462\u001b[0m \u001b[0;34m\u001b[0m\u001b[0m\n",
      "\u001b[0;31mSystemError\u001b[0m: PyEval_EvalFrameEx returned a result with an error set",
      "\nDuring handling of the above exception, another exception occurred:\n",
      "\u001b[0;31mSystemError\u001b[0m                               Traceback (most recent call last)",
      "\u001b[0;32mC:\\Users\\irina\\Miniconda3\\envs\\exmc\\lib\\site-packages\\scipy\\sparse\\base.py\u001b[0m in \u001b[0;36m__mul__\u001b[0;34m(self, other)\u001b[0m\n\u001b[1;32m    460\u001b[0m \u001b[0;34m\u001b[0m\u001b[0m\n\u001b[0;32m--> 461\u001b[0;31m         \u001b[0mM\u001b[0m\u001b[0;34m,\u001b[0m \u001b[0mN\u001b[0m \u001b[0;34m=\u001b[0m \u001b[0mself\u001b[0m\u001b[0;34m.\u001b[0m\u001b[0mshape\u001b[0m\u001b[0;34m\u001b[0m\u001b[0m\n\u001b[0m\u001b[1;32m    462\u001b[0m \u001b[0;34m\u001b[0m\u001b[0m\n",
      "\u001b[0;31mSystemError\u001b[0m: PyEval_EvalFrameEx returned a result with an error set",
      "\nDuring handling of the above exception, another exception occurred:\n",
      "\u001b[0;31mSystemError\u001b[0m                               Traceback (most recent call last)",
      "\u001b[0;32mC:\\Users\\irina\\Miniconda3\\envs\\exmc\\lib\\site-packages\\scipy\\sparse\\base.py\u001b[0m in \u001b[0;36m__mul__\u001b[0;34m(self, other)\u001b[0m\n\u001b[1;32m    460\u001b[0m \u001b[0;34m\u001b[0m\u001b[0m\n\u001b[0;32m--> 461\u001b[0;31m         \u001b[0mM\u001b[0m\u001b[0;34m,\u001b[0m \u001b[0mN\u001b[0m \u001b[0;34m=\u001b[0m \u001b[0mself\u001b[0m\u001b[0;34m.\u001b[0m\u001b[0mshape\u001b[0m\u001b[0;34m\u001b[0m\u001b[0m\n\u001b[0m\u001b[1;32m    462\u001b[0m \u001b[0;34m\u001b[0m\u001b[0m\n",
      "\u001b[0;31mSystemError\u001b[0m: PyEval_EvalFrameEx returned a result with an error set",
      "\nDuring handling of the above exception, another exception occurred:\n",
      "\u001b[0;31mSystemError\u001b[0m                               Traceback (most recent call last)",
      "\u001b[0;32mC:\\Users\\irina\\Miniconda3\\envs\\exmc\\lib\\site-packages\\scipy\\sparse\\base.py\u001b[0m in \u001b[0;36m__mul__\u001b[0;34m(self, other)\u001b[0m\n\u001b[1;32m    460\u001b[0m \u001b[0;34m\u001b[0m\u001b[0m\n\u001b[0;32m--> 461\u001b[0;31m         \u001b[0mM\u001b[0m\u001b[0;34m,\u001b[0m \u001b[0mN\u001b[0m \u001b[0;34m=\u001b[0m \u001b[0mself\u001b[0m\u001b[0;34m.\u001b[0m\u001b[0mshape\u001b[0m\u001b[0;34m\u001b[0m\u001b[0m\n\u001b[0m\u001b[1;32m    462\u001b[0m \u001b[0;34m\u001b[0m\u001b[0m\n",
      "\u001b[0;31mSystemError\u001b[0m: PyEval_EvalFrameEx returned a result with an error set",
      "\nDuring handling of the above exception, another exception occurred:\n",
      "\u001b[0;31mSystemError\u001b[0m                               Traceback (most recent call last)",
      "\u001b[0;32mC:\\Users\\irina\\Miniconda3\\envs\\exmc\\lib\\site-packages\\scipy\\sparse\\base.py\u001b[0m in \u001b[0;36m__mul__\u001b[0;34m(self, other)\u001b[0m\n\u001b[1;32m    460\u001b[0m \u001b[0;34m\u001b[0m\u001b[0m\n\u001b[0;32m--> 461\u001b[0;31m         \u001b[0mM\u001b[0m\u001b[0;34m,\u001b[0m \u001b[0mN\u001b[0m \u001b[0;34m=\u001b[0m \u001b[0mself\u001b[0m\u001b[0;34m.\u001b[0m\u001b[0mshape\u001b[0m\u001b[0;34m\u001b[0m\u001b[0m\n\u001b[0m\u001b[1;32m    462\u001b[0m \u001b[0;34m\u001b[0m\u001b[0m\n",
      "\u001b[0;31mSystemError\u001b[0m: PyEval_EvalFrameEx returned a result with an error set",
      "\nDuring handling of the above exception, another exception occurred:\n",
      "\u001b[0;31mSystemError\u001b[0m                               Traceback (most recent call last)",
      "\u001b[0;32mC:\\Users\\irina\\Miniconda3\\envs\\exmc\\lib\\site-packages\\scipy\\sparse\\base.py\u001b[0m in \u001b[0;36m__mul__\u001b[0;34m(self, other)\u001b[0m\n\u001b[1;32m    460\u001b[0m \u001b[0;34m\u001b[0m\u001b[0m\n\u001b[0;32m--> 461\u001b[0;31m         \u001b[0mM\u001b[0m\u001b[0;34m,\u001b[0m \u001b[0mN\u001b[0m \u001b[0;34m=\u001b[0m \u001b[0mself\u001b[0m\u001b[0;34m.\u001b[0m\u001b[0mshape\u001b[0m\u001b[0;34m\u001b[0m\u001b[0m\n\u001b[0m\u001b[1;32m    462\u001b[0m \u001b[0;34m\u001b[0m\u001b[0m\n",
      "\u001b[0;31mSystemError\u001b[0m: PyEval_EvalFrameEx returned a result with an error set",
      "\nDuring handling of the above exception, another exception occurred:\n",
      "\u001b[0;31mSystemError\u001b[0m                               Traceback (most recent call last)",
      "\u001b[0;32mC:\\Users\\irina\\Miniconda3\\envs\\exmc\\lib\\site-packages\\scipy\\sparse\\base.py\u001b[0m in \u001b[0;36m__mul__\u001b[0;34m(self, other)\u001b[0m\n\u001b[1;32m    460\u001b[0m \u001b[0;34m\u001b[0m\u001b[0m\n\u001b[0;32m--> 461\u001b[0;31m         \u001b[0mM\u001b[0m\u001b[0;34m,\u001b[0m \u001b[0mN\u001b[0m \u001b[0;34m=\u001b[0m \u001b[0mself\u001b[0m\u001b[0;34m.\u001b[0m\u001b[0mshape\u001b[0m\u001b[0;34m\u001b[0m\u001b[0m\n\u001b[0m\u001b[1;32m    462\u001b[0m \u001b[0;34m\u001b[0m\u001b[0m\n",
      "\u001b[0;31mSystemError\u001b[0m: PyEval_EvalFrameEx returned a result with an error set",
      "\nDuring handling of the above exception, another exception occurred:\n",
      "\u001b[0;31mSystemError\u001b[0m                               Traceback (most recent call last)",
      "\u001b[0;32mC:\\Users\\irina\\Miniconda3\\envs\\exmc\\lib\\site-packages\\scipy\\sparse\\base.py\u001b[0m in \u001b[0;36m__mul__\u001b[0;34m(self, other)\u001b[0m\n\u001b[1;32m    460\u001b[0m \u001b[0;34m\u001b[0m\u001b[0m\n\u001b[0;32m--> 461\u001b[0;31m         \u001b[0mM\u001b[0m\u001b[0;34m,\u001b[0m \u001b[0mN\u001b[0m \u001b[0;34m=\u001b[0m \u001b[0mself\u001b[0m\u001b[0;34m.\u001b[0m\u001b[0mshape\u001b[0m\u001b[0;34m\u001b[0m\u001b[0m\n\u001b[0m\u001b[1;32m    462\u001b[0m \u001b[0;34m\u001b[0m\u001b[0m\n",
      "\u001b[0;31mSystemError\u001b[0m: PyEval_EvalFrameEx returned a result with an error set",
      "\nDuring handling of the above exception, another exception occurred:\n",
      "\u001b[0;31mSystemError\u001b[0m                               Traceback (most recent call last)",
      "\u001b[0;32mC:\\Users\\irina\\Miniconda3\\envs\\exmc\\lib\\site-packages\\scipy\\sparse\\base.py\u001b[0m in \u001b[0;36m__mul__\u001b[0;34m(self, other)\u001b[0m\n\u001b[1;32m    460\u001b[0m \u001b[0;34m\u001b[0m\u001b[0m\n\u001b[0;32m--> 461\u001b[0;31m         \u001b[0mM\u001b[0m\u001b[0;34m,\u001b[0m \u001b[0mN\u001b[0m \u001b[0;34m=\u001b[0m \u001b[0mself\u001b[0m\u001b[0;34m.\u001b[0m\u001b[0mshape\u001b[0m\u001b[0;34m\u001b[0m\u001b[0m\n\u001b[0m\u001b[1;32m    462\u001b[0m \u001b[0;34m\u001b[0m\u001b[0m\n",
      "\u001b[0;31mSystemError\u001b[0m: PyEval_EvalFrameEx returned a result with an error set",
      "\nDuring handling of the above exception, another exception occurred:\n",
      "\u001b[0;31mSystemError\u001b[0m                               Traceback (most recent call last)",
      "\u001b[0;32mC:\\Users\\irina\\Miniconda3\\envs\\exmc\\lib\\site-packages\\scipy\\sparse\\base.py\u001b[0m in \u001b[0;36m__mul__\u001b[0;34m(self, other)\u001b[0m\n\u001b[1;32m    460\u001b[0m \u001b[0;34m\u001b[0m\u001b[0m\n\u001b[0;32m--> 461\u001b[0;31m         \u001b[0mM\u001b[0m\u001b[0;34m,\u001b[0m \u001b[0mN\u001b[0m \u001b[0;34m=\u001b[0m \u001b[0mself\u001b[0m\u001b[0;34m.\u001b[0m\u001b[0mshape\u001b[0m\u001b[0;34m\u001b[0m\u001b[0m\n\u001b[0m\u001b[1;32m    462\u001b[0m \u001b[0;34m\u001b[0m\u001b[0m\n",
      "\u001b[0;31mSystemError\u001b[0m: PyEval_EvalFrameEx returned a result with an error set",
      "\nDuring handling of the above exception, another exception occurred:\n",
      "\u001b[0;31mSystemError\u001b[0m                               Traceback (most recent call last)",
      "\u001b[0;32mC:\\Users\\irina\\Miniconda3\\envs\\exmc\\lib\\site-packages\\scipy\\sparse\\base.py\u001b[0m in \u001b[0;36m__mul__\u001b[0;34m(self, other)\u001b[0m\n\u001b[1;32m    460\u001b[0m \u001b[0;34m\u001b[0m\u001b[0m\n\u001b[0;32m--> 461\u001b[0;31m         \u001b[0mM\u001b[0m\u001b[0;34m,\u001b[0m \u001b[0mN\u001b[0m \u001b[0;34m=\u001b[0m \u001b[0mself\u001b[0m\u001b[0;34m.\u001b[0m\u001b[0mshape\u001b[0m\u001b[0;34m\u001b[0m\u001b[0m\n\u001b[0m\u001b[1;32m    462\u001b[0m \u001b[0;34m\u001b[0m\u001b[0m\n",
      "\u001b[0;31mSystemError\u001b[0m: PyEval_EvalFrameEx returned a result with an error set",
      "\nDuring handling of the above exception, another exception occurred:\n",
      "\u001b[0;31mSystemError\u001b[0m                               Traceback (most recent call last)",
      "\u001b[0;32mC:\\Users\\irina\\Miniconda3\\envs\\exmc\\lib\\site-packages\\scipy\\sparse\\base.py\u001b[0m in \u001b[0;36m__mul__\u001b[0;34m(self, other)\u001b[0m\n\u001b[1;32m    460\u001b[0m \u001b[0;34m\u001b[0m\u001b[0m\n\u001b[0;32m--> 461\u001b[0;31m         \u001b[0mM\u001b[0m\u001b[0;34m,\u001b[0m \u001b[0mN\u001b[0m \u001b[0;34m=\u001b[0m \u001b[0mself\u001b[0m\u001b[0;34m.\u001b[0m\u001b[0mshape\u001b[0m\u001b[0;34m\u001b[0m\u001b[0m\n\u001b[0m\u001b[1;32m    462\u001b[0m \u001b[0;34m\u001b[0m\u001b[0m\n",
      "\u001b[0;31mSystemError\u001b[0m: PyEval_EvalFrameEx returned a result with an error set",
      "\nDuring handling of the above exception, another exception occurred:\n",
      "\u001b[0;31mSystemError\u001b[0m                               Traceback (most recent call last)",
      "\u001b[0;32mC:\\Users\\irina\\Miniconda3\\envs\\exmc\\lib\\site-packages\\scipy\\sparse\\base.py\u001b[0m in \u001b[0;36m__mul__\u001b[0;34m(self, other)\u001b[0m\n\u001b[1;32m    460\u001b[0m \u001b[0;34m\u001b[0m\u001b[0m\n\u001b[0;32m--> 461\u001b[0;31m         \u001b[0mM\u001b[0m\u001b[0;34m,\u001b[0m \u001b[0mN\u001b[0m \u001b[0;34m=\u001b[0m \u001b[0mself\u001b[0m\u001b[0;34m.\u001b[0m\u001b[0mshape\u001b[0m\u001b[0;34m\u001b[0m\u001b[0m\n\u001b[0m\u001b[1;32m    462\u001b[0m \u001b[0;34m\u001b[0m\u001b[0m\n",
      "\u001b[0;31mSystemError\u001b[0m: PyEval_EvalFrameEx returned a result with an error set",
      "\nDuring handling of the above exception, another exception occurred:\n",
      "\u001b[0;31mSystemError\u001b[0m                               Traceback (most recent call last)",
      "\u001b[0;32mC:\\Users\\irina\\Miniconda3\\envs\\exmc\\lib\\site-packages\\scipy\\sparse\\base.py\u001b[0m in \u001b[0;36m__mul__\u001b[0;34m(self, other)\u001b[0m\n\u001b[1;32m    460\u001b[0m \u001b[0;34m\u001b[0m\u001b[0m\n\u001b[0;32m--> 461\u001b[0;31m         \u001b[0mM\u001b[0m\u001b[0;34m,\u001b[0m \u001b[0mN\u001b[0m \u001b[0;34m=\u001b[0m \u001b[0mself\u001b[0m\u001b[0;34m.\u001b[0m\u001b[0mshape\u001b[0m\u001b[0;34m\u001b[0m\u001b[0m\n\u001b[0m\u001b[1;32m    462\u001b[0m \u001b[0;34m\u001b[0m\u001b[0m\n",
      "\u001b[0;31mSystemError\u001b[0m: PyEval_EvalFrameEx returned a result with an error set",
      "\nDuring handling of the above exception, another exception occurred:\n",
      "\u001b[0;31mSystemError\u001b[0m                               Traceback (most recent call last)",
      "\u001b[0;32mC:\\Users\\irina\\Miniconda3\\envs\\exmc\\lib\\site-packages\\scipy\\sparse\\base.py\u001b[0m in \u001b[0;36m__mul__\u001b[0;34m(self, other)\u001b[0m\n\u001b[1;32m    460\u001b[0m \u001b[0;34m\u001b[0m\u001b[0m\n\u001b[0;32m--> 461\u001b[0;31m         \u001b[0mM\u001b[0m\u001b[0;34m,\u001b[0m \u001b[0mN\u001b[0m \u001b[0;34m=\u001b[0m \u001b[0mself\u001b[0m\u001b[0;34m.\u001b[0m\u001b[0mshape\u001b[0m\u001b[0;34m\u001b[0m\u001b[0m\n\u001b[0m\u001b[1;32m    462\u001b[0m \u001b[0;34m\u001b[0m\u001b[0m\n",
      "\u001b[0;31mSystemError\u001b[0m: PyEval_EvalFrameEx returned a result with an error set",
      "\nDuring handling of the above exception, another exception occurred:\n",
      "\u001b[0;31mSystemError\u001b[0m                               Traceback (most recent call last)",
      "\u001b[0;32mC:\\Users\\irina\\Miniconda3\\envs\\exmc\\lib\\site-packages\\scipy\\sparse\\base.py\u001b[0m in \u001b[0;36m__mul__\u001b[0;34m(self, other)\u001b[0m\n\u001b[1;32m    460\u001b[0m \u001b[0;34m\u001b[0m\u001b[0m\n\u001b[0;32m--> 461\u001b[0;31m         \u001b[0mM\u001b[0m\u001b[0;34m,\u001b[0m \u001b[0mN\u001b[0m \u001b[0;34m=\u001b[0m \u001b[0mself\u001b[0m\u001b[0;34m.\u001b[0m\u001b[0mshape\u001b[0m\u001b[0;34m\u001b[0m\u001b[0m\n\u001b[0m\u001b[1;32m    462\u001b[0m \u001b[0;34m\u001b[0m\u001b[0m\n",
      "\u001b[0;31mSystemError\u001b[0m: PyEval_EvalFrameEx returned a result with an error set",
      "\nDuring handling of the above exception, another exception occurred:\n",
      "\u001b[0;31mSystemError\u001b[0m                               Traceback (most recent call last)",
      "\u001b[0;32mC:\\Users\\irina\\Miniconda3\\envs\\exmc\\lib\\site-packages\\scipy\\sparse\\base.py\u001b[0m in \u001b[0;36m__mul__\u001b[0;34m(self, other)\u001b[0m\n\u001b[1;32m    460\u001b[0m \u001b[0;34m\u001b[0m\u001b[0m\n\u001b[0;32m--> 461\u001b[0;31m         \u001b[0mM\u001b[0m\u001b[0;34m,\u001b[0m \u001b[0mN\u001b[0m \u001b[0;34m=\u001b[0m \u001b[0mself\u001b[0m\u001b[0;34m.\u001b[0m\u001b[0mshape\u001b[0m\u001b[0;34m\u001b[0m\u001b[0m\n\u001b[0m\u001b[1;32m    462\u001b[0m \u001b[0;34m\u001b[0m\u001b[0m\n",
      "\u001b[0;31mSystemError\u001b[0m: PyEval_EvalFrameEx returned a result with an error set",
      "\nDuring handling of the above exception, another exception occurred:\n",
      "\u001b[0;31mSystemError\u001b[0m                               Traceback (most recent call last)",
      "\u001b[0;32mC:\\Users\\irina\\Miniconda3\\envs\\exmc\\lib\\site-packages\\scipy\\sparse\\base.py\u001b[0m in \u001b[0;36m__mul__\u001b[0;34m(self, other)\u001b[0m\n\u001b[1;32m    460\u001b[0m \u001b[0;34m\u001b[0m\u001b[0m\n\u001b[0;32m--> 461\u001b[0;31m         \u001b[0mM\u001b[0m\u001b[0;34m,\u001b[0m \u001b[0mN\u001b[0m \u001b[0;34m=\u001b[0m \u001b[0mself\u001b[0m\u001b[0;34m.\u001b[0m\u001b[0mshape\u001b[0m\u001b[0;34m\u001b[0m\u001b[0m\n\u001b[0m\u001b[1;32m    462\u001b[0m \u001b[0;34m\u001b[0m\u001b[0m\n",
      "\u001b[0;31mSystemError\u001b[0m: PyEval_EvalFrameEx returned a result with an error set",
      "\nDuring handling of the above exception, another exception occurred:\n",
      "\u001b[0;31mSystemError\u001b[0m                               Traceback (most recent call last)",
      "\u001b[0;32mC:\\Users\\irina\\Miniconda3\\envs\\exmc\\lib\\site-packages\\scipy\\sparse\\base.py\u001b[0m in \u001b[0;36m__mul__\u001b[0;34m(self, other)\u001b[0m\n\u001b[1;32m    460\u001b[0m \u001b[0;34m\u001b[0m\u001b[0m\n\u001b[0;32m--> 461\u001b[0;31m         \u001b[0mM\u001b[0m\u001b[0;34m,\u001b[0m \u001b[0mN\u001b[0m \u001b[0;34m=\u001b[0m \u001b[0mself\u001b[0m\u001b[0;34m.\u001b[0m\u001b[0mshape\u001b[0m\u001b[0;34m\u001b[0m\u001b[0m\n\u001b[0m\u001b[1;32m    462\u001b[0m \u001b[0;34m\u001b[0m\u001b[0m\n",
      "\u001b[0;31mSystemError\u001b[0m: PyEval_EvalFrameEx returned a result with an error set",
      "\nDuring handling of the above exception, another exception occurred:\n",
      "\u001b[0;31mSystemError\u001b[0m                               Traceback (most recent call last)",
      "\u001b[0;32mC:\\Users\\irina\\Miniconda3\\envs\\exmc\\lib\\site-packages\\scipy\\sparse\\base.py\u001b[0m in \u001b[0;36m__mul__\u001b[0;34m(self, other)\u001b[0m\n\u001b[1;32m    460\u001b[0m \u001b[0;34m\u001b[0m\u001b[0m\n\u001b[0;32m--> 461\u001b[0;31m         \u001b[0mM\u001b[0m\u001b[0;34m,\u001b[0m \u001b[0mN\u001b[0m \u001b[0;34m=\u001b[0m \u001b[0mself\u001b[0m\u001b[0;34m.\u001b[0m\u001b[0mshape\u001b[0m\u001b[0;34m\u001b[0m\u001b[0m\n\u001b[0m\u001b[1;32m    462\u001b[0m \u001b[0;34m\u001b[0m\u001b[0m\n",
      "\u001b[0;31mSystemError\u001b[0m: PyEval_EvalFrameEx returned a result with an error set",
      "\nDuring handling of the above exception, another exception occurred:\n",
      "\u001b[0;31mSystemError\u001b[0m                               Traceback (most recent call last)",
      "\u001b[0;32mC:\\Users\\irina\\Miniconda3\\envs\\exmc\\lib\\site-packages\\scipy\\sparse\\base.py\u001b[0m in \u001b[0;36m__mul__\u001b[0;34m(self, other)\u001b[0m\n\u001b[1;32m    460\u001b[0m \u001b[0;34m\u001b[0m\u001b[0m\n\u001b[0;32m--> 461\u001b[0;31m         \u001b[0mM\u001b[0m\u001b[0;34m,\u001b[0m \u001b[0mN\u001b[0m \u001b[0;34m=\u001b[0m \u001b[0mself\u001b[0m\u001b[0;34m.\u001b[0m\u001b[0mshape\u001b[0m\u001b[0;34m\u001b[0m\u001b[0m\n\u001b[0m\u001b[1;32m    462\u001b[0m \u001b[0;34m\u001b[0m\u001b[0m\n",
      "\u001b[0;31mSystemError\u001b[0m: PyEval_EvalFrameEx returned a result with an error set",
      "\nDuring handling of the above exception, another exception occurred:\n",
      "\u001b[0;31mSystemError\u001b[0m                               Traceback (most recent call last)",
      "\u001b[0;32mC:\\Users\\irina\\Miniconda3\\envs\\exmc\\lib\\site-packages\\scipy\\sparse\\base.py\u001b[0m in \u001b[0;36m__mul__\u001b[0;34m(self, other)\u001b[0m\n\u001b[1;32m    460\u001b[0m \u001b[0;34m\u001b[0m\u001b[0m\n\u001b[0;32m--> 461\u001b[0;31m         \u001b[0mM\u001b[0m\u001b[0;34m,\u001b[0m \u001b[0mN\u001b[0m \u001b[0;34m=\u001b[0m \u001b[0mself\u001b[0m\u001b[0;34m.\u001b[0m\u001b[0mshape\u001b[0m\u001b[0;34m\u001b[0m\u001b[0m\n\u001b[0m\u001b[1;32m    462\u001b[0m \u001b[0;34m\u001b[0m\u001b[0m\n",
      "\u001b[0;31mSystemError\u001b[0m: PyEval_EvalFrameEx returned a result with an error set",
      "\nDuring handling of the above exception, another exception occurred:\n",
      "\u001b[0;31mSystemError\u001b[0m                               Traceback (most recent call last)",
      "\u001b[0;32mC:\\Users\\irina\\Miniconda3\\envs\\exmc\\lib\\site-packages\\scipy\\sparse\\base.py\u001b[0m in \u001b[0;36m__mul__\u001b[0;34m(self, other)\u001b[0m\n\u001b[1;32m    460\u001b[0m \u001b[0;34m\u001b[0m\u001b[0m\n\u001b[0;32m--> 461\u001b[0;31m         \u001b[0mM\u001b[0m\u001b[0;34m,\u001b[0m \u001b[0mN\u001b[0m \u001b[0;34m=\u001b[0m \u001b[0mself\u001b[0m\u001b[0;34m.\u001b[0m\u001b[0mshape\u001b[0m\u001b[0;34m\u001b[0m\u001b[0m\n\u001b[0m\u001b[1;32m    462\u001b[0m \u001b[0;34m\u001b[0m\u001b[0m\n",
      "\u001b[0;31mSystemError\u001b[0m: PyEval_EvalFrameEx returned a result with an error set",
      "\nDuring handling of the above exception, another exception occurred:\n",
      "\u001b[0;31mSystemError\u001b[0m                               Traceback (most recent call last)",
      "\u001b[0;32mC:\\Users\\irina\\Miniconda3\\envs\\exmc\\lib\\site-packages\\scipy\\sparse\\base.py\u001b[0m in \u001b[0;36m__mul__\u001b[0;34m(self, other)\u001b[0m\n\u001b[1;32m    460\u001b[0m \u001b[0;34m\u001b[0m\u001b[0m\n\u001b[0;32m--> 461\u001b[0;31m         \u001b[0mM\u001b[0m\u001b[0;34m,\u001b[0m \u001b[0mN\u001b[0m \u001b[0;34m=\u001b[0m \u001b[0mself\u001b[0m\u001b[0;34m.\u001b[0m\u001b[0mshape\u001b[0m\u001b[0;34m\u001b[0m\u001b[0m\n\u001b[0m\u001b[1;32m    462\u001b[0m \u001b[0;34m\u001b[0m\u001b[0m\n",
      "\u001b[0;31mSystemError\u001b[0m: PyEval_EvalFrameEx returned a result with an error set",
      "\nDuring handling of the above exception, another exception occurred:\n",
      "\u001b[0;31mSystemError\u001b[0m                               Traceback (most recent call last)",
      "\u001b[0;32mC:\\Users\\irina\\Miniconda3\\envs\\exmc\\lib\\site-packages\\scipy\\sparse\\base.py\u001b[0m in \u001b[0;36m__mul__\u001b[0;34m(self, other)\u001b[0m\n\u001b[1;32m    460\u001b[0m \u001b[0;34m\u001b[0m\u001b[0m\n\u001b[0;32m--> 461\u001b[0;31m         \u001b[0mM\u001b[0m\u001b[0;34m,\u001b[0m \u001b[0mN\u001b[0m \u001b[0;34m=\u001b[0m \u001b[0mself\u001b[0m\u001b[0;34m.\u001b[0m\u001b[0mshape\u001b[0m\u001b[0;34m\u001b[0m\u001b[0m\n\u001b[0m\u001b[1;32m    462\u001b[0m \u001b[0;34m\u001b[0m\u001b[0m\n",
      "\u001b[0;31mSystemError\u001b[0m: PyEval_EvalFrameEx returned a result with an error set",
      "\nDuring handling of the above exception, another exception occurred:\n",
      "\u001b[0;31mSystemError\u001b[0m                               Traceback (most recent call last)",
      "\u001b[0;32mC:\\Users\\irina\\Miniconda3\\envs\\exmc\\lib\\site-packages\\scipy\\sparse\\base.py\u001b[0m in \u001b[0;36m__mul__\u001b[0;34m(self, other)\u001b[0m\n\u001b[1;32m    460\u001b[0m \u001b[0;34m\u001b[0m\u001b[0m\n\u001b[0;32m--> 461\u001b[0;31m         \u001b[0mM\u001b[0m\u001b[0;34m,\u001b[0m \u001b[0mN\u001b[0m \u001b[0;34m=\u001b[0m \u001b[0mself\u001b[0m\u001b[0;34m.\u001b[0m\u001b[0mshape\u001b[0m\u001b[0;34m\u001b[0m\u001b[0m\n\u001b[0m\u001b[1;32m    462\u001b[0m \u001b[0;34m\u001b[0m\u001b[0m\n",
      "\u001b[0;31mSystemError\u001b[0m: PyEval_EvalFrameEx returned a result with an error set",
      "\nDuring handling of the above exception, another exception occurred:\n",
      "\u001b[0;31mSystemError\u001b[0m                               Traceback (most recent call last)",
      "\u001b[0;32mC:\\Users\\irina\\Miniconda3\\envs\\exmc\\lib\\site-packages\\scipy\\sparse\\base.py\u001b[0m in \u001b[0;36m__mul__\u001b[0;34m(self, other)\u001b[0m\n\u001b[1;32m    460\u001b[0m \u001b[0;34m\u001b[0m\u001b[0m\n\u001b[0;32m--> 461\u001b[0;31m         \u001b[0mM\u001b[0m\u001b[0;34m,\u001b[0m \u001b[0mN\u001b[0m \u001b[0;34m=\u001b[0m \u001b[0mself\u001b[0m\u001b[0;34m.\u001b[0m\u001b[0mshape\u001b[0m\u001b[0;34m\u001b[0m\u001b[0m\n\u001b[0m\u001b[1;32m    462\u001b[0m \u001b[0;34m\u001b[0m\u001b[0m\n",
      "\u001b[0;31mSystemError\u001b[0m: PyEval_EvalFrameEx returned a result with an error set",
      "\nDuring handling of the above exception, another exception occurred:\n",
      "\u001b[0;31mSystemError\u001b[0m                               Traceback (most recent call last)",
      "\u001b[0;32mC:\\Users\\irina\\Miniconda3\\envs\\exmc\\lib\\site-packages\\scipy\\sparse\\base.py\u001b[0m in \u001b[0;36m__mul__\u001b[0;34m(self, other)\u001b[0m\n\u001b[1;32m    460\u001b[0m \u001b[0;34m\u001b[0m\u001b[0m\n\u001b[0;32m--> 461\u001b[0;31m         \u001b[0mM\u001b[0m\u001b[0;34m,\u001b[0m \u001b[0mN\u001b[0m \u001b[0;34m=\u001b[0m \u001b[0mself\u001b[0m\u001b[0;34m.\u001b[0m\u001b[0mshape\u001b[0m\u001b[0;34m\u001b[0m\u001b[0m\n\u001b[0m\u001b[1;32m    462\u001b[0m \u001b[0;34m\u001b[0m\u001b[0m\n",
      "\u001b[0;31mSystemError\u001b[0m: PyEval_EvalFrameEx returned a result with an error set",
      "\nDuring handling of the above exception, another exception occurred:\n",
      "\u001b[0;31mSystemError\u001b[0m                               Traceback (most recent call last)",
      "\u001b[0;32mC:\\Users\\irina\\Miniconda3\\envs\\exmc\\lib\\site-packages\\scipy\\sparse\\base.py\u001b[0m in \u001b[0;36m__mul__\u001b[0;34m(self, other)\u001b[0m\n\u001b[1;32m    460\u001b[0m \u001b[0;34m\u001b[0m\u001b[0m\n\u001b[0;32m--> 461\u001b[0;31m         \u001b[0mM\u001b[0m\u001b[0;34m,\u001b[0m \u001b[0mN\u001b[0m \u001b[0;34m=\u001b[0m \u001b[0mself\u001b[0m\u001b[0;34m.\u001b[0m\u001b[0mshape\u001b[0m\u001b[0;34m\u001b[0m\u001b[0m\n\u001b[0m\u001b[1;32m    462\u001b[0m \u001b[0;34m\u001b[0m\u001b[0m\n",
      "\u001b[0;31mSystemError\u001b[0m: PyEval_EvalFrameEx returned a result with an error set",
      "\nDuring handling of the above exception, another exception occurred:\n",
      "\u001b[0;31mSystemError\u001b[0m                               Traceback (most recent call last)",
      "\u001b[0;32mC:\\Users\\irina\\Miniconda3\\envs\\exmc\\lib\\site-packages\\scipy\\sparse\\base.py\u001b[0m in \u001b[0;36m__mul__\u001b[0;34m(self, other)\u001b[0m\n\u001b[1;32m    460\u001b[0m \u001b[0;34m\u001b[0m\u001b[0m\n\u001b[0;32m--> 461\u001b[0;31m         \u001b[0mM\u001b[0m\u001b[0;34m,\u001b[0m \u001b[0mN\u001b[0m \u001b[0;34m=\u001b[0m \u001b[0mself\u001b[0m\u001b[0;34m.\u001b[0m\u001b[0mshape\u001b[0m\u001b[0;34m\u001b[0m\u001b[0m\n\u001b[0m\u001b[1;32m    462\u001b[0m \u001b[0;34m\u001b[0m\u001b[0m\n",
      "\u001b[0;31mSystemError\u001b[0m: PyEval_EvalFrameEx returned a result with an error set",
      "\nDuring handling of the above exception, another exception occurred:\n",
      "\u001b[0;31mSystemError\u001b[0m                               Traceback (most recent call last)",
      "\u001b[0;32mC:\\Users\\irina\\Miniconda3\\envs\\exmc\\lib\\site-packages\\scipy\\sparse\\base.py\u001b[0m in \u001b[0;36m__mul__\u001b[0;34m(self, other)\u001b[0m\n\u001b[1;32m    460\u001b[0m \u001b[0;34m\u001b[0m\u001b[0m\n\u001b[0;32m--> 461\u001b[0;31m         \u001b[0mM\u001b[0m\u001b[0;34m,\u001b[0m \u001b[0mN\u001b[0m \u001b[0;34m=\u001b[0m \u001b[0mself\u001b[0m\u001b[0;34m.\u001b[0m\u001b[0mshape\u001b[0m\u001b[0;34m\u001b[0m\u001b[0m\n\u001b[0m\u001b[1;32m    462\u001b[0m \u001b[0;34m\u001b[0m\u001b[0m\n",
      "\u001b[0;31mSystemError\u001b[0m: PyEval_EvalFrameEx returned a result with an error set",
      "\nDuring handling of the above exception, another exception occurred:\n",
      "\u001b[0;31mSystemError\u001b[0m                               Traceback (most recent call last)",
      "\u001b[0;32mC:\\Users\\irina\\Miniconda3\\envs\\exmc\\lib\\site-packages\\scipy\\sparse\\base.py\u001b[0m in \u001b[0;36m__mul__\u001b[0;34m(self, other)\u001b[0m\n\u001b[1;32m    460\u001b[0m \u001b[0;34m\u001b[0m\u001b[0m\n\u001b[0;32m--> 461\u001b[0;31m         \u001b[0mM\u001b[0m\u001b[0;34m,\u001b[0m \u001b[0mN\u001b[0m \u001b[0;34m=\u001b[0m \u001b[0mself\u001b[0m\u001b[0;34m.\u001b[0m\u001b[0mshape\u001b[0m\u001b[0;34m\u001b[0m\u001b[0m\n\u001b[0m\u001b[1;32m    462\u001b[0m \u001b[0;34m\u001b[0m\u001b[0m\n",
      "\u001b[0;31mSystemError\u001b[0m: PyEval_EvalFrameEx returned a result with an error set",
      "\nDuring handling of the above exception, another exception occurred:\n",
      "\u001b[0;31mSystemError\u001b[0m                               Traceback (most recent call last)",
      "\u001b[0;32mC:\\Users\\irina\\Miniconda3\\envs\\exmc\\lib\\site-packages\\scipy\\sparse\\base.py\u001b[0m in \u001b[0;36m__mul__\u001b[0;34m(self, other)\u001b[0m\n\u001b[1;32m    460\u001b[0m \u001b[0;34m\u001b[0m\u001b[0m\n\u001b[0;32m--> 461\u001b[0;31m         \u001b[0mM\u001b[0m\u001b[0;34m,\u001b[0m \u001b[0mN\u001b[0m \u001b[0;34m=\u001b[0m \u001b[0mself\u001b[0m\u001b[0;34m.\u001b[0m\u001b[0mshape\u001b[0m\u001b[0;34m\u001b[0m\u001b[0m\n\u001b[0m\u001b[1;32m    462\u001b[0m \u001b[0;34m\u001b[0m\u001b[0m\n",
      "\u001b[0;31mSystemError\u001b[0m: PyEval_EvalFrameEx returned a result with an error set",
      "\nDuring handling of the above exception, another exception occurred:\n",
      "\u001b[0;31mSystemError\u001b[0m                               Traceback (most recent call last)",
      "\u001b[0;32mC:\\Users\\irina\\Miniconda3\\envs\\exmc\\lib\\site-packages\\scipy\\sparse\\base.py\u001b[0m in \u001b[0;36m__mul__\u001b[0;34m(self, other)\u001b[0m\n\u001b[1;32m    460\u001b[0m \u001b[0;34m\u001b[0m\u001b[0m\n\u001b[0;32m--> 461\u001b[0;31m         \u001b[0mM\u001b[0m\u001b[0;34m,\u001b[0m \u001b[0mN\u001b[0m \u001b[0;34m=\u001b[0m \u001b[0mself\u001b[0m\u001b[0;34m.\u001b[0m\u001b[0mshape\u001b[0m\u001b[0;34m\u001b[0m\u001b[0m\n\u001b[0m\u001b[1;32m    462\u001b[0m \u001b[0;34m\u001b[0m\u001b[0m\n",
      "\u001b[0;31mSystemError\u001b[0m: PyEval_EvalFrameEx returned a result with an error set",
      "\nDuring handling of the above exception, another exception occurred:\n",
      "\u001b[0;31mSystemError\u001b[0m                               Traceback (most recent call last)",
      "\u001b[0;32mC:\\Users\\irina\\Miniconda3\\envs\\exmc\\lib\\site-packages\\scipy\\sparse\\base.py\u001b[0m in \u001b[0;36m__mul__\u001b[0;34m(self, other)\u001b[0m\n\u001b[1;32m    460\u001b[0m \u001b[0;34m\u001b[0m\u001b[0m\n\u001b[0;32m--> 461\u001b[0;31m         \u001b[0mM\u001b[0m\u001b[0;34m,\u001b[0m \u001b[0mN\u001b[0m \u001b[0;34m=\u001b[0m \u001b[0mself\u001b[0m\u001b[0;34m.\u001b[0m\u001b[0mshape\u001b[0m\u001b[0;34m\u001b[0m\u001b[0m\n\u001b[0m\u001b[1;32m    462\u001b[0m \u001b[0;34m\u001b[0m\u001b[0m\n",
      "\u001b[0;31mSystemError\u001b[0m: PyEval_EvalFrameEx returned a result with an error set",
      "\nDuring handling of the above exception, another exception occurred:\n",
      "\u001b[0;31mSystemError\u001b[0m                               Traceback (most recent call last)",
      "\u001b[0;32mC:\\Users\\irina\\Miniconda3\\envs\\exmc\\lib\\site-packages\\scipy\\sparse\\base.py\u001b[0m in \u001b[0;36m__mul__\u001b[0;34m(self, other)\u001b[0m\n\u001b[1;32m    460\u001b[0m \u001b[0;34m\u001b[0m\u001b[0m\n\u001b[0;32m--> 461\u001b[0;31m         \u001b[0mM\u001b[0m\u001b[0;34m,\u001b[0m \u001b[0mN\u001b[0m \u001b[0;34m=\u001b[0m \u001b[0mself\u001b[0m\u001b[0;34m.\u001b[0m\u001b[0mshape\u001b[0m\u001b[0;34m\u001b[0m\u001b[0m\n\u001b[0m\u001b[1;32m    462\u001b[0m \u001b[0;34m\u001b[0m\u001b[0m\n",
      "\u001b[0;31mSystemError\u001b[0m: PyEval_EvalFrameEx returned a result with an error set",
      "\nDuring handling of the above exception, another exception occurred:\n",
      "\u001b[0;31mSystemError\u001b[0m                               Traceback (most recent call last)",
      "\u001b[0;32mC:\\Users\\irina\\Miniconda3\\envs\\exmc\\lib\\site-packages\\scipy\\sparse\\base.py\u001b[0m in \u001b[0;36m__mul__\u001b[0;34m(self, other)\u001b[0m\n\u001b[1;32m    460\u001b[0m \u001b[0;34m\u001b[0m\u001b[0m\n\u001b[0;32m--> 461\u001b[0;31m         \u001b[0mM\u001b[0m\u001b[0;34m,\u001b[0m \u001b[0mN\u001b[0m \u001b[0;34m=\u001b[0m \u001b[0mself\u001b[0m\u001b[0;34m.\u001b[0m\u001b[0mshape\u001b[0m\u001b[0;34m\u001b[0m\u001b[0m\n\u001b[0m\u001b[1;32m    462\u001b[0m \u001b[0;34m\u001b[0m\u001b[0m\n",
      "\u001b[0;31mSystemError\u001b[0m: PyEval_EvalFrameEx returned a result with an error set",
      "\nDuring handling of the above exception, another exception occurred:\n",
      "\u001b[0;31mSystemError\u001b[0m                               Traceback (most recent call last)",
      "\u001b[0;32mC:\\Users\\irina\\Miniconda3\\envs\\exmc\\lib\\site-packages\\scipy\\sparse\\base.py\u001b[0m in \u001b[0;36m__mul__\u001b[0;34m(self, other)\u001b[0m\n\u001b[1;32m    460\u001b[0m \u001b[0;34m\u001b[0m\u001b[0m\n\u001b[0;32m--> 461\u001b[0;31m         \u001b[0mM\u001b[0m\u001b[0;34m,\u001b[0m \u001b[0mN\u001b[0m \u001b[0;34m=\u001b[0m \u001b[0mself\u001b[0m\u001b[0;34m.\u001b[0m\u001b[0mshape\u001b[0m\u001b[0;34m\u001b[0m\u001b[0m\n\u001b[0m\u001b[1;32m    462\u001b[0m \u001b[0;34m\u001b[0m\u001b[0m\n",
      "\u001b[0;31mSystemError\u001b[0m: PyEval_EvalFrameEx returned a result with an error set",
      "\nDuring handling of the above exception, another exception occurred:\n",
      "\u001b[0;31mSystemError\u001b[0m                               Traceback (most recent call last)",
      "\u001b[0;32mC:\\Users\\irina\\Miniconda3\\envs\\exmc\\lib\\site-packages\\scipy\\sparse\\base.py\u001b[0m in \u001b[0;36m__mul__\u001b[0;34m(self, other)\u001b[0m\n\u001b[1;32m    460\u001b[0m \u001b[0;34m\u001b[0m\u001b[0m\n\u001b[0;32m--> 461\u001b[0;31m         \u001b[0mM\u001b[0m\u001b[0;34m,\u001b[0m \u001b[0mN\u001b[0m \u001b[0;34m=\u001b[0m \u001b[0mself\u001b[0m\u001b[0;34m.\u001b[0m\u001b[0mshape\u001b[0m\u001b[0;34m\u001b[0m\u001b[0m\n\u001b[0m\u001b[1;32m    462\u001b[0m \u001b[0;34m\u001b[0m\u001b[0m\n",
      "\u001b[0;31mSystemError\u001b[0m: PyEval_EvalFrameEx returned a result with an error set",
      "\nDuring handling of the above exception, another exception occurred:\n",
      "\u001b[0;31mSystemError\u001b[0m                               Traceback (most recent call last)",
      "\u001b[0;32mC:\\Users\\irina\\Miniconda3\\envs\\exmc\\lib\\site-packages\\scipy\\sparse\\base.py\u001b[0m in \u001b[0;36m__mul__\u001b[0;34m(self, other)\u001b[0m\n\u001b[1;32m    460\u001b[0m \u001b[0;34m\u001b[0m\u001b[0m\n\u001b[0;32m--> 461\u001b[0;31m         \u001b[0mM\u001b[0m\u001b[0;34m,\u001b[0m \u001b[0mN\u001b[0m \u001b[0;34m=\u001b[0m \u001b[0mself\u001b[0m\u001b[0;34m.\u001b[0m\u001b[0mshape\u001b[0m\u001b[0;34m\u001b[0m\u001b[0m\n\u001b[0m\u001b[1;32m    462\u001b[0m \u001b[0;34m\u001b[0m\u001b[0m\n",
      "\u001b[0;31mSystemError\u001b[0m: PyEval_EvalFrameEx returned a result with an error set",
      "\nDuring handling of the above exception, another exception occurred:\n",
      "\u001b[0;31mSystemError\u001b[0m                               Traceback (most recent call last)",
      "\u001b[0;32mC:\\Users\\irina\\Miniconda3\\envs\\exmc\\lib\\site-packages\\scipy\\sparse\\base.py\u001b[0m in \u001b[0;36m__mul__\u001b[0;34m(self, other)\u001b[0m\n\u001b[1;32m    460\u001b[0m \u001b[0;34m\u001b[0m\u001b[0m\n\u001b[0;32m--> 461\u001b[0;31m         \u001b[0mM\u001b[0m\u001b[0;34m,\u001b[0m \u001b[0mN\u001b[0m \u001b[0;34m=\u001b[0m \u001b[0mself\u001b[0m\u001b[0;34m.\u001b[0m\u001b[0mshape\u001b[0m\u001b[0;34m\u001b[0m\u001b[0m\n\u001b[0m\u001b[1;32m    462\u001b[0m \u001b[0;34m\u001b[0m\u001b[0m\n",
      "\u001b[0;31mSystemError\u001b[0m: PyEval_EvalFrameEx returned a result with an error set",
      "\nDuring handling of the above exception, another exception occurred:\n",
      "\u001b[0;31mSystemError\u001b[0m                               Traceback (most recent call last)",
      "\u001b[0;32mC:\\Users\\irina\\Miniconda3\\envs\\exmc\\lib\\site-packages\\scipy\\sparse\\base.py\u001b[0m in \u001b[0;36m__mul__\u001b[0;34m(self, other)\u001b[0m\n\u001b[1;32m    460\u001b[0m \u001b[0;34m\u001b[0m\u001b[0m\n\u001b[0;32m--> 461\u001b[0;31m         \u001b[0mM\u001b[0m\u001b[0;34m,\u001b[0m \u001b[0mN\u001b[0m \u001b[0;34m=\u001b[0m \u001b[0mself\u001b[0m\u001b[0;34m.\u001b[0m\u001b[0mshape\u001b[0m\u001b[0;34m\u001b[0m\u001b[0m\n\u001b[0m\u001b[1;32m    462\u001b[0m \u001b[0;34m\u001b[0m\u001b[0m\n",
      "\u001b[0;31mSystemError\u001b[0m: PyEval_EvalFrameEx returned a result with an error set",
      "\nDuring handling of the above exception, another exception occurred:\n",
      "\u001b[0;31mSystemError\u001b[0m                               Traceback (most recent call last)",
      "\u001b[0;32mC:\\Users\\irina\\Miniconda3\\envs\\exmc\\lib\\site-packages\\scipy\\sparse\\base.py\u001b[0m in \u001b[0;36m__mul__\u001b[0;34m(self, other)\u001b[0m\n\u001b[1;32m    460\u001b[0m \u001b[0;34m\u001b[0m\u001b[0m\n\u001b[0;32m--> 461\u001b[0;31m         \u001b[0mM\u001b[0m\u001b[0;34m,\u001b[0m \u001b[0mN\u001b[0m \u001b[0;34m=\u001b[0m \u001b[0mself\u001b[0m\u001b[0;34m.\u001b[0m\u001b[0mshape\u001b[0m\u001b[0;34m\u001b[0m\u001b[0m\n\u001b[0m\u001b[1;32m    462\u001b[0m \u001b[0;34m\u001b[0m\u001b[0m\n",
      "\u001b[0;31mSystemError\u001b[0m: PyEval_EvalFrameEx returned a result with an error set",
      "\nDuring handling of the above exception, another exception occurred:\n",
      "\u001b[0;31mSystemError\u001b[0m                               Traceback (most recent call last)",
      "\u001b[0;32mC:\\Users\\irina\\Miniconda3\\envs\\exmc\\lib\\site-packages\\scipy\\sparse\\base.py\u001b[0m in \u001b[0;36m__mul__\u001b[0;34m(self, other)\u001b[0m\n\u001b[1;32m    460\u001b[0m \u001b[0;34m\u001b[0m\u001b[0m\n\u001b[0;32m--> 461\u001b[0;31m         \u001b[0mM\u001b[0m\u001b[0;34m,\u001b[0m \u001b[0mN\u001b[0m \u001b[0;34m=\u001b[0m \u001b[0mself\u001b[0m\u001b[0;34m.\u001b[0m\u001b[0mshape\u001b[0m\u001b[0;34m\u001b[0m\u001b[0m\n\u001b[0m\u001b[1;32m    462\u001b[0m \u001b[0;34m\u001b[0m\u001b[0m\n",
      "\u001b[0;31mSystemError\u001b[0m: PyEval_EvalFrameEx returned a result with an error set",
      "\nDuring handling of the above exception, another exception occurred:\n",
      "\u001b[0;31mSystemError\u001b[0m                               Traceback (most recent call last)",
      "\u001b[0;32mC:\\Users\\irina\\Miniconda3\\envs\\exmc\\lib\\site-packages\\scipy\\sparse\\base.py\u001b[0m in \u001b[0;36m__mul__\u001b[0;34m(self, other)\u001b[0m\n\u001b[1;32m    460\u001b[0m \u001b[0;34m\u001b[0m\u001b[0m\n\u001b[0;32m--> 461\u001b[0;31m         \u001b[0mM\u001b[0m\u001b[0;34m,\u001b[0m \u001b[0mN\u001b[0m \u001b[0;34m=\u001b[0m \u001b[0mself\u001b[0m\u001b[0;34m.\u001b[0m\u001b[0mshape\u001b[0m\u001b[0;34m\u001b[0m\u001b[0m\n\u001b[0m\u001b[1;32m    462\u001b[0m \u001b[0;34m\u001b[0m\u001b[0m\n",
      "\u001b[0;31mSystemError\u001b[0m: PyEval_EvalFrameEx returned a result with an error set",
      "\nDuring handling of the above exception, another exception occurred:\n",
      "\u001b[0;31mSystemError\u001b[0m                               Traceback (most recent call last)",
      "\u001b[0;32mC:\\Users\\irina\\Miniconda3\\envs\\exmc\\lib\\site-packages\\scipy\\sparse\\base.py\u001b[0m in \u001b[0;36m__mul__\u001b[0;34m(self, other)\u001b[0m\n\u001b[1;32m    460\u001b[0m \u001b[0;34m\u001b[0m\u001b[0m\n\u001b[0;32m--> 461\u001b[0;31m         \u001b[0mM\u001b[0m\u001b[0;34m,\u001b[0m \u001b[0mN\u001b[0m \u001b[0;34m=\u001b[0m \u001b[0mself\u001b[0m\u001b[0;34m.\u001b[0m\u001b[0mshape\u001b[0m\u001b[0;34m\u001b[0m\u001b[0m\n\u001b[0m\u001b[1;32m    462\u001b[0m \u001b[0;34m\u001b[0m\u001b[0m\n",
      "\u001b[0;31mSystemError\u001b[0m: PyEval_EvalFrameEx returned a result with an error set",
      "\nDuring handling of the above exception, another exception occurred:\n",
      "\u001b[0;31mSystemError\u001b[0m                               Traceback (most recent call last)",
      "\u001b[0;32mC:\\Users\\irina\\Miniconda3\\envs\\exmc\\lib\\site-packages\\scipy\\sparse\\base.py\u001b[0m in \u001b[0;36m__mul__\u001b[0;34m(self, other)\u001b[0m\n\u001b[1;32m    460\u001b[0m \u001b[0;34m\u001b[0m\u001b[0m\n\u001b[0;32m--> 461\u001b[0;31m         \u001b[0mM\u001b[0m\u001b[0;34m,\u001b[0m \u001b[0mN\u001b[0m \u001b[0;34m=\u001b[0m \u001b[0mself\u001b[0m\u001b[0;34m.\u001b[0m\u001b[0mshape\u001b[0m\u001b[0;34m\u001b[0m\u001b[0m\n\u001b[0m\u001b[1;32m    462\u001b[0m \u001b[0;34m\u001b[0m\u001b[0m\n",
      "\u001b[0;31mSystemError\u001b[0m: PyEval_EvalFrameEx returned a result with an error set",
      "\nDuring handling of the above exception, another exception occurred:\n",
      "\u001b[0;31mSystemError\u001b[0m                               Traceback (most recent call last)",
      "\u001b[0;32mC:\\Users\\irina\\Miniconda3\\envs\\exmc\\lib\\site-packages\\scipy\\sparse\\base.py\u001b[0m in \u001b[0;36m__mul__\u001b[0;34m(self, other)\u001b[0m\n\u001b[1;32m    460\u001b[0m \u001b[0;34m\u001b[0m\u001b[0m\n\u001b[0;32m--> 461\u001b[0;31m         \u001b[0mM\u001b[0m\u001b[0;34m,\u001b[0m \u001b[0mN\u001b[0m \u001b[0;34m=\u001b[0m \u001b[0mself\u001b[0m\u001b[0;34m.\u001b[0m\u001b[0mshape\u001b[0m\u001b[0;34m\u001b[0m\u001b[0m\n\u001b[0m\u001b[1;32m    462\u001b[0m \u001b[0;34m\u001b[0m\u001b[0m\n",
      "\u001b[0;31mSystemError\u001b[0m: PyEval_EvalFrameEx returned a result with an error set",
      "\nDuring handling of the above exception, another exception occurred:\n",
      "\u001b[0;31mSystemError\u001b[0m                               Traceback (most recent call last)",
      "\u001b[0;32mC:\\Users\\irina\\Miniconda3\\envs\\exmc\\lib\\site-packages\\scipy\\sparse\\base.py\u001b[0m in \u001b[0;36m__mul__\u001b[0;34m(self, other)\u001b[0m\n\u001b[1;32m    460\u001b[0m \u001b[0;34m\u001b[0m\u001b[0m\n\u001b[0;32m--> 461\u001b[0;31m         \u001b[0mM\u001b[0m\u001b[0;34m,\u001b[0m \u001b[0mN\u001b[0m \u001b[0;34m=\u001b[0m \u001b[0mself\u001b[0m\u001b[0;34m.\u001b[0m\u001b[0mshape\u001b[0m\u001b[0;34m\u001b[0m\u001b[0m\n\u001b[0m\u001b[1;32m    462\u001b[0m \u001b[0;34m\u001b[0m\u001b[0m\n",
      "\u001b[0;31mSystemError\u001b[0m: PyEval_EvalFrameEx returned a result with an error set",
      "\nDuring handling of the above exception, another exception occurred:\n",
      "\u001b[0;31mSystemError\u001b[0m                               Traceback (most recent call last)",
      "\u001b[0;32mC:\\Users\\irina\\Miniconda3\\envs\\exmc\\lib\\site-packages\\scipy\\sparse\\base.py\u001b[0m in \u001b[0;36m__mul__\u001b[0;34m(self, other)\u001b[0m\n\u001b[1;32m    460\u001b[0m \u001b[0;34m\u001b[0m\u001b[0m\n\u001b[0;32m--> 461\u001b[0;31m         \u001b[0mM\u001b[0m\u001b[0;34m,\u001b[0m \u001b[0mN\u001b[0m \u001b[0;34m=\u001b[0m \u001b[0mself\u001b[0m\u001b[0;34m.\u001b[0m\u001b[0mshape\u001b[0m\u001b[0;34m\u001b[0m\u001b[0m\n\u001b[0m\u001b[1;32m    462\u001b[0m \u001b[0;34m\u001b[0m\u001b[0m\n",
      "\u001b[0;31mSystemError\u001b[0m: PyEval_EvalFrameEx returned a result with an error set",
      "\nDuring handling of the above exception, another exception occurred:\n",
      "\u001b[0;31mSystemError\u001b[0m                               Traceback (most recent call last)",
      "\u001b[0;32mC:\\Users\\irina\\Miniconda3\\envs\\exmc\\lib\\site-packages\\scipy\\sparse\\base.py\u001b[0m in \u001b[0;36m__mul__\u001b[0;34m(self, other)\u001b[0m\n\u001b[1;32m    460\u001b[0m \u001b[0;34m\u001b[0m\u001b[0m\n\u001b[0;32m--> 461\u001b[0;31m         \u001b[0mM\u001b[0m\u001b[0;34m,\u001b[0m \u001b[0mN\u001b[0m \u001b[0;34m=\u001b[0m \u001b[0mself\u001b[0m\u001b[0;34m.\u001b[0m\u001b[0mshape\u001b[0m\u001b[0;34m\u001b[0m\u001b[0m\n\u001b[0m\u001b[1;32m    462\u001b[0m \u001b[0;34m\u001b[0m\u001b[0m\n",
      "\u001b[0;31mSystemError\u001b[0m: PyEval_EvalFrameEx returned a result with an error set",
      "\nDuring handling of the above exception, another exception occurred:\n",
      "\u001b[0;31mSystemError\u001b[0m                               Traceback (most recent call last)",
      "\u001b[0;32mC:\\Users\\irina\\Miniconda3\\envs\\exmc\\lib\\site-packages\\scipy\\sparse\\base.py\u001b[0m in \u001b[0;36m__mul__\u001b[0;34m(self, other)\u001b[0m\n\u001b[1;32m    460\u001b[0m \u001b[0;34m\u001b[0m\u001b[0m\n\u001b[0;32m--> 461\u001b[0;31m         \u001b[0mM\u001b[0m\u001b[0;34m,\u001b[0m \u001b[0mN\u001b[0m \u001b[0;34m=\u001b[0m \u001b[0mself\u001b[0m\u001b[0;34m.\u001b[0m\u001b[0mshape\u001b[0m\u001b[0;34m\u001b[0m\u001b[0m\n\u001b[0m\u001b[1;32m    462\u001b[0m \u001b[0;34m\u001b[0m\u001b[0m\n",
      "\u001b[0;31mSystemError\u001b[0m: PyEval_EvalFrameEx returned a result with an error set",
      "\nDuring handling of the above exception, another exception occurred:\n",
      "\u001b[0;31mSystemError\u001b[0m                               Traceback (most recent call last)",
      "\u001b[0;32mC:\\Users\\irina\\Miniconda3\\envs\\exmc\\lib\\site-packages\\scipy\\sparse\\base.py\u001b[0m in \u001b[0;36m__mul__\u001b[0;34m(self, other)\u001b[0m\n\u001b[1;32m    460\u001b[0m \u001b[0;34m\u001b[0m\u001b[0m\n\u001b[0;32m--> 461\u001b[0;31m         \u001b[0mM\u001b[0m\u001b[0;34m,\u001b[0m \u001b[0mN\u001b[0m \u001b[0;34m=\u001b[0m \u001b[0mself\u001b[0m\u001b[0;34m.\u001b[0m\u001b[0mshape\u001b[0m\u001b[0;34m\u001b[0m\u001b[0m\n\u001b[0m\u001b[1;32m    462\u001b[0m \u001b[0;34m\u001b[0m\u001b[0m\n",
      "\u001b[0;31mSystemError\u001b[0m: PyEval_EvalFrameEx returned a result with an error set",
      "\nDuring handling of the above exception, another exception occurred:\n",
      "\u001b[0;31mSystemError\u001b[0m                               Traceback (most recent call last)",
      "\u001b[0;32mC:\\Users\\irina\\Miniconda3\\envs\\exmc\\lib\\site-packages\\scipy\\sparse\\base.py\u001b[0m in \u001b[0;36m__mul__\u001b[0;34m(self, other)\u001b[0m\n\u001b[1;32m    460\u001b[0m \u001b[0;34m\u001b[0m\u001b[0m\n\u001b[0;32m--> 461\u001b[0;31m         \u001b[0mM\u001b[0m\u001b[0;34m,\u001b[0m \u001b[0mN\u001b[0m \u001b[0;34m=\u001b[0m \u001b[0mself\u001b[0m\u001b[0;34m.\u001b[0m\u001b[0mshape\u001b[0m\u001b[0;34m\u001b[0m\u001b[0m\n\u001b[0m\u001b[1;32m    462\u001b[0m \u001b[0;34m\u001b[0m\u001b[0m\n",
      "\u001b[0;31mSystemError\u001b[0m: PyEval_EvalFrameEx returned a result with an error set",
      "\nDuring handling of the above exception, another exception occurred:\n",
      "\u001b[0;31mSystemError\u001b[0m                               Traceback (most recent call last)",
      "\u001b[0;32mC:\\Users\\irina\\Miniconda3\\envs\\exmc\\lib\\site-packages\\scipy\\sparse\\base.py\u001b[0m in \u001b[0;36m__mul__\u001b[0;34m(self, other)\u001b[0m\n\u001b[1;32m    460\u001b[0m \u001b[0;34m\u001b[0m\u001b[0m\n\u001b[0;32m--> 461\u001b[0;31m         \u001b[0mM\u001b[0m\u001b[0;34m,\u001b[0m \u001b[0mN\u001b[0m \u001b[0;34m=\u001b[0m \u001b[0mself\u001b[0m\u001b[0;34m.\u001b[0m\u001b[0mshape\u001b[0m\u001b[0;34m\u001b[0m\u001b[0m\n\u001b[0m\u001b[1;32m    462\u001b[0m \u001b[0;34m\u001b[0m\u001b[0m\n",
      "\u001b[0;31mSystemError\u001b[0m: PyEval_EvalFrameEx returned a result with an error set",
      "\nDuring handling of the above exception, another exception occurred:\n",
      "\u001b[0;31mSystemError\u001b[0m                               Traceback (most recent call last)",
      "\u001b[0;32mC:\\Users\\irina\\Miniconda3\\envs\\exmc\\lib\\site-packages\\scipy\\sparse\\base.py\u001b[0m in \u001b[0;36m__mul__\u001b[0;34m(self, other)\u001b[0m\n\u001b[1;32m    460\u001b[0m \u001b[0;34m\u001b[0m\u001b[0m\n\u001b[0;32m--> 461\u001b[0;31m         \u001b[0mM\u001b[0m\u001b[0;34m,\u001b[0m \u001b[0mN\u001b[0m \u001b[0;34m=\u001b[0m \u001b[0mself\u001b[0m\u001b[0;34m.\u001b[0m\u001b[0mshape\u001b[0m\u001b[0;34m\u001b[0m\u001b[0m\n\u001b[0m\u001b[1;32m    462\u001b[0m \u001b[0;34m\u001b[0m\u001b[0m\n",
      "\u001b[0;31mSystemError\u001b[0m: PyEval_EvalFrameEx returned a result with an error set",
      "\nDuring handling of the above exception, another exception occurred:\n",
      "\u001b[0;31mSystemError\u001b[0m                               Traceback (most recent call last)",
      "\u001b[0;32mC:\\Users\\irina\\Miniconda3\\envs\\exmc\\lib\\site-packages\\scipy\\sparse\\base.py\u001b[0m in \u001b[0;36m__mul__\u001b[0;34m(self, other)\u001b[0m\n\u001b[1;32m    460\u001b[0m \u001b[0;34m\u001b[0m\u001b[0m\n\u001b[0;32m--> 461\u001b[0;31m         \u001b[0mM\u001b[0m\u001b[0;34m,\u001b[0m \u001b[0mN\u001b[0m \u001b[0;34m=\u001b[0m \u001b[0mself\u001b[0m\u001b[0;34m.\u001b[0m\u001b[0mshape\u001b[0m\u001b[0;34m\u001b[0m\u001b[0m\n\u001b[0m\u001b[1;32m    462\u001b[0m \u001b[0;34m\u001b[0m\u001b[0m\n",
      "\u001b[0;31mSystemError\u001b[0m: PyEval_EvalFrameEx returned a result with an error set",
      "\nDuring handling of the above exception, another exception occurred:\n",
      "\u001b[0;31mSystemError\u001b[0m                               Traceback (most recent call last)",
      "\u001b[0;32mC:\\Users\\irina\\Miniconda3\\envs\\exmc\\lib\\site-packages\\scipy\\sparse\\base.py\u001b[0m in \u001b[0;36m__mul__\u001b[0;34m(self, other)\u001b[0m\n\u001b[1;32m    460\u001b[0m \u001b[0;34m\u001b[0m\u001b[0m\n\u001b[0;32m--> 461\u001b[0;31m         \u001b[0mM\u001b[0m\u001b[0;34m,\u001b[0m \u001b[0mN\u001b[0m \u001b[0;34m=\u001b[0m \u001b[0mself\u001b[0m\u001b[0;34m.\u001b[0m\u001b[0mshape\u001b[0m\u001b[0;34m\u001b[0m\u001b[0m\n\u001b[0m\u001b[1;32m    462\u001b[0m \u001b[0;34m\u001b[0m\u001b[0m\n",
      "\u001b[0;31mSystemError\u001b[0m: PyEval_EvalFrameEx returned a result with an error set",
      "\nDuring handling of the above exception, another exception occurred:\n",
      "\u001b[0;31mSystemError\u001b[0m                               Traceback (most recent call last)",
      "\u001b[0;32mC:\\Users\\irina\\Miniconda3\\envs\\exmc\\lib\\site-packages\\scipy\\sparse\\base.py\u001b[0m in \u001b[0;36m__mul__\u001b[0;34m(self, other)\u001b[0m\n\u001b[1;32m    460\u001b[0m \u001b[0;34m\u001b[0m\u001b[0m\n\u001b[0;32m--> 461\u001b[0;31m         \u001b[0mM\u001b[0m\u001b[0;34m,\u001b[0m \u001b[0mN\u001b[0m \u001b[0;34m=\u001b[0m \u001b[0mself\u001b[0m\u001b[0;34m.\u001b[0m\u001b[0mshape\u001b[0m\u001b[0;34m\u001b[0m\u001b[0m\n\u001b[0m\u001b[1;32m    462\u001b[0m \u001b[0;34m\u001b[0m\u001b[0m\n",
      "\u001b[0;31mSystemError\u001b[0m: PyEval_EvalFrameEx returned a result with an error set",
      "\nDuring handling of the above exception, another exception occurred:\n",
      "\u001b[0;31mSystemError\u001b[0m                               Traceback (most recent call last)",
      "\u001b[0;32mC:\\Users\\irina\\Miniconda3\\envs\\exmc\\lib\\site-packages\\scipy\\sparse\\base.py\u001b[0m in \u001b[0;36m__mul__\u001b[0;34m(self, other)\u001b[0m\n\u001b[1;32m    460\u001b[0m \u001b[0;34m\u001b[0m\u001b[0m\n\u001b[0;32m--> 461\u001b[0;31m         \u001b[0mM\u001b[0m\u001b[0;34m,\u001b[0m \u001b[0mN\u001b[0m \u001b[0;34m=\u001b[0m \u001b[0mself\u001b[0m\u001b[0;34m.\u001b[0m\u001b[0mshape\u001b[0m\u001b[0;34m\u001b[0m\u001b[0m\n\u001b[0m\u001b[1;32m    462\u001b[0m \u001b[0;34m\u001b[0m\u001b[0m\n",
      "\u001b[0;31mSystemError\u001b[0m: PyEval_EvalFrameEx returned a result with an error set",
      "\nDuring handling of the above exception, another exception occurred:\n",
      "\u001b[0;31mSystemError\u001b[0m                               Traceback (most recent call last)",
      "\u001b[0;32mC:\\Users\\irina\\Miniconda3\\envs\\exmc\\lib\\site-packages\\scipy\\sparse\\base.py\u001b[0m in \u001b[0;36m__mul__\u001b[0;34m(self, other)\u001b[0m\n\u001b[1;32m    460\u001b[0m \u001b[0;34m\u001b[0m\u001b[0m\n\u001b[0;32m--> 461\u001b[0;31m         \u001b[0mM\u001b[0m\u001b[0;34m,\u001b[0m \u001b[0mN\u001b[0m \u001b[0;34m=\u001b[0m \u001b[0mself\u001b[0m\u001b[0;34m.\u001b[0m\u001b[0mshape\u001b[0m\u001b[0;34m\u001b[0m\u001b[0m\n\u001b[0m\u001b[1;32m    462\u001b[0m \u001b[0;34m\u001b[0m\u001b[0m\n",
      "\u001b[0;31mSystemError\u001b[0m: PyEval_EvalFrameEx returned a result with an error set",
      "\nDuring handling of the above exception, another exception occurred:\n",
      "\u001b[0;31mSystemError\u001b[0m                               Traceback (most recent call last)",
      "\u001b[0;32mC:\\Users\\irina\\Miniconda3\\envs\\exmc\\lib\\site-packages\\scipy\\sparse\\base.py\u001b[0m in \u001b[0;36m__mul__\u001b[0;34m(self, other)\u001b[0m\n\u001b[1;32m    460\u001b[0m \u001b[0;34m\u001b[0m\u001b[0m\n\u001b[0;32m--> 461\u001b[0;31m         \u001b[0mM\u001b[0m\u001b[0;34m,\u001b[0m \u001b[0mN\u001b[0m \u001b[0;34m=\u001b[0m \u001b[0mself\u001b[0m\u001b[0;34m.\u001b[0m\u001b[0mshape\u001b[0m\u001b[0;34m\u001b[0m\u001b[0m\n\u001b[0m\u001b[1;32m    462\u001b[0m \u001b[0;34m\u001b[0m\u001b[0m\n",
      "\u001b[0;31mSystemError\u001b[0m: PyEval_EvalFrameEx returned a result with an error set",
      "\nDuring handling of the above exception, another exception occurred:\n",
      "\u001b[0;31mSystemError\u001b[0m                               Traceback (most recent call last)",
      "\u001b[0;32mC:\\Users\\irina\\Miniconda3\\envs\\exmc\\lib\\site-packages\\scipy\\sparse\\base.py\u001b[0m in \u001b[0;36m__mul__\u001b[0;34m(self, other)\u001b[0m\n\u001b[1;32m    460\u001b[0m \u001b[0;34m\u001b[0m\u001b[0m\n\u001b[0;32m--> 461\u001b[0;31m         \u001b[0mM\u001b[0m\u001b[0;34m,\u001b[0m \u001b[0mN\u001b[0m \u001b[0;34m=\u001b[0m \u001b[0mself\u001b[0m\u001b[0;34m.\u001b[0m\u001b[0mshape\u001b[0m\u001b[0;34m\u001b[0m\u001b[0m\n\u001b[0m\u001b[1;32m    462\u001b[0m \u001b[0;34m\u001b[0m\u001b[0m\n",
      "\u001b[0;31mSystemError\u001b[0m: PyEval_EvalFrameEx returned a result with an error set",
      "\nDuring handling of the above exception, another exception occurred:\n",
      "\u001b[0;31mSystemError\u001b[0m                               Traceback (most recent call last)",
      "\u001b[0;32mC:\\Users\\irina\\Miniconda3\\envs\\exmc\\lib\\site-packages\\scipy\\sparse\\base.py\u001b[0m in \u001b[0;36m__mul__\u001b[0;34m(self, other)\u001b[0m\n\u001b[1;32m    460\u001b[0m \u001b[0;34m\u001b[0m\u001b[0m\n\u001b[0;32m--> 461\u001b[0;31m         \u001b[0mM\u001b[0m\u001b[0;34m,\u001b[0m \u001b[0mN\u001b[0m \u001b[0;34m=\u001b[0m \u001b[0mself\u001b[0m\u001b[0;34m.\u001b[0m\u001b[0mshape\u001b[0m\u001b[0;34m\u001b[0m\u001b[0m\n\u001b[0m\u001b[1;32m    462\u001b[0m \u001b[0;34m\u001b[0m\u001b[0m\n",
      "\u001b[0;31mSystemError\u001b[0m: PyEval_EvalFrameEx returned a result with an error set",
      "\nDuring handling of the above exception, another exception occurred:\n",
      "\u001b[0;31mSystemError\u001b[0m                               Traceback (most recent call last)",
      "\u001b[0;32mC:\\Users\\irina\\Miniconda3\\envs\\exmc\\lib\\site-packages\\scipy\\sparse\\base.py\u001b[0m in \u001b[0;36m__mul__\u001b[0;34m(self, other)\u001b[0m\n\u001b[1;32m    460\u001b[0m \u001b[0;34m\u001b[0m\u001b[0m\n\u001b[0;32m--> 461\u001b[0;31m         \u001b[0mM\u001b[0m\u001b[0;34m,\u001b[0m \u001b[0mN\u001b[0m \u001b[0;34m=\u001b[0m \u001b[0mself\u001b[0m\u001b[0;34m.\u001b[0m\u001b[0mshape\u001b[0m\u001b[0;34m\u001b[0m\u001b[0m\n\u001b[0m\u001b[1;32m    462\u001b[0m \u001b[0;34m\u001b[0m\u001b[0m\n",
      "\u001b[0;31mSystemError\u001b[0m: PyEval_EvalFrameEx returned a result with an error set",
      "\nDuring handling of the above exception, another exception occurred:\n",
      "\u001b[0;31mSystemError\u001b[0m                               Traceback (most recent call last)",
      "\u001b[0;32mC:\\Users\\irina\\Miniconda3\\envs\\exmc\\lib\\site-packages\\scipy\\sparse\\base.py\u001b[0m in \u001b[0;36m__mul__\u001b[0;34m(self, other)\u001b[0m\n\u001b[1;32m    460\u001b[0m \u001b[0;34m\u001b[0m\u001b[0m\n\u001b[0;32m--> 461\u001b[0;31m         \u001b[0mM\u001b[0m\u001b[0;34m,\u001b[0m \u001b[0mN\u001b[0m \u001b[0;34m=\u001b[0m \u001b[0mself\u001b[0m\u001b[0;34m.\u001b[0m\u001b[0mshape\u001b[0m\u001b[0;34m\u001b[0m\u001b[0m\n\u001b[0m\u001b[1;32m    462\u001b[0m \u001b[0;34m\u001b[0m\u001b[0m\n",
      "\u001b[0;31mSystemError\u001b[0m: PyEval_EvalFrameEx returned a result with an error set",
      "\nDuring handling of the above exception, another exception occurred:\n",
      "\u001b[0;31mSystemError\u001b[0m                               Traceback (most recent call last)",
      "\u001b[0;32mC:\\Users\\irina\\Miniconda3\\envs\\exmc\\lib\\site-packages\\scipy\\sparse\\base.py\u001b[0m in \u001b[0;36m__mul__\u001b[0;34m(self, other)\u001b[0m\n\u001b[1;32m    460\u001b[0m \u001b[0;34m\u001b[0m\u001b[0m\n\u001b[0;32m--> 461\u001b[0;31m         \u001b[0mM\u001b[0m\u001b[0;34m,\u001b[0m \u001b[0mN\u001b[0m \u001b[0;34m=\u001b[0m \u001b[0mself\u001b[0m\u001b[0;34m.\u001b[0m\u001b[0mshape\u001b[0m\u001b[0;34m\u001b[0m\u001b[0m\n\u001b[0m\u001b[1;32m    462\u001b[0m \u001b[0;34m\u001b[0m\u001b[0m\n",
      "\u001b[0;31mSystemError\u001b[0m: PyEval_EvalFrameEx returned a result with an error set",
      "\nDuring handling of the above exception, another exception occurred:\n",
      "\u001b[0;31mSystemError\u001b[0m                               Traceback (most recent call last)",
      "\u001b[0;32mC:\\Users\\irina\\Miniconda3\\envs\\exmc\\lib\\site-packages\\scipy\\sparse\\base.py\u001b[0m in \u001b[0;36m__mul__\u001b[0;34m(self, other)\u001b[0m\n\u001b[1;32m    460\u001b[0m \u001b[0;34m\u001b[0m\u001b[0m\n\u001b[0;32m--> 461\u001b[0;31m         \u001b[0mM\u001b[0m\u001b[0;34m,\u001b[0m \u001b[0mN\u001b[0m \u001b[0;34m=\u001b[0m \u001b[0mself\u001b[0m\u001b[0;34m.\u001b[0m\u001b[0mshape\u001b[0m\u001b[0;34m\u001b[0m\u001b[0m\n\u001b[0m\u001b[1;32m    462\u001b[0m \u001b[0;34m\u001b[0m\u001b[0m\n",
      "\u001b[0;31mSystemError\u001b[0m: PyEval_EvalFrameEx returned a result with an error set",
      "\nDuring handling of the above exception, another exception occurred:\n",
      "\u001b[0;31mSystemError\u001b[0m                               Traceback (most recent call last)",
      "\u001b[0;32mC:\\Users\\irina\\Miniconda3\\envs\\exmc\\lib\\site-packages\\scipy\\sparse\\base.py\u001b[0m in \u001b[0;36m__mul__\u001b[0;34m(self, other)\u001b[0m\n\u001b[1;32m    460\u001b[0m \u001b[0;34m\u001b[0m\u001b[0m\n\u001b[0;32m--> 461\u001b[0;31m         \u001b[0mM\u001b[0m\u001b[0;34m,\u001b[0m \u001b[0mN\u001b[0m \u001b[0;34m=\u001b[0m \u001b[0mself\u001b[0m\u001b[0;34m.\u001b[0m\u001b[0mshape\u001b[0m\u001b[0;34m\u001b[0m\u001b[0m\n\u001b[0m\u001b[1;32m    462\u001b[0m \u001b[0;34m\u001b[0m\u001b[0m\n",
      "\u001b[0;31mSystemError\u001b[0m: PyEval_EvalFrameEx returned a result with an error set",
      "\nDuring handling of the above exception, another exception occurred:\n",
      "\u001b[0;31mSystemError\u001b[0m                               Traceback (most recent call last)",
      "\u001b[0;32mC:\\Users\\irina\\Miniconda3\\envs\\exmc\\lib\\site-packages\\scipy\\sparse\\base.py\u001b[0m in \u001b[0;36m__mul__\u001b[0;34m(self, other)\u001b[0m\n\u001b[1;32m    460\u001b[0m \u001b[0;34m\u001b[0m\u001b[0m\n\u001b[0;32m--> 461\u001b[0;31m         \u001b[0mM\u001b[0m\u001b[0;34m,\u001b[0m \u001b[0mN\u001b[0m \u001b[0;34m=\u001b[0m \u001b[0mself\u001b[0m\u001b[0;34m.\u001b[0m\u001b[0mshape\u001b[0m\u001b[0;34m\u001b[0m\u001b[0m\n\u001b[0m\u001b[1;32m    462\u001b[0m \u001b[0;34m\u001b[0m\u001b[0m\n",
      "\u001b[0;31mSystemError\u001b[0m: PyEval_EvalFrameEx returned a result with an error set",
      "\nDuring handling of the above exception, another exception occurred:\n",
      "\u001b[0;31mSystemError\u001b[0m                               Traceback (most recent call last)",
      "\u001b[0;32mC:\\Users\\irina\\Miniconda3\\envs\\exmc\\lib\\site-packages\\scipy\\sparse\\base.py\u001b[0m in \u001b[0;36m__mul__\u001b[0;34m(self, other)\u001b[0m\n\u001b[1;32m    460\u001b[0m \u001b[0;34m\u001b[0m\u001b[0m\n\u001b[0;32m--> 461\u001b[0;31m         \u001b[0mM\u001b[0m\u001b[0;34m,\u001b[0m \u001b[0mN\u001b[0m \u001b[0;34m=\u001b[0m \u001b[0mself\u001b[0m\u001b[0;34m.\u001b[0m\u001b[0mshape\u001b[0m\u001b[0;34m\u001b[0m\u001b[0m\n\u001b[0m\u001b[1;32m    462\u001b[0m \u001b[0;34m\u001b[0m\u001b[0m\n",
      "\u001b[0;31mSystemError\u001b[0m: PyEval_EvalFrameEx returned a result with an error set",
      "\nDuring handling of the above exception, another exception occurred:\n",
      "\u001b[0;31mSystemError\u001b[0m                               Traceback (most recent call last)",
      "\u001b[0;32mC:\\Users\\irina\\Miniconda3\\envs\\exmc\\lib\\site-packages\\scipy\\sparse\\base.py\u001b[0m in \u001b[0;36m__mul__\u001b[0;34m(self, other)\u001b[0m\n\u001b[1;32m    460\u001b[0m \u001b[0;34m\u001b[0m\u001b[0m\n\u001b[0;32m--> 461\u001b[0;31m         \u001b[0mM\u001b[0m\u001b[0;34m,\u001b[0m \u001b[0mN\u001b[0m \u001b[0;34m=\u001b[0m \u001b[0mself\u001b[0m\u001b[0;34m.\u001b[0m\u001b[0mshape\u001b[0m\u001b[0;34m\u001b[0m\u001b[0m\n\u001b[0m\u001b[1;32m    462\u001b[0m \u001b[0;34m\u001b[0m\u001b[0m\n",
      "\u001b[0;31mSystemError\u001b[0m: PyEval_EvalFrameEx returned a result with an error set",
      "\nDuring handling of the above exception, another exception occurred:\n",
      "\u001b[0;31mSystemError\u001b[0m                               Traceback (most recent call last)",
      "\u001b[0;32mC:\\Users\\irina\\Miniconda3\\envs\\exmc\\lib\\site-packages\\scipy\\sparse\\base.py\u001b[0m in \u001b[0;36m__mul__\u001b[0;34m(self, other)\u001b[0m\n\u001b[1;32m    460\u001b[0m \u001b[0;34m\u001b[0m\u001b[0m\n\u001b[0;32m--> 461\u001b[0;31m         \u001b[0mM\u001b[0m\u001b[0;34m,\u001b[0m \u001b[0mN\u001b[0m \u001b[0;34m=\u001b[0m \u001b[0mself\u001b[0m\u001b[0;34m.\u001b[0m\u001b[0mshape\u001b[0m\u001b[0;34m\u001b[0m\u001b[0m\n\u001b[0m\u001b[1;32m    462\u001b[0m \u001b[0;34m\u001b[0m\u001b[0m\n",
      "\u001b[0;31mSystemError\u001b[0m: PyEval_EvalFrameEx returned a result with an error set",
      "\nDuring handling of the above exception, another exception occurred:\n",
      "\u001b[0;31mSystemError\u001b[0m                               Traceback (most recent call last)",
      "\u001b[0;32mC:\\Users\\irina\\Miniconda3\\envs\\exmc\\lib\\site-packages\\scipy\\sparse\\base.py\u001b[0m in \u001b[0;36m__mul__\u001b[0;34m(self, other)\u001b[0m\n\u001b[1;32m    460\u001b[0m \u001b[0;34m\u001b[0m\u001b[0m\n\u001b[0;32m--> 461\u001b[0;31m         \u001b[0mM\u001b[0m\u001b[0;34m,\u001b[0m \u001b[0mN\u001b[0m \u001b[0;34m=\u001b[0m \u001b[0mself\u001b[0m\u001b[0;34m.\u001b[0m\u001b[0mshape\u001b[0m\u001b[0;34m\u001b[0m\u001b[0m\n\u001b[0m\u001b[1;32m    462\u001b[0m \u001b[0;34m\u001b[0m\u001b[0m\n",
      "\u001b[0;31mSystemError\u001b[0m: PyEval_EvalFrameEx returned a result with an error set",
      "\nDuring handling of the above exception, another exception occurred:\n",
      "\u001b[0;31mSystemError\u001b[0m                               Traceback (most recent call last)",
      "\u001b[0;32mC:\\Users\\irina\\Miniconda3\\envs\\exmc\\lib\\site-packages\\scipy\\sparse\\base.py\u001b[0m in \u001b[0;36m__mul__\u001b[0;34m(self, other)\u001b[0m\n\u001b[1;32m    460\u001b[0m \u001b[0;34m\u001b[0m\u001b[0m\n\u001b[0;32m--> 461\u001b[0;31m         \u001b[0mM\u001b[0m\u001b[0;34m,\u001b[0m \u001b[0mN\u001b[0m \u001b[0;34m=\u001b[0m \u001b[0mself\u001b[0m\u001b[0;34m.\u001b[0m\u001b[0mshape\u001b[0m\u001b[0;34m\u001b[0m\u001b[0m\n\u001b[0m\u001b[1;32m    462\u001b[0m \u001b[0;34m\u001b[0m\u001b[0m\n",
      "\u001b[0;31mSystemError\u001b[0m: PyEval_EvalFrameEx returned a result with an error set",
      "\nDuring handling of the above exception, another exception occurred:\n",
      "\u001b[0;31mSystemError\u001b[0m                               Traceback (most recent call last)",
      "\u001b[0;32mC:\\Users\\irina\\Miniconda3\\envs\\exmc\\lib\\site-packages\\scipy\\sparse\\base.py\u001b[0m in \u001b[0;36m__mul__\u001b[0;34m(self, other)\u001b[0m\n\u001b[1;32m    460\u001b[0m \u001b[0;34m\u001b[0m\u001b[0m\n\u001b[0;32m--> 461\u001b[0;31m         \u001b[0mM\u001b[0m\u001b[0;34m,\u001b[0m \u001b[0mN\u001b[0m \u001b[0;34m=\u001b[0m \u001b[0mself\u001b[0m\u001b[0;34m.\u001b[0m\u001b[0mshape\u001b[0m\u001b[0;34m\u001b[0m\u001b[0m\n\u001b[0m\u001b[1;32m    462\u001b[0m \u001b[0;34m\u001b[0m\u001b[0m\n",
      "\u001b[0;31mSystemError\u001b[0m: PyEval_EvalFrameEx returned a result with an error set",
      "\nDuring handling of the above exception, another exception occurred:\n",
      "\u001b[0;31mSystemError\u001b[0m                               Traceback (most recent call last)",
      "\u001b[0;32mC:\\Users\\irina\\Miniconda3\\envs\\exmc\\lib\\site-packages\\scipy\\sparse\\base.py\u001b[0m in \u001b[0;36m__mul__\u001b[0;34m(self, other)\u001b[0m\n\u001b[1;32m    460\u001b[0m \u001b[0;34m\u001b[0m\u001b[0m\n\u001b[0;32m--> 461\u001b[0;31m         \u001b[0mM\u001b[0m\u001b[0;34m,\u001b[0m \u001b[0mN\u001b[0m \u001b[0;34m=\u001b[0m \u001b[0mself\u001b[0m\u001b[0;34m.\u001b[0m\u001b[0mshape\u001b[0m\u001b[0;34m\u001b[0m\u001b[0m\n\u001b[0m\u001b[1;32m    462\u001b[0m \u001b[0;34m\u001b[0m\u001b[0m\n",
      "\u001b[0;31mSystemError\u001b[0m: PyEval_EvalFrameEx returned a result with an error set",
      "\nDuring handling of the above exception, another exception occurred:\n",
      "\u001b[0;31mSystemError\u001b[0m                               Traceback (most recent call last)",
      "\u001b[0;32mC:\\Users\\irina\\Miniconda3\\envs\\exmc\\lib\\site-packages\\scipy\\sparse\\base.py\u001b[0m in \u001b[0;36m__mul__\u001b[0;34m(self, other)\u001b[0m\n\u001b[1;32m    460\u001b[0m \u001b[0;34m\u001b[0m\u001b[0m\n\u001b[0;32m--> 461\u001b[0;31m         \u001b[0mM\u001b[0m\u001b[0;34m,\u001b[0m \u001b[0mN\u001b[0m \u001b[0;34m=\u001b[0m \u001b[0mself\u001b[0m\u001b[0;34m.\u001b[0m\u001b[0mshape\u001b[0m\u001b[0;34m\u001b[0m\u001b[0m\n\u001b[0m\u001b[1;32m    462\u001b[0m \u001b[0;34m\u001b[0m\u001b[0m\n",
      "\u001b[0;31mSystemError\u001b[0m: PyEval_EvalFrameEx returned a result with an error set",
      "\nDuring handling of the above exception, another exception occurred:\n",
      "\u001b[0;31mSystemError\u001b[0m                               Traceback (most recent call last)",
      "\u001b[0;32mC:\\Users\\irina\\Miniconda3\\envs\\exmc\\lib\\site-packages\\scipy\\sparse\\base.py\u001b[0m in \u001b[0;36m__mul__\u001b[0;34m(self, other)\u001b[0m\n\u001b[1;32m    460\u001b[0m \u001b[0;34m\u001b[0m\u001b[0m\n\u001b[0;32m--> 461\u001b[0;31m         \u001b[0mM\u001b[0m\u001b[0;34m,\u001b[0m \u001b[0mN\u001b[0m \u001b[0;34m=\u001b[0m \u001b[0mself\u001b[0m\u001b[0;34m.\u001b[0m\u001b[0mshape\u001b[0m\u001b[0;34m\u001b[0m\u001b[0m\n\u001b[0m\u001b[1;32m    462\u001b[0m \u001b[0;34m\u001b[0m\u001b[0m\n",
      "\u001b[0;31mSystemError\u001b[0m: PyEval_EvalFrameEx returned a result with an error set",
      "\nDuring handling of the above exception, another exception occurred:\n",
      "\u001b[0;31mSystemError\u001b[0m                               Traceback (most recent call last)",
      "\u001b[0;32mC:\\Users\\irina\\Miniconda3\\envs\\exmc\\lib\\site-packages\\scipy\\sparse\\base.py\u001b[0m in \u001b[0;36m__mul__\u001b[0;34m(self, other)\u001b[0m\n\u001b[1;32m    460\u001b[0m \u001b[0;34m\u001b[0m\u001b[0m\n\u001b[0;32m--> 461\u001b[0;31m         \u001b[0mM\u001b[0m\u001b[0;34m,\u001b[0m \u001b[0mN\u001b[0m \u001b[0;34m=\u001b[0m \u001b[0mself\u001b[0m\u001b[0;34m.\u001b[0m\u001b[0mshape\u001b[0m\u001b[0;34m\u001b[0m\u001b[0m\n\u001b[0m\u001b[1;32m    462\u001b[0m \u001b[0;34m\u001b[0m\u001b[0m\n",
      "\u001b[0;31mSystemError\u001b[0m: PyEval_EvalFrameEx returned a result with an error set",
      "\nDuring handling of the above exception, another exception occurred:\n",
      "\u001b[0;31mSystemError\u001b[0m                               Traceback (most recent call last)",
      "\u001b[0;32mC:\\Users\\irina\\Miniconda3\\envs\\exmc\\lib\\site-packages\\scipy\\sparse\\base.py\u001b[0m in \u001b[0;36m__mul__\u001b[0;34m(self, other)\u001b[0m\n\u001b[1;32m    460\u001b[0m \u001b[0;34m\u001b[0m\u001b[0m\n\u001b[0;32m--> 461\u001b[0;31m         \u001b[0mM\u001b[0m\u001b[0;34m,\u001b[0m \u001b[0mN\u001b[0m \u001b[0;34m=\u001b[0m \u001b[0mself\u001b[0m\u001b[0;34m.\u001b[0m\u001b[0mshape\u001b[0m\u001b[0;34m\u001b[0m\u001b[0m\n\u001b[0m\u001b[1;32m    462\u001b[0m \u001b[0;34m\u001b[0m\u001b[0m\n",
      "\u001b[0;31mSystemError\u001b[0m: PyEval_EvalFrameEx returned a result with an error set",
      "\nDuring handling of the above exception, another exception occurred:\n",
      "\u001b[0;31mSystemError\u001b[0m                               Traceback (most recent call last)",
      "\u001b[0;32mC:\\Users\\irina\\Miniconda3\\envs\\exmc\\lib\\site-packages\\scipy\\sparse\\base.py\u001b[0m in \u001b[0;36m__mul__\u001b[0;34m(self, other)\u001b[0m\n\u001b[1;32m    460\u001b[0m \u001b[0;34m\u001b[0m\u001b[0m\n\u001b[0;32m--> 461\u001b[0;31m         \u001b[0mM\u001b[0m\u001b[0;34m,\u001b[0m \u001b[0mN\u001b[0m \u001b[0;34m=\u001b[0m \u001b[0mself\u001b[0m\u001b[0;34m.\u001b[0m\u001b[0mshape\u001b[0m\u001b[0;34m\u001b[0m\u001b[0m\n\u001b[0m\u001b[1;32m    462\u001b[0m \u001b[0;34m\u001b[0m\u001b[0m\n",
      "\u001b[0;31mSystemError\u001b[0m: PyEval_EvalFrameEx returned a result with an error set",
      "\nDuring handling of the above exception, another exception occurred:\n",
      "\u001b[0;31mSystemError\u001b[0m                               Traceback (most recent call last)",
      "\u001b[0;32mC:\\Users\\irina\\Miniconda3\\envs\\exmc\\lib\\site-packages\\scipy\\sparse\\base.py\u001b[0m in \u001b[0;36m__mul__\u001b[0;34m(self, other)\u001b[0m\n\u001b[1;32m    460\u001b[0m \u001b[0;34m\u001b[0m\u001b[0m\n\u001b[0;32m--> 461\u001b[0;31m         \u001b[0mM\u001b[0m\u001b[0;34m,\u001b[0m \u001b[0mN\u001b[0m \u001b[0;34m=\u001b[0m \u001b[0mself\u001b[0m\u001b[0;34m.\u001b[0m\u001b[0mshape\u001b[0m\u001b[0;34m\u001b[0m\u001b[0m\n\u001b[0m\u001b[1;32m    462\u001b[0m \u001b[0;34m\u001b[0m\u001b[0m\n",
      "\u001b[0;31mSystemError\u001b[0m: PyEval_EvalFrameEx returned a result with an error set",
      "\nDuring handling of the above exception, another exception occurred:\n",
      "\u001b[0;31mSystemError\u001b[0m                               Traceback (most recent call last)",
      "\u001b[0;32mC:\\Users\\irina\\Miniconda3\\envs\\exmc\\lib\\site-packages\\scipy\\sparse\\base.py\u001b[0m in \u001b[0;36m__mul__\u001b[0;34m(self, other)\u001b[0m\n\u001b[1;32m    460\u001b[0m \u001b[0;34m\u001b[0m\u001b[0m\n\u001b[0;32m--> 461\u001b[0;31m         \u001b[0mM\u001b[0m\u001b[0;34m,\u001b[0m \u001b[0mN\u001b[0m \u001b[0;34m=\u001b[0m \u001b[0mself\u001b[0m\u001b[0;34m.\u001b[0m\u001b[0mshape\u001b[0m\u001b[0;34m\u001b[0m\u001b[0m\n\u001b[0m\u001b[1;32m    462\u001b[0m \u001b[0;34m\u001b[0m\u001b[0m\n",
      "\u001b[0;31mSystemError\u001b[0m: PyEval_EvalFrameEx returned a result with an error set",
      "\nDuring handling of the above exception, another exception occurred:\n",
      "\u001b[0;31mSystemError\u001b[0m                               Traceback (most recent call last)",
      "\u001b[0;32mC:\\Users\\irina\\Miniconda3\\envs\\exmc\\lib\\site-packages\\scipy\\sparse\\base.py\u001b[0m in \u001b[0;36m__mul__\u001b[0;34m(self, other)\u001b[0m\n\u001b[1;32m    460\u001b[0m \u001b[0;34m\u001b[0m\u001b[0m\n\u001b[0;32m--> 461\u001b[0;31m         \u001b[0mM\u001b[0m\u001b[0;34m,\u001b[0m \u001b[0mN\u001b[0m \u001b[0;34m=\u001b[0m \u001b[0mself\u001b[0m\u001b[0;34m.\u001b[0m\u001b[0mshape\u001b[0m\u001b[0;34m\u001b[0m\u001b[0m\n\u001b[0m\u001b[1;32m    462\u001b[0m \u001b[0;34m\u001b[0m\u001b[0m\n",
      "\u001b[0;31mSystemError\u001b[0m: PyEval_EvalFrameEx returned a result with an error set",
      "\nDuring handling of the above exception, another exception occurred:\n",
      "\u001b[0;31mSystemError\u001b[0m                               Traceback (most recent call last)",
      "\u001b[0;32mC:\\Users\\irina\\Miniconda3\\envs\\exmc\\lib\\site-packages\\scipy\\sparse\\base.py\u001b[0m in \u001b[0;36m__mul__\u001b[0;34m(self, other)\u001b[0m\n\u001b[1;32m    460\u001b[0m \u001b[0;34m\u001b[0m\u001b[0m\n\u001b[0;32m--> 461\u001b[0;31m         \u001b[0mM\u001b[0m\u001b[0;34m,\u001b[0m \u001b[0mN\u001b[0m \u001b[0;34m=\u001b[0m \u001b[0mself\u001b[0m\u001b[0;34m.\u001b[0m\u001b[0mshape\u001b[0m\u001b[0;34m\u001b[0m\u001b[0m\n\u001b[0m\u001b[1;32m    462\u001b[0m \u001b[0;34m\u001b[0m\u001b[0m\n",
      "\u001b[0;31mSystemError\u001b[0m: PyEval_EvalFrameEx returned a result with an error set",
      "\nDuring handling of the above exception, another exception occurred:\n",
      "\u001b[0;31mSystemError\u001b[0m                               Traceback (most recent call last)",
      "\u001b[0;32mC:\\Users\\irina\\Miniconda3\\envs\\exmc\\lib\\site-packages\\scipy\\sparse\\base.py\u001b[0m in \u001b[0;36m__mul__\u001b[0;34m(self, other)\u001b[0m\n\u001b[1;32m    460\u001b[0m \u001b[0;34m\u001b[0m\u001b[0m\n\u001b[0;32m--> 461\u001b[0;31m         \u001b[0mM\u001b[0m\u001b[0;34m,\u001b[0m \u001b[0mN\u001b[0m \u001b[0;34m=\u001b[0m \u001b[0mself\u001b[0m\u001b[0;34m.\u001b[0m\u001b[0mshape\u001b[0m\u001b[0;34m\u001b[0m\u001b[0m\n\u001b[0m\u001b[1;32m    462\u001b[0m \u001b[0;34m\u001b[0m\u001b[0m\n",
      "\u001b[0;31mSystemError\u001b[0m: PyEval_EvalFrameEx returned a result with an error set",
      "\nDuring handling of the above exception, another exception occurred:\n",
      "\u001b[0;31mSystemError\u001b[0m                               Traceback (most recent call last)",
      "\u001b[0;32mC:\\Users\\irina\\Miniconda3\\envs\\exmc\\lib\\site-packages\\scipy\\sparse\\base.py\u001b[0m in \u001b[0;36m__mul__\u001b[0;34m(self, other)\u001b[0m\n\u001b[1;32m    460\u001b[0m \u001b[0;34m\u001b[0m\u001b[0m\n\u001b[0;32m--> 461\u001b[0;31m         \u001b[0mM\u001b[0m\u001b[0;34m,\u001b[0m \u001b[0mN\u001b[0m \u001b[0;34m=\u001b[0m \u001b[0mself\u001b[0m\u001b[0;34m.\u001b[0m\u001b[0mshape\u001b[0m\u001b[0;34m\u001b[0m\u001b[0m\n\u001b[0m\u001b[1;32m    462\u001b[0m \u001b[0;34m\u001b[0m\u001b[0m\n",
      "\u001b[0;31mSystemError\u001b[0m: PyEval_EvalFrameEx returned a result with an error set",
      "\nDuring handling of the above exception, another exception occurred:\n",
      "\u001b[0;31mSystemError\u001b[0m                               Traceback (most recent call last)",
      "\u001b[0;32mC:\\Users\\irina\\Miniconda3\\envs\\exmc\\lib\\site-packages\\scipy\\sparse\\base.py\u001b[0m in \u001b[0;36m__mul__\u001b[0;34m(self, other)\u001b[0m\n\u001b[1;32m    460\u001b[0m \u001b[0;34m\u001b[0m\u001b[0m\n\u001b[0;32m--> 461\u001b[0;31m         \u001b[0mM\u001b[0m\u001b[0;34m,\u001b[0m \u001b[0mN\u001b[0m \u001b[0;34m=\u001b[0m \u001b[0mself\u001b[0m\u001b[0;34m.\u001b[0m\u001b[0mshape\u001b[0m\u001b[0;34m\u001b[0m\u001b[0m\n\u001b[0m\u001b[1;32m    462\u001b[0m \u001b[0;34m\u001b[0m\u001b[0m\n",
      "\u001b[0;31mSystemError\u001b[0m: PyEval_EvalFrameEx returned a result with an error set",
      "\nDuring handling of the above exception, another exception occurred:\n",
      "\u001b[0;31mSystemError\u001b[0m                               Traceback (most recent call last)",
      "\u001b[0;32mC:\\Users\\irina\\Miniconda3\\envs\\exmc\\lib\\site-packages\\scipy\\sparse\\base.py\u001b[0m in \u001b[0;36m__mul__\u001b[0;34m(self, other)\u001b[0m\n\u001b[1;32m    460\u001b[0m \u001b[0;34m\u001b[0m\u001b[0m\n\u001b[0;32m--> 461\u001b[0;31m         \u001b[0mM\u001b[0m\u001b[0;34m,\u001b[0m \u001b[0mN\u001b[0m \u001b[0;34m=\u001b[0m \u001b[0mself\u001b[0m\u001b[0;34m.\u001b[0m\u001b[0mshape\u001b[0m\u001b[0;34m\u001b[0m\u001b[0m\n\u001b[0m\u001b[1;32m    462\u001b[0m \u001b[0;34m\u001b[0m\u001b[0m\n",
      "\u001b[0;31mSystemError\u001b[0m: PyEval_EvalFrameEx returned a result with an error set",
      "\nDuring handling of the above exception, another exception occurred:\n",
      "\u001b[0;31mSystemError\u001b[0m                               Traceback (most recent call last)",
      "\u001b[0;32mC:\\Users\\irina\\Miniconda3\\envs\\exmc\\lib\\site-packages\\scipy\\sparse\\base.py\u001b[0m in \u001b[0;36m__mul__\u001b[0;34m(self, other)\u001b[0m\n\u001b[1;32m    460\u001b[0m \u001b[0;34m\u001b[0m\u001b[0m\n\u001b[0;32m--> 461\u001b[0;31m         \u001b[0mM\u001b[0m\u001b[0;34m,\u001b[0m \u001b[0mN\u001b[0m \u001b[0;34m=\u001b[0m \u001b[0mself\u001b[0m\u001b[0;34m.\u001b[0m\u001b[0mshape\u001b[0m\u001b[0;34m\u001b[0m\u001b[0m\n\u001b[0m\u001b[1;32m    462\u001b[0m \u001b[0;34m\u001b[0m\u001b[0m\n",
      "\u001b[0;31mSystemError\u001b[0m: PyEval_EvalFrameEx returned a result with an error set",
      "\nDuring handling of the above exception, another exception occurred:\n",
      "\u001b[0;31mSystemError\u001b[0m                               Traceback (most recent call last)",
      "\u001b[0;32mC:\\Users\\irina\\Miniconda3\\envs\\exmc\\lib\\site-packages\\scipy\\sparse\\base.py\u001b[0m in \u001b[0;36m__mul__\u001b[0;34m(self, other)\u001b[0m\n\u001b[1;32m    460\u001b[0m \u001b[0;34m\u001b[0m\u001b[0m\n\u001b[0;32m--> 461\u001b[0;31m         \u001b[0mM\u001b[0m\u001b[0;34m,\u001b[0m \u001b[0mN\u001b[0m \u001b[0;34m=\u001b[0m \u001b[0mself\u001b[0m\u001b[0;34m.\u001b[0m\u001b[0mshape\u001b[0m\u001b[0;34m\u001b[0m\u001b[0m\n\u001b[0m\u001b[1;32m    462\u001b[0m \u001b[0;34m\u001b[0m\u001b[0m\n",
      "\u001b[0;31mSystemError\u001b[0m: PyEval_EvalFrameEx returned a result with an error set",
      "\nDuring handling of the above exception, another exception occurred:\n",
      "\u001b[0;31mSystemError\u001b[0m                               Traceback (most recent call last)",
      "\u001b[0;32mC:\\Users\\irina\\Miniconda3\\envs\\exmc\\lib\\site-packages\\scipy\\sparse\\base.py\u001b[0m in \u001b[0;36m__mul__\u001b[0;34m(self, other)\u001b[0m\n\u001b[1;32m    460\u001b[0m \u001b[0;34m\u001b[0m\u001b[0m\n\u001b[0;32m--> 461\u001b[0;31m         \u001b[0mM\u001b[0m\u001b[0;34m,\u001b[0m \u001b[0mN\u001b[0m \u001b[0;34m=\u001b[0m \u001b[0mself\u001b[0m\u001b[0;34m.\u001b[0m\u001b[0mshape\u001b[0m\u001b[0;34m\u001b[0m\u001b[0m\n\u001b[0m\u001b[1;32m    462\u001b[0m \u001b[0;34m\u001b[0m\u001b[0m\n",
      "\u001b[0;31mSystemError\u001b[0m: PyEval_EvalFrameEx returned a result with an error set",
      "\nDuring handling of the above exception, another exception occurred:\n",
      "\u001b[0;31mSystemError\u001b[0m                               Traceback (most recent call last)",
      "\u001b[0;32mC:\\Users\\irina\\Miniconda3\\envs\\exmc\\lib\\site-packages\\scipy\\sparse\\base.py\u001b[0m in \u001b[0;36m__mul__\u001b[0;34m(self, other)\u001b[0m\n\u001b[1;32m    460\u001b[0m \u001b[0;34m\u001b[0m\u001b[0m\n\u001b[0;32m--> 461\u001b[0;31m         \u001b[0mM\u001b[0m\u001b[0;34m,\u001b[0m \u001b[0mN\u001b[0m \u001b[0;34m=\u001b[0m \u001b[0mself\u001b[0m\u001b[0;34m.\u001b[0m\u001b[0mshape\u001b[0m\u001b[0;34m\u001b[0m\u001b[0m\n\u001b[0m\u001b[1;32m    462\u001b[0m \u001b[0;34m\u001b[0m\u001b[0m\n",
      "\u001b[0;31mSystemError\u001b[0m: PyEval_EvalFrameEx returned a result with an error set",
      "\nDuring handling of the above exception, another exception occurred:\n",
      "\u001b[0;31mSystemError\u001b[0m                               Traceback (most recent call last)",
      "\u001b[0;32mC:\\Users\\irina\\Miniconda3\\envs\\exmc\\lib\\site-packages\\scipy\\sparse\\base.py\u001b[0m in \u001b[0;36m__mul__\u001b[0;34m(self, other)\u001b[0m\n\u001b[1;32m    460\u001b[0m \u001b[0;34m\u001b[0m\u001b[0m\n\u001b[0;32m--> 461\u001b[0;31m         \u001b[0mM\u001b[0m\u001b[0;34m,\u001b[0m \u001b[0mN\u001b[0m \u001b[0;34m=\u001b[0m \u001b[0mself\u001b[0m\u001b[0;34m.\u001b[0m\u001b[0mshape\u001b[0m\u001b[0;34m\u001b[0m\u001b[0m\n\u001b[0m\u001b[1;32m    462\u001b[0m \u001b[0;34m\u001b[0m\u001b[0m\n",
      "\u001b[0;31mSystemError\u001b[0m: PyEval_EvalFrameEx returned a result with an error set",
      "\nDuring handling of the above exception, another exception occurred:\n",
      "\u001b[0;31mSystemError\u001b[0m                               Traceback (most recent call last)",
      "\u001b[0;32mC:\\Users\\irina\\Miniconda3\\envs\\exmc\\lib\\site-packages\\scipy\\sparse\\base.py\u001b[0m in \u001b[0;36m__mul__\u001b[0;34m(self, other)\u001b[0m\n\u001b[1;32m    460\u001b[0m \u001b[0;34m\u001b[0m\u001b[0m\n\u001b[0;32m--> 461\u001b[0;31m         \u001b[0mM\u001b[0m\u001b[0;34m,\u001b[0m \u001b[0mN\u001b[0m \u001b[0;34m=\u001b[0m \u001b[0mself\u001b[0m\u001b[0;34m.\u001b[0m\u001b[0mshape\u001b[0m\u001b[0;34m\u001b[0m\u001b[0m\n\u001b[0m\u001b[1;32m    462\u001b[0m \u001b[0;34m\u001b[0m\u001b[0m\n",
      "\u001b[0;31mSystemError\u001b[0m: PyEval_EvalFrameEx returned a result with an error set",
      "\nDuring handling of the above exception, another exception occurred:\n",
      "\u001b[0;31mSystemError\u001b[0m                               Traceback (most recent call last)",
      "\u001b[0;32mC:\\Users\\irina\\Miniconda3\\envs\\exmc\\lib\\site-packages\\scipy\\sparse\\base.py\u001b[0m in \u001b[0;36m__mul__\u001b[0;34m(self, other)\u001b[0m\n\u001b[1;32m    460\u001b[0m \u001b[0;34m\u001b[0m\u001b[0m\n\u001b[0;32m--> 461\u001b[0;31m         \u001b[0mM\u001b[0m\u001b[0;34m,\u001b[0m \u001b[0mN\u001b[0m \u001b[0;34m=\u001b[0m \u001b[0mself\u001b[0m\u001b[0;34m.\u001b[0m\u001b[0mshape\u001b[0m\u001b[0;34m\u001b[0m\u001b[0m\n\u001b[0m\u001b[1;32m    462\u001b[0m \u001b[0;34m\u001b[0m\u001b[0m\n",
      "\u001b[0;31mSystemError\u001b[0m: PyEval_EvalFrameEx returned a result with an error set",
      "\nDuring handling of the above exception, another exception occurred:\n",
      "\u001b[0;31mSystemError\u001b[0m                               Traceback (most recent call last)",
      "\u001b[0;32mC:\\Users\\irina\\Miniconda3\\envs\\exmc\\lib\\site-packages\\scipy\\sparse\\base.py\u001b[0m in \u001b[0;36m__mul__\u001b[0;34m(self, other)\u001b[0m\n\u001b[1;32m    460\u001b[0m \u001b[0;34m\u001b[0m\u001b[0m\n\u001b[0;32m--> 461\u001b[0;31m         \u001b[0mM\u001b[0m\u001b[0;34m,\u001b[0m \u001b[0mN\u001b[0m \u001b[0;34m=\u001b[0m \u001b[0mself\u001b[0m\u001b[0;34m.\u001b[0m\u001b[0mshape\u001b[0m\u001b[0;34m\u001b[0m\u001b[0m\n\u001b[0m\u001b[1;32m    462\u001b[0m \u001b[0;34m\u001b[0m\u001b[0m\n",
      "\u001b[0;31mSystemError\u001b[0m: PyEval_EvalFrameEx returned a result with an error set",
      "\nDuring handling of the above exception, another exception occurred:\n",
      "\nDuring handling of the above exception, another exception occurred:\n",
      "\u001b[0;31mKeyboardInterrupt\u001b[0m                         Traceback (most recent call last)",
      "\u001b[0;32mC:\\Users\\irina\\Miniconda3\\envs\\exmc\\lib\\site-packages\\IPython\\core\\interactiveshell.py\u001b[0m in \u001b[0;36mrun_code\u001b[0;34m(self, code_obj, result)\u001b[0m\n\u001b[1;32m   2871\u001b[0m                 \u001b[0;31m# Reset our crash handler in place\u001b[0m\u001b[0;34m\u001b[0m\u001b[0;34m\u001b[0m\u001b[0m\n\u001b[0;32m-> 2872\u001b[0;31m                 \u001b[0msys\u001b[0m\u001b[0;34m.\u001b[0m\u001b[0mexcepthook\u001b[0m \u001b[0;34m=\u001b[0m \u001b[0mold_excepthook\u001b[0m\u001b[0;34m\u001b[0m\u001b[0m\n\u001b[0m\u001b[1;32m   2873\u001b[0m         \u001b[0;32mexcept\u001b[0m \u001b[0mSystemExit\u001b[0m \u001b[0;32mas\u001b[0m \u001b[0me\u001b[0m\u001b[0;34m:\u001b[0m\u001b[0;34m\u001b[0m\u001b[0m\n",
      "\u001b[0;31mKeyboardInterrupt\u001b[0m: ",
      "\nDuring handling of the above exception, another exception occurred:\n",
      "\u001b[0;31mKeyboardInterrupt\u001b[0m                         Traceback (most recent call last)",
      "\u001b[0;32mC:\\Users\\irina\\Miniconda3\\envs\\exmc\\lib\\site-packages\\IPython\\core\\interactiveshell.py\u001b[0m in \u001b[0;36mrun_code\u001b[0;34m(self, code_obj, result)\u001b[0m\n\u001b[1;32m   2871\u001b[0m                 \u001b[0;31m# Reset our crash handler in place\u001b[0m\u001b[0;34m\u001b[0m\u001b[0;34m\u001b[0m\u001b[0m\n\u001b[1;32m   2872\u001b[0m                 \u001b[0msys\u001b[0m\u001b[0;34m.\u001b[0m\u001b[0mexcepthook\u001b[0m \u001b[0;34m=\u001b[0m \u001b[0mold_excepthook\u001b[0m\u001b[0;34m\u001b[0m\u001b[0m\n\u001b[0;32m-> 2873\u001b[0;31m         \u001b[0;32mexcept\u001b[0m \u001b[0mSystemExit\u001b[0m \u001b[0;32mas\u001b[0m \u001b[0me\u001b[0m\u001b[0;34m:\u001b[0m\u001b[0;34m\u001b[0m\u001b[0m\n\u001b[0m\u001b[1;32m   2874\u001b[0m             \u001b[0;32mif\u001b[0m \u001b[0mresult\u001b[0m \u001b[0;32mis\u001b[0m \u001b[0;32mnot\u001b[0m \u001b[0;32mNone\u001b[0m\u001b[0;34m:\u001b[0m\u001b[0;34m\u001b[0m\u001b[0m\n\u001b[1;32m   2875\u001b[0m                 \u001b[0mresult\u001b[0m\u001b[0;34m.\u001b[0m\u001b[0merror_in_exec\u001b[0m \u001b[0;34m=\u001b[0m \u001b[0me\u001b[0m\u001b[0;34m\u001b[0m\u001b[0m\n",
      "\u001b[0;31mKeyboardInterrupt\u001b[0m: "
     ]
    }
   ],
   "source": [
    "X_train_noised = add_noise(X_train , 0.3)"
   ]
  },
  {
   "cell_type": "code",
   "execution_count": null,
   "metadata": {},
   "outputs": [],
   "source": [
    "cdl = CDL(rating_matrix , X_train)\n",
    "cdl.training()"
   ]
  },
  {
   "cell_type": "code",
   "execution_count": 16,
   "metadata": {},
   "outputs": [
    {
     "name": "stdout",
     "output_type": "stream",
     "text": [
      "Once deleted, variables cannot be recovered. Proceed (y/[n])? y\n",
      "Flushing output cache (4 entries)\n"
     ]
    }
   ],
   "source": [
    "%reset Out"
   ]
  },
  {
   "cell_type": "code",
   "execution_count": null,
   "metadata": {},
   "outputs": [],
   "source": []
  },
  {
   "cell_type": "code",
   "execution_count": null,
   "metadata": {},
   "outputs": [],
   "source": []
  },
  {
   "cell_type": "code",
   "execution_count": null,
   "metadata": {},
   "outputs": [],
   "source": []
  }
 ],
 "metadata": {
  "kernelspec": {
   "display_name": "Python 3",
   "language": "python",
   "name": "python3"
  },
  "language_info": {
   "codemirror_mode": {
    "name": "ipython",
    "version": 3
   },
   "file_extension": ".py",
   "mimetype": "text/x-python",
   "name": "python",
   "nbconvert_exporter": "python",
   "pygments_lexer": "ipython3",
   "version": "3.5.5"
  }
 },
 "nbformat": 4,
 "nbformat_minor": 2
}
